ply
format ascii 1.0
comment : MagicaVoxel @ Ephtracy
element vertex 2628
property float x
property float y
property float z
property uchar red
property uchar green
property uchar blue
end_header
-8 -9 0 255 204 153
-7 -9 0 255 204 153
-6 -9 0 255 204 153
-5 -9 0 255 204 153
-4 -9 0 255 204 153
4 -9 0 255 204 153
5 -9 0 255 204 153
6 -9 0 255 204 153
7 -9 0 255 204 153
8 -9 0 255 204 153
-8 -8 0 255 204 153
-7 -8 0 255 204 153
-6 -8 0 255 204 153
-5 -8 0 255 204 153
-4 -8 0 255 204 153
4 -8 0 255 204 153
5 -8 0 255 204 153
6 -8 0 255 204 153
7 -8 0 255 204 153
8 -8 0 255 204 153
-8 -7 0 255 204 153
-7 -7 0 255 204 153
-6 -7 0 255 204 153
-5 -7 0 255 204 153
-4 -7 0 255 204 153
4 -7 0 255 204 153
5 -7 0 255 204 153
6 -7 0 255 204 153
7 -7 0 255 204 153
8 -7 0 255 204 153
-7 -6 0 255 204 153
-6 -6 0 255 204 153
-5 -6 0 255 204 153
-4 -6 0 255 204 153
4 -6 0 255 204 153
5 -6 0 255 204 153
6 -6 0 255 204 153
7 -6 0 255 204 153
-6 -5 0 255 204 153
6 -5 0 255 204 153
-7 -4 0 255 204 153
-6 -4 0 255 204 153
6 -4 0 255 204 153
7 -4 0 255 204 153
-8 -3 0 255 204 153
-7 -3 0 255 204 153
-6 -3 0 255 204 153
6 -3 0 255 204 153
7 -3 0 255 204 153
8 -3 0 255 204 153
-8 -2 0 255 204 153
-7 -2 0 255 204 153
-6 -2 0 255 204 153
6 -2 0 255 204 153
7 -2 0 255 204 153
8 -2 0 255 204 153
-8 -1 0 255 204 153
-7 -1 0 255 204 153
-6 -1 0 255 204 153
6 -1 0 255 204 153
7 -1 0 255 204 153
8 -1 0 255 204 153
-8 0 0 255 204 153
-7 0 0 255 204 153
-6 0 0 255 204 153
6 0 0 255 204 153
7 0 0 255 204 153
8 0 0 255 204 153
-8 1 0 255 204 153
-7 1 0 255 204 153
-6 1 0 255 204 153
6 1 0 255 204 153
7 1 0 255 204 153
8 1 0 255 204 153
-8 2 0 255 204 153
-7 2 0 255 204 153
-6 2 0 255 204 153
6 2 0 255 204 153
7 2 0 255 204 153
8 2 0 255 204 153
-8 3 0 255 204 153
-7 3 0 255 204 153
-6 3 0 255 204 153
6 3 0 255 204 153
7 3 0 255 204 153
8 3 0 255 204 153
-7 4 0 255 204 153
-6 4 0 255 204 153
6 4 0 255 204 153
7 4 0 255 204 153
-6 5 0 255 204 153
6 5 0 255 204 153
-7 6 0 255 204 153
-6 6 0 255 204 153
-5 6 0 255 204 153
-4 6 0 255 204 153
4 6 0 255 204 153
5 6 0 255 204 153
6 6 0 255 204 153
7 6 0 255 204 153
-8 7 0 255 204 153
-7 7 0 255 204 153
-6 7 0 255 204 153
-5 7 0 255 204 153
-4 7 0 255 204 153
4 7 0 255 204 153
5 7 0 255 204 153
6 7 0 255 204 153
7 7 0 255 204 153
8 7 0 255 204 153
-8 8 0 255 204 153
-7 8 0 255 204 153
-6 8 0 255 204 153
-5 8 0 255 204 153
-4 8 0 255 204 153
4 8 0 255 204 153
5 8 0 255 204 153
6 8 0 255 204 153
7 8 0 255 204 153
8 8 0 255 204 153
-8 9 0 255 204 153
-7 9 0 255 204 153
-6 9 0 255 204 153
-5 9 0 255 204 153
-4 9 0 255 204 153
4 9 0 255 204 153
5 9 0 255 204 153
6 9 0 255 204 153
7 9 0 255 204 153
8 9 0 255 204 153
-8 -9 1 255 204 153
-7 -9 1 255 204 153
-6 -9 1 255 204 153
-5 -9 1 255 204 153
-4 -9 1 255 204 153
4 -9 1 255 204 153
5 -9 1 255 204 153
6 -9 1 255 204 153
7 -9 1 255 204 153
8 -9 1 255 204 153
-8 -8 1 255 204 153
-7 -8 1 255 204 153
-6 -8 1 255 204 153
-5 -8 1 255 204 153
-4 -8 1 255 204 153
4 -8 1 255 204 153
5 -8 1 255 204 153
6 -8 1 255 204 153
7 -8 1 255 204 153
8 -8 1 255 204 153
-8 -7 1 255 204 153
-7 -7 1 255 204 153
-6 -7 1 255 204 153
-5 -7 1 255 204 153
-4 -7 1 255 204 153
4 -7 1 255 204 153
5 -7 1 255 204 153
6 -7 1 255 204 153
7 -7 1 255 204 153
8 -7 1 255 204 153
-7 -6 1 255 204 153
-6 -6 1 255 204 153
-5 -6 1 255 204 153
-4 -6 1 255 204 153
4 -6 1 255 204 153
5 -6 1 255 204 153
6 -6 1 255 204 153
7 -6 1 255 204 153
-6 -5 1 255 204 153
6 -5 1 255 204 153
-7 -4 1 255 204 153
-6 -4 1 255 204 153
6 -4 1 255 204 153
7 -4 1 255 204 153
-8 -3 1 255 204 153
-7 -3 1 255 204 153
-6 -3 1 255 204 153
6 -3 1 255 204 153
7 -3 1 255 204 153
8 -3 1 255 204 153
-8 -2 1 255 204 153
-7 -2 1 255 204 153
-6 -2 1 255 204 153
6 -2 1 255 204 153
7 -2 1 255 204 153
8 -2 1 255 204 153
-8 -1 1 255 204 153
-7 -1 1 255 204 153
-6 -1 1 255 204 153
6 -1 1 255 204 153
7 -1 1 255 204 153
8 -1 1 255 204 153
-8 0 1 255 204 153
-7 0 1 255 204 153
-6 0 1 255 204 153
6 0 1 255 204 153
7 0 1 255 204 153
8 0 1 255 204 153
-8 1 1 255 204 153
-7 1 1 255 204 153
-6 1 1 255 204 153
6 1 1 255 204 153
7 1 1 255 204 153
8 1 1 255 204 153
-8 2 1 255 204 153
-7 2 1 255 204 153
-6 2 1 255 204 153
6 2 1 255 204 153
7 2 1 255 204 153
8 2 1 255 204 153
-8 3 1 255 204 153
-7 3 1 255 204 153
-6 3 1 255 204 153
6 3 1 255 204 153
7 3 1 255 204 153
8 3 1 255 204 153
-7 4 1 255 204 153
-6 4 1 255 204 153
6 4 1 255 204 153
7 4 1 255 204 153
-6 5 1 255 204 153
6 5 1 255 204 153
-7 6 1 255 204 153
-6 6 1 255 204 153
-5 6 1 255 204 153
-4 6 1 255 204 153
4 6 1 255 204 153
5 6 1 255 204 153
6 6 1 255 204 153
7 6 1 255 204 153
-8 7 1 255 204 153
-7 7 1 255 204 153
-6 7 1 255 204 153
-5 7 1 255 204 153
-4 7 1 255 204 153
4 7 1 255 204 153
5 7 1 255 204 153
6 7 1 255 204 153
7 7 1 255 204 153
8 7 1 255 204 153
-8 8 1 255 204 153
-7 8 1 255 204 153
-6 8 1 255 204 153
-5 8 1 255 204 153
-4 8 1 255 204 153
4 8 1 255 204 153
5 8 1 255 204 153
6 8 1 255 204 153
7 8 1 255 204 153
8 8 1 255 204 153
-8 9 1 255 204 153
-7 9 1 255 204 153
-6 9 1 255 204 153
-5 9 1 255 204 153
-4 9 1 255 204 153
4 9 1 255 204 153
5 9 1 255 204 153
6 9 1 255 204 153
7 9 1 255 204 153
8 9 1 255 204 153
-8 -9 2 255 204 153
-7 -9 2 255 204 153
-6 -9 2 255 204 153
-5 -9 2 255 204 153
-4 -9 2 255 204 153
4 -9 2 255 204 153
5 -9 2 255 204 153
6 -9 2 255 204 153
7 -9 2 255 204 153
8 -9 2 255 204 153
-8 -8 2 255 204 153
-7 -8 2 255 204 153
-6 -8 2 255 204 153
-5 -8 2 255 204 153
-4 -8 2 255 204 153
4 -8 2 255 204 153
5 -8 2 255 204 153
6 -8 2 255 204 153
7 -8 2 255 204 153
8 -8 2 255 204 153
-8 -7 2 255 204 153
-7 -7 2 255 204 153
-6 -7 2 255 204 153
-5 -7 2 255 204 153
-4 -7 2 255 204 153
4 -7 2 255 204 153
5 -7 2 255 204 153
6 -7 2 255 204 153
7 -7 2 255 204 153
8 -7 2 255 204 153
-7 -6 2 255 204 153
-6 -6 2 255 204 153
-5 -6 2 255 204 153
-4 -6 2 255 204 153
4 -6 2 255 204 153
5 -6 2 255 204 153
6 -6 2 255 204 153
7 -6 2 255 204 153
-6 -5 2 255 204 153
6 -5 2 255 204 153
-7 -4 2 255 204 153
-6 -4 2 255 204 153
6 -4 2 255 204 153
7 -4 2 255 204 153
-8 -3 2 255 204 153
-7 -3 2 255 204 153
-6 -3 2 255 204 153
6 -3 2 255 204 153
7 -3 2 255 204 153
8 -3 2 255 204 153
-8 -2 2 255 204 153
-7 -2 2 255 204 153
-6 -2 2 255 204 153
6 -2 2 255 204 153
7 -2 2 255 204 153
8 -2 2 255 204 153
-8 -1 2 255 204 153
-7 -1 2 255 204 153
-6 -1 2 255 204 153
6 -1 2 255 204 153
7 -1 2 255 204 153
8 -1 2 255 204 153
-8 0 2 255 204 153
-7 0 2 255 204 153
-6 0 2 255 204 153
6 0 2 255 204 153
7 0 2 255 204 153
8 0 2 255 204 153
-8 1 2 255 204 153
-7 1 2 255 204 153
-6 1 2 255 204 153
6 1 2 255 204 153
7 1 2 255 204 153
8 1 2 255 204 153
-8 2 2 255 204 153
-7 2 2 255 204 153
-6 2 2 255 204 153
6 2 2 255 204 153
7 2 2 255 204 153
8 2 2 255 204 153
-8 3 2 255 204 153
-7 3 2 255 204 153
-6 3 2 255 204 153
6 3 2 255 204 153
7 3 2 255 204 153
8 3 2 255 204 153
-7 4 2 255 204 153
-6 4 2 255 204 153
6 4 2 255 204 153
7 4 2 255 204 153
-6 5 2 255 204 153
6 5 2 255 204 153
-7 6 2 255 204 153
-6 6 2 255 204 153
-5 6 2 255 204 153
-4 6 2 255 204 153
4 6 2 255 204 153
5 6 2 255 204 153
6 6 2 255 204 153
7 6 2 255 204 153
-8 7 2 255 204 153
-7 7 2 255 204 153
-6 7 2 255 204 153
-5 7 2 255 204 153
-4 7 2 255 204 153
4 7 2 255 204 153
5 7 2 255 204 153
6 7 2 255 204 153
7 7 2 255 204 153
8 7 2 255 204 153
-8 8 2 255 204 153
-7 8 2 255 204 153
-6 8 2 255 204 153
-5 8 2 255 204 153
-4 8 2 255 204 153
4 8 2 255 204 153
5 8 2 255 204 153
6 8 2 255 204 153
7 8 2 255 204 153
8 8 2 255 204 153
-8 9 2 255 204 153
-7 9 2 255 204 153
-6 9 2 255 204 153
-5 9 2 255 204 153
-4 9 2 255 204 153
4 9 2 255 204 153
5 9 2 255 204 153
6 9 2 255 204 153
7 9 2 255 204 153
8 9 2 255 204 153
-8 -9 3 255 204 153
-7 -9 3 255 204 153
-6 -9 3 255 204 153
-5 -9 3 255 204 153
-4 -9 3 255 204 153
4 -9 3 255 204 153
5 -9 3 255 204 153
6 -9 3 255 204 153
7 -9 3 255 204 153
8 -9 3 255 204 153
-8 -8 3 255 204 153
-7 -8 3 255 204 153
-6 -8 3 255 204 153
-5 -8 3 255 204 153
-4 -8 3 255 204 153
4 -8 3 255 204 153
5 -8 3 255 204 153
6 -8 3 255 204 153
7 -8 3 255 204 153
8 -8 3 255 204 153
-8 -7 3 255 204 153
-7 -7 3 255 204 153
-6 -7 3 255 204 153
-5 -7 3 255 204 153
-4 -7 3 255 204 153
4 -7 3 255 204 153
5 -7 3 255 204 153
6 -7 3 255 204 153
7 -7 3 255 204 153
8 -7 3 255 204 153
-7 -6 3 255 204 153
-6 -6 3 255 204 153
-5 -6 3 255 204 153
-4 -6 3 255 204 153
4 -6 3 255 204 153
5 -6 3 255 204 153
6 -6 3 255 204 153
7 -6 3 255 204 153
-6 -5 3 255 204 153
6 -5 3 255 204 153
-7 -4 3 255 204 153
-6 -4 3 255 204 153
6 -4 3 255 204 153
7 -4 3 255 204 153
-8 -3 3 255 204 153
-7 -3 3 255 204 153
-6 -3 3 255 204 153
6 -3 3 255 204 153
7 -3 3 255 204 153
8 -3 3 255 204 153
-8 -2 3 255 204 153
-7 -2 3 255 204 153
-6 -2 3 255 204 153
6 -2 3 255 204 153
7 -2 3 255 204 153
8 -2 3 255 204 153
-8 -1 3 255 204 153
-7 -1 3 255 204 153
-6 -1 3 255 204 153
6 -1 3 255 204 153
7 -1 3 255 204 153
8 -1 3 255 204 153
-8 0 3 255 204 153
-7 0 3 255 204 153
-6 0 3 255 204 153
6 0 3 255 204 153
7 0 3 255 204 153
8 0 3 255 204 153
-8 1 3 255 204 153
-7 1 3 255 204 153
-6 1 3 255 204 153
6 1 3 255 204 153
7 1 3 255 204 153
8 1 3 255 204 153
-8 2 3 255 204 153
-7 2 3 255 204 153
-6 2 3 255 204 153
6 2 3 255 204 153
7 2 3 255 204 153
8 2 3 255 204 153
-8 3 3 255 204 153
-7 3 3 255 204 153
-6 3 3 255 204 153
6 3 3 255 204 153
7 3 3 255 204 153
8 3 3 255 204 153
-7 4 3 255 204 153
-6 4 3 255 204 153
6 4 3 255 204 153
7 4 3 255 204 153
-6 5 3 255 204 153
6 5 3 255 204 153
-7 6 3 255 204 153
-6 6 3 255 204 153
-5 6 3 255 204 153
-4 6 3 255 204 153
4 6 3 255 204 153
5 6 3 255 204 153
6 6 3 255 204 153
7 6 3 255 204 153
-8 7 3 255 204 153
-7 7 3 255 204 153
-6 7 3 255 204 153
-5 7 3 255 204 153
-4 7 3 255 204 153
4 7 3 255 204 153
5 7 3 255 204 153
6 7 3 255 204 153
7 7 3 255 204 153
8 7 3 255 204 153
-8 8 3 255 204 153
-7 8 3 255 204 153
-6 8 3 255 204 153
-5 8 3 255 204 153
-4 8 3 255 204 153
4 8 3 255 204 153
5 8 3 255 204 153
6 8 3 255 204 153
7 8 3 255 204 153
8 8 3 255 204 153
-8 9 3 255 204 153
-7 9 3 255 204 153
-6 9 3 255 204 153
-5 9 3 255 204 153
-4 9 3 255 204 153
4 9 3 255 204 153
5 9 3 255 204 153
6 9 3 255 204 153
7 9 3 255 204 153
8 9 3 255 204 153
-8 -9 4 255 204 153
-7 -9 4 255 204 153
-6 -9 4 255 204 153
-5 -9 4 255 204 153
-4 -9 4 255 204 153
4 -9 4 255 204 153
5 -9 4 255 204 153
6 -9 4 255 204 153
7 -9 4 255 204 153
8 -9 4 255 204 153
-8 -8 4 255 204 153
-7 -8 4 255 204 153
-6 -8 4 255 204 153
-5 -8 4 255 204 153
-4 -8 4 255 204 153
4 -8 4 255 204 153
5 -8 4 255 204 153
6 -8 4 255 204 153
7 -8 4 255 204 153
8 -8 4 255 204 153
-8 -7 4 255 204 153
-7 -7 4 255 204 153
-6 -7 4 255 204 153
-5 -7 4 255 204 153
-4 -7 4 255 204 153
4 -7 4 255 204 153
5 -7 4 255 204 153
6 -7 4 255 204 153
7 -7 4 255 204 153
8 -7 4 255 204 153
-8 -6 4 255 204 153
-7 -6 4 255 204 153
-6 -6 4 255 204 153
-5 -6 4 255 204 153
-4 -6 4 255 204 153
4 -6 4 255 204 153
5 -6 4 255 204 153
6 -6 4 255 204 153
7 -6 4 255 204 153
8 -6 4 255 204 153
-8 -5 4 255 204 153
-7 -5 4 255 204 153
-6 -5 4 255 204 153
6 -5 4 255 204 153
7 -5 4 255 204 153
8 -5 4 255 204 153
-8 -4 4 255 204 153
-7 -4 4 255 204 153
-6 -4 4 255 204 153
6 -4 4 255 204 153
7 -4 4 255 204 153
8 -4 4 255 204 153
-8 -3 4 255 204 153
-7 -3 4 255 204 153
-6 -3 4 255 204 153
6 -3 4 255 204 153
7 -3 4 255 204 153
8 -3 4 255 204 153
-8 -2 4 255 204 153
-7 -2 4 255 204 153
-6 -2 4 255 204 153
6 -2 4 255 204 153
7 -2 4 255 204 153
8 -2 4 255 204 153
-8 -1 4 255 204 153
-7 -1 4 255 204 153
-6 -1 4 255 204 153
6 -1 4 255 204 153
7 -1 4 255 204 153
8 -1 4 255 204 153
-8 0 4 255 204 153
-7 0 4 255 204 153
-6 0 4 255 204 153
6 0 4 255 204 153
7 0 4 255 204 153
8 0 4 255 204 153
-8 1 4 255 204 153
-7 1 4 255 204 153
-6 1 4 255 204 153
6 1 4 255 204 153
7 1 4 255 204 153
8 1 4 255 204 153
-8 2 4 255 204 153
-7 2 4 255 204 153
-6 2 4 255 204 153
6 2 4 255 204 153
7 2 4 255 204 153
8 2 4 255 204 153
-8 3 4 255 204 153
-7 3 4 255 204 153
-6 3 4 255 204 153
6 3 4 255 204 153
7 3 4 255 204 153
8 3 4 255 204 153
-8 4 4 255 204 153
-7 4 4 255 204 153
-6 4 4 255 204 153
6 4 4 255 204 153
7 4 4 255 204 153
8 4 4 255 204 153
-8 5 4 255 204 153
-7 5 4 255 204 153
-6 5 4 255 204 153
6 5 4 255 204 153
7 5 4 255 204 153
8 5 4 255 204 153
-8 6 4 255 204 153
-7 6 4 255 204 153
-6 6 4 255 204 153
-5 6 4 255 204 153
-4 6 4 255 204 153
4 6 4 255 204 153
5 6 4 255 204 153
6 6 4 255 204 153
7 6 4 255 204 153
8 6 4 255 204 153
-8 7 4 255 204 153
-7 7 4 255 204 153
-6 7 4 255 204 153
-5 7 4 255 204 153
-4 7 4 255 204 153
4 7 4 255 204 153
5 7 4 255 204 153
6 7 4 255 204 153
7 7 4 255 204 153
8 7 4 255 204 153
-8 8 4 255 204 153
-7 8 4 255 204 153
-6 8 4 255 204 153
-5 8 4 255 204 153
-4 8 4 255 204 153
4 8 4 255 204 153
5 8 4 255 204 153
6 8 4 255 204 153
7 8 4 255 204 153
8 8 4 255 204 153
-8 9 4 255 204 153
-7 9 4 255 204 153
-6 9 4 255 204 153
-5 9 4 255 204 153
-4 9 4 255 204 153
4 9 4 255 204 153
5 9 4 255 204 153
6 9 4 255 204 153
7 9 4 255 204 153
8 9 4 255 204 153
-8 -9 5 255 204 153
-7 -9 5 255 204 153
-6 -9 5 255 204 153
-5 -9 5 255 204 153
-4 -9 5 255 204 153
4 -9 5 255 204 153
5 -9 5 255 204 153
6 -9 5 255 204 153
7 -9 5 255 204 153
8 -9 5 255 204 153
-8 -8 5 255 204 153
-7 -8 5 255 204 153
-6 -8 5 255 204 153
-5 -8 5 255 204 153
-4 -8 5 255 204 153
4 -8 5 255 204 153
5 -8 5 255 204 153
6 -8 5 255 204 153
7 -8 5 255 204 153
8 -8 5 255 204 153
-8 -7 5 255 204 153
-7 -7 5 255 204 153
-6 -7 5 255 204 153
-5 -7 5 255 204 153
-4 -7 5 255 204 153
4 -7 5 255 204 153
5 -7 5 255 204 153
6 -7 5 255 204 153
7 -7 5 255 204 153
8 -7 5 255 204 153
-8 -6 5 255 204 153
-7 -6 5 255 204 153
-6 -6 5 255 204 153
-5 -6 5 255 204 153
-4 -6 5 255 204 153
4 -6 5 255 204 153
5 -6 5 255 204 153
6 -6 5 255 204 153
7 -6 5 255 204 153
8 -6 5 255 204 153
-8 -5 5 255 204 153
-7 -5 5 255 204 153
-6 -5 5 255 204 153
6 -5 5 255 204 153
7 -5 5 255 204 153
8 -5 5 255 204 153
-8 -4 5 255 204 153
-7 -4 5 255 204 153
-6 -4 5 255 204 153
6 -4 5 255 204 153
7 -4 5 255 204 153
8 -4 5 255 204 153
-8 -3 5 255 204 153
-7 -3 5 255 204 153
-6 -3 5 255 204 153
6 -3 5 255 204 153
7 -3 5 255 204 153
8 -3 5 255 204 153
-8 -2 5 255 204 153
-7 -2 5 255 204 153
-6 -2 5 255 204 153
6 -2 5 255 204 153
7 -2 5 255 204 153
8 -2 5 255 204 153
-8 -1 5 255 204 153
-7 -1 5 255 204 153
-6 -1 5 255 204 153
6 -1 5 255 204 153
7 -1 5 255 204 153
8 -1 5 255 204 153
-8 0 5 255 204 153
-7 0 5 255 204 153
-6 0 5 255 204 153
6 0 5 255 204 153
7 0 5 255 204 153
8 0 5 255 204 153
-8 1 5 255 204 153
-7 1 5 255 204 153
-6 1 5 255 204 153
6 1 5 255 204 153
7 1 5 255 204 153
8 1 5 255 204 153
-8 2 5 255 204 153
-7 2 5 255 204 153
-6 2 5 255 204 153
6 2 5 255 204 153
7 2 5 255 204 153
8 2 5 255 204 153
-8 3 5 255 204 153
-7 3 5 255 204 153
-6 3 5 255 204 153
6 3 5 255 204 153
7 3 5 255 204 153
8 3 5 255 204 153
-8 4 5 255 204 153
-7 4 5 255 204 153
-6 4 5 255 204 153
6 4 5 255 204 153
7 4 5 255 204 153
8 4 5 255 204 153
-8 5 5 255 204 153
-7 5 5 255 204 153
-6 5 5 255 204 153
6 5 5 255 204 153
7 5 5 255 204 153
8 5 5 255 204 153
-8 6 5 255 204 153
-7 6 5 255 204 153
-6 6 5 255 204 153
-5 6 5 255 204 153
-4 6 5 255 204 153
4 6 5 255 204 153
5 6 5 255 204 153
6 6 5 255 204 153
7 6 5 255 204 153
8 6 5 255 204 153
-8 7 5 255 204 153
-7 7 5 255 204 153
-6 7 5 255 204 153
-5 7 5 255 204 153
-4 7 5 255 204 153
4 7 5 255 204 153
5 7 5 255 204 153
6 7 5 255 204 153
7 7 5 255 204 153
8 7 5 255 204 153
-8 8 5 255 204 153
-7 8 5 255 204 153
-6 8 5 255 204 153
-5 8 5 255 204 153
-4 8 5 255 204 153
4 8 5 255 204 153
5 8 5 255 204 153
6 8 5 255 204 153
7 8 5 255 204 153
8 8 5 255 204 153
-8 9 5 255 204 153
-7 9 5 255 204 153
-6 9 5 255 204 153
-5 9 5 255 204 153
-4 9 5 255 204 153
4 9 5 255 204 153
5 9 5 255 204 153
6 9 5 255 204 153
7 9 5 255 204 153
8 9 5 255 204 153
-8 -9 6 255 204 153
-7 -9 6 255 204 153
-6 -9 6 255 204 153
-5 -9 6 255 204 153
-4 -9 6 255 204 153
4 -9 6 255 204 153
5 -9 6 255 204 153
6 -9 6 255 204 153
7 -9 6 255 204 153
8 -9 6 255 204 153
-8 -8 6 255 204 153
-7 -8 6 255 204 153
-6 -8 6 255 204 153
-5 -8 6 255 204 153
-4 -8 6 255 204 153
4 -8 6 255 204 153
5 -8 6 255 204 153
6 -8 6 255 204 153
7 -8 6 255 204 153
8 -8 6 255 204 153
-8 -7 6 255 204 153
-7 -7 6 255 204 153
-6 -7 6 255 204 153
-5 -7 6 255 204 153
-4 -7 6 255 204 153
4 -7 6 255 204 153
5 -7 6 255 204 153
6 -7 6 255 204 153
7 -7 6 255 204 153
8 -7 6 255 204 153
-8 -6 6 255 204 153
-7 -6 6 255 204 153
-6 -6 6 255 204 153
-5 -6 6 255 204 153
-4 -6 6 255 204 153
4 -6 6 255 204 153
5 -6 6 255 204 153
6 -6 6 255 204 153
7 -6 6 255 204 153
8 -6 6 255 204 153
-8 -5 6 255 204 153
-7 -5 6 255 204 153
-6 -5 6 255 204 153
6 -5 6 255 204 153
7 -5 6 255 204 153
8 -5 6 255 204 153
-8 -4 6 255 204 153
-7 -4 6 255 204 153
-6 -4 6 255 204 153
6 -4 6 255 204 153
7 -4 6 255 204 153
8 -4 6 255 204 153
-8 -3 6 255 204 153
-7 -3 6 255 204 153
-6 -3 6 255 204 153
6 -3 6 255 204 153
7 -3 6 255 204 153
8 -3 6 255 204 153
-8 -2 6 255 204 153
-7 -2 6 255 204 153
-6 -2 6 255 204 153
6 -2 6 255 204 153
7 -2 6 255 204 153
8 -2 6 255 204 153
-8 -1 6 255 204 153
-7 -1 6 255 204 153
-6 -1 6 255 204 153
6 -1 6 255 204 153
7 -1 6 255 204 153
8 -1 6 255 204 153
-8 0 6 255 204 153
-7 0 6 255 204 153
-6 0 6 255 204 153
6 0 6 255 204 153
7 0 6 255 204 153
8 0 6 255 204 153
-8 1 6 255 204 153
-7 1 6 255 204 153
-6 1 6 255 204 153
6 1 6 255 204 153
7 1 6 255 204 153
8 1 6 255 204 153
-8 2 6 255 204 153
-7 2 6 255 204 153
-6 2 6 255 204 153
6 2 6 255 204 153
7 2 6 255 204 153
8 2 6 255 204 153
-8 3 6 255 204 153
-7 3 6 255 204 153
-6 3 6 255 204 153
6 3 6 255 204 153
7 3 6 255 204 153
8 3 6 255 204 153
-8 4 6 255 204 153
-7 4 6 255 204 153
-6 4 6 255 204 153
6 4 6 255 204 153
7 4 6 255 204 153
8 4 6 255 204 153
-8 5 6 255 204 153
-7 5 6 255 204 153
-6 5 6 255 204 153
6 5 6 255 204 153
7 5 6 255 204 153
8 5 6 255 204 153
-8 6 6 255 204 153
-7 6 6 255 204 153
-6 6 6 255 204 153
-5 6 6 255 204 153
-4 6 6 255 204 153
4 6 6 255 204 153
5 6 6 255 204 153
6 6 6 255 204 153
7 6 6 255 204 153
8 6 6 255 204 153
-8 7 6 255 204 153
-7 7 6 255 204 153
-6 7 6 255 204 153
-5 7 6 255 204 153
-4 7 6 255 204 153
4 7 6 255 204 153
5 7 6 255 204 153
6 7 6 255 204 153
7 7 6 255 204 153
8 7 6 255 204 153
-8 8 6 255 204 153
-7 8 6 255 204 153
-6 8 6 255 204 153
-5 8 6 255 204 153
-4 8 6 255 204 153
4 8 6 255 204 153
5 8 6 255 204 153
6 8 6 255 204 153
7 8 6 255 204 153
8 8 6 255 204 153
-8 9 6 255 204 153
-7 9 6 255 204 153
-6 9 6 255 204 153
-5 9 6 255 204 153
-4 9 6 255 204 153
4 9 6 255 204 153
5 9 6 255 204 153
6 9 6 255 204 153
7 9 6 255 204 153
8 9 6 255 204 153
-8 -10 7 255 204 153
-7 -10 7 255 204 153
-6 -10 7 255 204 153
-5 -10 7 255 204 153
-4 -10 7 255 204 153
4 -10 7 255 204 153
5 -10 7 255 204 153
6 -10 7 255 204 153
7 -10 7 255 204 153
8 -10 7 255 204 153
-9 -9 7 255 204 153
-8 -9 7 255 204 153
-7 -9 7 255 204 153
-6 -9 7 255 204 153
-5 -9 7 255 204 153
-4 -9 7 255 204 153
-3 -9 7 255 204 153
3 -9 7 255 204 153
4 -9 7 255 204 153
5 -9 7 255 204 153
6 -9 7 255 204 153
7 -9 7 255 204 153
8 -9 7 255 204 153
9 -9 7 255 204 153
-9 -8 7 255 204 153
-8 -8 7 255 204 153
-7 -8 7 255 204 153
-6 -8 7 255 204 153
-5 -8 7 255 204 153
-4 -8 7 255 204 153
-3 -8 7 255 204 153
3 -8 7 255 204 153
4 -8 7 255 204 153
5 -8 7 255 204 153
6 -8 7 255 204 153
7 -8 7 255 204 153
8 -8 7 255 204 153
9 -8 7 255 204 153
-9 -7 7 255 204 153
-8 -7 7 255 204 153
-7 -7 7 255 204 153
-6 -7 7 255 204 153
-5 -7 7 255 204 153
-4 -7 7 255 204 153
-3 -7 7 255 204 153
3 -7 7 255 204 153
4 -7 7 255 204 153
5 -7 7 255 204 153
6 -7 7 255 204 153
7 -7 7 255 204 153
8 -7 7 255 204 153
9 -7 7 255 204 153
-9 -6 7 255 204 153
-8 -6 7 255 204 153
-7 -6 7 255 204 153
-6 -6 7 255 204 153
-5 -6 7 255 204 153
-4 -6 7 255 204 153
-3 -6 7 255 204 153
3 -6 7 255 204 153
4 -6 7 255 204 153
5 -6 7 255 204 153
6 -6 7 255 204 153
7 -6 7 255 204 153
8 -6 7 255 204 153
9 -6 7 255 204 153
-9 -5 7 255 204 153
-8 -5 7 255 204 153
-7 -5 7 255 204 153
-6 -5 7 255 204 153
6 -5 7 255 204 153
7 -5 7 255 204 153
8 -5 7 255 204 153
9 -5 7 255 204 153
-9 -4 7 255 204 153
-8 -4 7 255 204 153
-7 -4 7 255 204 153
-6 -4 7 255 204 153
6 -4 7 255 204 153
7 -4 7 255 204 153
8 -4 7 255 204 153
9 -4 7 255 204 153
-9 -3 7 255 204 153
-8 -3 7 255 204 153
-7 -3 7 255 204 153
-6 -3 7 255 204 153
6 -3 7 255 204 153
7 -3 7 255 204 153
8 -3 7 255 204 153
9 -3 7 255 204 153
-9 -2 7 255 204 153
-8 -2 7 255 204 153
-7 -2 7 255 204 153
-6 -2 7 255 204 153
6 -2 7 255 204 153
7 -2 7 255 204 153
8 -2 7 255 204 153
9 -2 7 255 204 153
-9 -1 7 255 204 153
-8 -1 7 255 204 153
-7 -1 7 255 204 153
-6 -1 7 255 204 153
6 -1 7 255 204 153
7 -1 7 255 204 153
8 -1 7 255 204 153
9 -1 7 255 204 153
-9 0 7 255 204 153
-8 0 7 255 204 153
-7 0 7 255 204 153
-6 0 7 255 204 153
6 0 7 255 204 153
7 0 7 255 204 153
8 0 7 255 204 153
9 0 7 255 204 153
-9 1 7 255 204 153
-8 1 7 255 204 153
-7 1 7 255 204 153
-6 1 7 255 204 153
6 1 7 255 204 153
7 1 7 255 204 153
8 1 7 255 204 153
9 1 7 255 204 153
-9 2 7 255 204 153
-8 2 7 255 204 153
-7 2 7 255 204 153
-6 2 7 255 204 153
6 2 7 255 204 153
7 2 7 255 204 153
8 2 7 255 204 153
9 2 7 255 204 153
-9 3 7 255 204 153
-8 3 7 255 204 153
-7 3 7 255 204 153
-6 3 7 255 204 153
6 3 7 255 204 153
7 3 7 255 204 153
8 3 7 255 204 153
9 3 7 255 204 153
-9 4 7 255 204 153
-8 4 7 255 204 153
-7 4 7 255 204 153
-6 4 7 255 204 153
6 4 7 255 204 153
7 4 7 255 204 153
8 4 7 255 204 153
9 4 7 255 204 153
-9 5 7 255 204 153
-8 5 7 255 204 153
-7 5 7 255 204 153
-6 5 7 255 204 153
6 5 7 255 204 153
7 5 7 255 204 153
8 5 7 255 204 153
9 5 7 255 204 153
-9 6 7 255 204 153
-8 6 7 255 204 153
-7 6 7 255 204 153
-6 6 7 255 204 153
-5 6 7 255 204 153
-4 6 7 255 204 153
-3 6 7 255 204 153
3 6 7 255 204 153
4 6 7 255 204 153
5 6 7 255 204 153
6 6 7 255 204 153
7 6 7 255 204 153
8 6 7 255 204 153
9 6 7 255 204 153
-9 7 7 255 204 153
-8 7 7 255 204 153
-7 7 7 255 204 153
-6 7 7 255 204 153
-5 7 7 255 204 153
-4 7 7 255 204 153
-3 7 7 255 204 153
3 7 7 255 204 153
4 7 7 255 204 153
5 7 7 255 204 153
6 7 7 255 204 153
7 7 7 255 204 153
8 7 7 255 204 153
9 7 7 255 204 153
-9 8 7 255 204 153
-8 8 7 255 204 153
-7 8 7 255 204 153
-6 8 7 255 204 153
-5 8 7 255 204 153
-4 8 7 255 204 153
-3 8 7 255 204 153
3 8 7 255 204 153
4 8 7 255 204 153
5 8 7 255 204 153
6 8 7 255 204 153
7 8 7 255 204 153
8 8 7 255 204 153
9 8 7 255 204 153
-9 9 7 255 204 153
-8 9 7 255 204 153
-7 9 7 255 204 153
-6 9 7 255 204 153
-5 9 7 255 204 153
-4 9 7 255 204 153
-3 9 7 255 204 153
3 9 7 255 204 153
4 9 7 255 204 153
5 9 7 255 204 153
6 9 7 255 204 153
7 9 7 255 204 153
8 9 7 255 204 153
9 9 7 255 204 153
-8 10 7 255 204 153
-7 10 7 255 204 153
-6 10 7 255 204 153
-5 10 7 255 204 153
-4 10 7 255 204 153
4 10 7 255 204 153
5 10 7 255 204 153
6 10 7 255 204 153
7 10 7 255 204 153
8 10 7 255 204 153
-8 -9 8 255 204 153
-7 -9 8 255 204 153
-6 -9 8 255 204 153
-5 -9 8 255 204 153
-4 -9 8 255 204 153
4 -9 8 255 204 153
5 -9 8 255 204 153
6 -9 8 255 204 153
7 -9 8 255 204 153
8 -9 8 255 204 153
-8 -8 8 255 204 153
-7 -8 8 255 204 153
-6 -8 8 255 204 153
-5 -8 8 255 204 153
-4 -8 8 255 204 153
4 -8 8 255 204 153
5 -8 8 255 204 153
6 -8 8 255 204 153
7 -8 8 255 204 153
8 -8 8 255 204 153
-8 -7 8 255 204 153
-7 -7 8 255 204 153
-6 -7 8 255 204 153
-5 -7 8 255 204 153
-4 -7 8 255 204 153
4 -7 8 255 204 153
5 -7 8 255 204 153
6 -7 8 255 204 153
7 -7 8 255 204 153
8 -7 8 255 204 153
-8 -6 8 255 204 153
-7 -6 8 255 204 153
-6 -6 8 255 204 153
-5 -6 8 255 204 153
-4 -6 8 255 204 153
4 -6 8 255 204 153
5 -6 8 255 204 153
6 -6 8 255 204 153
7 -6 8 255 204 153
8 -6 8 255 204 153
-8 -5 8 255 204 153
-7 -5 8 255 204 153
-6 -5 8 255 204 153
6 -5 8 255 204 153
7 -5 8 255 204 153
8 -5 8 255 204 153
-8 -4 8 255 204 153
-7 -4 8 255 204 153
-6 -4 8 255 204 153
6 -4 8 255 204 153
7 -4 8 255 204 153
8 -4 8 255 204 153
-8 -3 8 255 204 153
-7 -3 8 255 204 153
-6 -3 8 255 204 153
6 -3 8 255 204 153
7 -3 8 255 204 153
8 -3 8 255 204 153
-8 -2 8 255 204 153
-7 -2 8 255 204 153
-6 -2 8 255 204 153
6 -2 8 255 204 153
7 -2 8 255 204 153
8 -2 8 255 204 153
-8 -1 8 255 204 153
-7 -1 8 255 204 153
-6 -1 8 255 204 153
6 -1 8 255 204 153
7 -1 8 255 204 153
8 -1 8 255 204 153
-8 0 8 255 204 153
-7 0 8 255 204 153
-6 0 8 255 204 153
6 0 8 255 204 153
7 0 8 255 204 153
8 0 8 255 204 153
-8 1 8 255 204 153
-7 1 8 255 204 153
-6 1 8 255 204 153
6 1 8 255 204 153
7 1 8 255 204 153
8 1 8 255 204 153
-8 2 8 255 204 153
-7 2 8 255 204 153
-6 2 8 255 204 153
6 2 8 255 204 153
7 2 8 255 204 153
8 2 8 255 204 153
-8 3 8 255 204 153
-7 3 8 255 204 153
-6 3 8 255 204 153
6 3 8 255 204 153
7 3 8 255 204 153
8 3 8 255 204 153
-8 4 8 255 204 153
-7 4 8 255 204 153
-6 4 8 255 204 153
6 4 8 255 204 153
7 4 8 255 204 153
8 4 8 255 204 153
-8 5 8 255 204 153
-7 5 8 255 204 153
-6 5 8 255 204 153
6 5 8 255 204 153
7 5 8 255 204 153
8 5 8 255 204 153
-8 6 8 255 204 153
-7 6 8 255 204 153
-6 6 8 255 204 153
-5 6 8 255 204 153
-4 6 8 255 204 153
4 6 8 255 204 153
5 6 8 255 204 153
6 6 8 255 204 153
7 6 8 255 204 153
8 6 8 255 204 153
-8 7 8 255 204 153
-7 7 8 255 204 153
-6 7 8 255 204 153
-5 7 8 255 204 153
-4 7 8 255 204 153
4 7 8 255 204 153
5 7 8 255 204 153
6 7 8 255 204 153
7 7 8 255 204 153
8 7 8 255 204 153
-8 8 8 255 204 153
-7 8 8 255 204 153
-6 8 8 255 204 153
-5 8 8 255 204 153
-4 8 8 255 204 153
4 8 8 255 204 153
5 8 8 255 204 153
6 8 8 255 204 153
7 8 8 255 204 153
8 8 8 255 204 153
-8 9 8 255 204 153
-7 9 8 255 204 153
-6 9 8 255 204 153
-5 9 8 255 204 153
-4 9 8 255 204 153
4 9 8 255 204 153
5 9 8 255 204 153
6 9 8 255 204 153
7 9 8 255 204 153
8 9 8 255 204 153
-8 -9 9 255 204 153
-7 -9 9 255 204 153
-6 -9 9 255 204 153
-5 -9 9 255 204 153
-4 -9 9 255 204 153
-3 -9 9 255 204 153
3 -9 9 255 204 153
4 -9 9 255 204 153
5 -9 9 255 204 153
6 -9 9 255 204 153
7 -9 9 255 204 153
8 -9 9 255 204 153
-8 -8 9 255 204 153
-7 -8 9 255 204 153
-6 -8 9 255 204 153
-5 -8 9 255 204 153
-4 -8 9 255 204 153
-3 -8 9 255 204 153
-2 -8 9 255 204 153
2 -8 9 255 204 153
3 -8 9 255 204 153
4 -8 9 255 204 153
5 -8 9 255 204 153
6 -8 9 255 204 153
7 -8 9 255 204 153
8 -8 9 255 204 153
-8 -7 9 255 204 153
-7 -7 9 255 204 153
-6 -7 9 255 204 153
-5 -7 9 255 204 153
-4 -7 9 255 204 153
-3 -7 9 255 204 153
-2 -7 9 255 204 153
-1 -7 9 255 204 153
0 -7 9 255 204 153
1 -7 9 255 204 153
2 -7 9 255 204 153
3 -7 9 255 204 153
4 -7 9 255 204 153
5 -7 9 255 204 153
6 -7 9 255 204 153
7 -7 9 255 204 153
8 -7 9 255 204 153
-8 -6 9 255 204 153
-7 -6 9 255 204 153
-6 -6 9 255 204 153
-5 -6 9 255 204 153
-4 -6 9 255 204 153
-3 -6 9 255 204 153
-2 -6 9 255 204 153
-1 -6 9 255 204 153
0 -6 9 255 204 153
1 -6 9 255 204 153
2 -6 9 255 204 153
3 -6 9 255 204 153
4 -6 9 255 204 153
5 -6 9 255 204 153
6 -6 9 255 204 153
7 -6 9 255 204 153
8 -6 9 255 204 153
-8 -5 9 255 204 153
-7 -5 9 255 204 153
-6 -5 9 255 204 153
6 -5 9 255 204 153
7 -5 9 255 204 153
8 -5 9 255 204 153
-8 -4 9 255 204 153
-7 -4 9 255 204 153
-6 -4 9 255 204 153
6 -4 9 255 204 153
7 -4 9 255 204 153
8 -4 9 255 204 153
-8 -3 9 255 204 153
-7 -3 9 255 204 153
-6 -3 9 255 204 153
6 -3 9 255 204 153
7 -3 9 255 204 153
8 -3 9 255 204 153
-8 -2 9 255 204 153
-7 -2 9 255 204 153
-6 -2 9 255 204 153
6 -2 9 255 204 153
7 -2 9 255 204 153
8 -2 9 255 204 153
-8 -1 9 255 204 153
-7 -1 9 255 204 153
-6 -1 9 255 204 153
6 -1 9 255 204 153
7 -1 9 255 204 153
8 -1 9 255 204 153
-8 0 9 255 204 153
-7 0 9 255 204 153
-6 0 9 255 204 153
6 0 9 255 204 153
7 0 9 255 204 153
8 0 9 255 204 153
-8 1 9 255 204 153
-7 1 9 255 204 153
-6 1 9 255 204 153
6 1 9 255 204 153
7 1 9 255 204 153
8 1 9 255 204 153
-8 2 9 255 204 153
-7 2 9 255 204 153
-6 2 9 255 204 153
6 2 9 255 204 153
7 2 9 255 204 153
8 2 9 255 204 153
-8 3 9 255 204 153
-7 3 9 255 204 153
-6 3 9 255 204 153
6 3 9 255 204 153
7 3 9 255 204 153
8 3 9 255 204 153
-8 4 9 255 204 153
-7 4 9 255 204 153
-6 4 9 255 204 153
6 4 9 255 204 153
7 4 9 255 204 153
8 4 9 255 204 153
-8 5 9 255 204 153
-7 5 9 255 204 153
-6 5 9 255 204 153
6 5 9 255 204 153
7 5 9 255 204 153
8 5 9 255 204 153
-8 6 9 255 204 153
-7 6 9 255 204 153
-6 6 9 255 204 153
-5 6 9 255 204 153
-4 6 9 255 204 153
-3 6 9 255 204 153
-2 6 9 255 204 153
-1 6 9 255 204 153
0 6 9 255 204 153
1 6 9 255 204 153
2 6 9 255 204 153
3 6 9 255 204 153
4 6 9 255 204 153
5 6 9 255 204 153
6 6 9 255 204 153
7 6 9 255 204 153
8 6 9 255 204 153
-8 7 9 255 204 153
-7 7 9 255 204 153
-6 7 9 255 204 153
-5 7 9 255 204 153
-4 7 9 255 204 153
-3 7 9 255 204 153
-2 7 9 255 204 153
-1 7 9 255 204 153
0 7 9 255 204 153
1 7 9 255 204 153
2 7 9 255 204 153
3 7 9 255 204 153
4 7 9 255 204 153
5 7 9 255 204 153
6 7 9 255 204 153
7 7 9 255 204 153
8 7 9 255 204 153
-8 8 9 255 204 153
-7 8 9 255 204 153
-6 8 9 255 204 153
-5 8 9 255 204 153
-4 8 9 255 204 153
-3 8 9 255 204 153
-2 8 9 255 204 153
2 8 9 255 204 153
3 8 9 255 204 153
4 8 9 255 204 153
5 8 9 255 204 153
6 8 9 255 204 153
7 8 9 255 204 153
8 8 9 255 204 153
-8 9 9 255 204 153
-7 9 9 255 204 153
-6 9 9 255 204 153
-5 9 9 255 204 153
-4 9 9 255 204 153
-3 9 9 255 204 153
3 9 9 255 204 153
4 9 9 255 204 153
5 9 9 255 204 153
6 9 9 255 204 153
7 9 9 255 204 153
8 9 9 255 204 153
-8 -9 10 255 204 153
-7 -9 10 255 204 153
-6 -9 10 255 204 153
-5 -9 10 255 204 153
-4 -9 10 255 204 153
-3 -9 10 255 204 153
-2 -9 10 255 204 153
2 -9 10 255 204 153
3 -9 10 255 204 153
4 -9 10 255 204 153
5 -9 10 255 204 153
6 -9 10 255 204 153
7 -9 10 255 204 153
8 -9 10 255 204 153
-8 -8 10 255 204 153
-7 -8 10 255 204 153
-6 -8 10 255 204 153
-5 -8 10 255 204 153
-4 -8 10 255 204 153
-3 -8 10 255 204 153
-2 -8 10 255 204 153
-1 -8 10 255 204 153
0 -8 10 255 204 153
1 -8 10 255 204 153
2 -8 10 255 204 153
3 -8 10 255 204 153
4 -8 10 255 204 153
5 -8 10 255 204 153
6 -8 10 255 204 153
7 -8 10 255 204 153
8 -8 10 255 204 153
-8 -7 10 255 204 153
-7 -7 10 255 204 153
-6 -7 10 255 204 153
-5 -7 10 255 204 153
-4 -7 10 255 204 153
-3 -7 10 255 204 153
-2 -7 10 255 204 153
-1 -7 10 255 204 153
0 -7 10 255 204 153
1 -7 10 255 204 153
2 -7 10 255 204 153
3 -7 10 255 204 153
4 -7 10 255 204 153
5 -7 10 255 204 153
6 -7 10 255 204 153
7 -7 10 255 204 153
8 -7 10 255 204 153
-8 -6 10 255 204 153
-7 -6 10 255 204 153
-6 -6 10 255 204 153
-5 -6 10 255 204 153
-4 -6 10 255 204 153
-3 -6 10 255 204 153
-2 -6 10 255 204 153
-1 -6 10 255 204 153
0 -6 10 255 204 153
1 -6 10 255 204 153
2 -6 10 255 204 153
3 -6 10 255 204 153
4 -6 10 255 204 153
5 -6 10 255 204 153
6 -6 10 255 204 153
7 -6 10 255 204 153
8 -6 10 255 204 153
-8 -5 10 255 204 153
-7 -5 10 255 204 153
-6 -5 10 255 204 153
6 -5 10 255 204 153
7 -5 10 255 204 153
8 -5 10 255 204 153
-8 -4 10 255 204 153
-7 -4 10 255 204 153
-6 -4 10 255 204 153
6 -4 10 255 204 153
7 -4 10 255 204 153
8 -4 10 255 204 153
-8 -3 10 255 204 153
-7 -3 10 255 204 153
-6 -3 10 255 204 153
6 -3 10 255 204 153
7 -3 10 255 204 153
8 -3 10 255 204 153
-8 -2 10 255 204 153
-7 -2 10 255 204 153
-6 -2 10 255 204 153
6 -2 10 255 204 153
7 -2 10 255 204 153
8 -2 10 255 204 153
-8 -1 10 255 204 153
-7 -1 10 255 204 153
-6 -1 10 255 204 153
6 -1 10 255 204 153
7 -1 10 255 204 153
8 -1 10 255 204 153
-8 0 10 255 204 153
-7 0 10 255 204 153
-6 0 10 255 204 153
6 0 10 255 204 153
7 0 10 255 204 153
8 0 10 255 204 153
-8 1 10 255 204 153
-7 1 10 255 204 153
-6 1 10 255 204 153
6 1 10 255 204 153
7 1 10 255 204 153
8 1 10 255 204 153
-8 2 10 255 204 153
-7 2 10 255 204 153
-6 2 10 255 204 153
6 2 10 255 204 153
7 2 10 255 204 153
8 2 10 255 204 153
-8 3 10 255 204 153
-7 3 10 255 204 153
-6 3 10 255 204 153
6 3 10 255 204 153
7 3 10 255 204 153
8 3 10 255 204 153
-8 4 10 255 204 153
-7 4 10 255 204 153
-6 4 10 255 204 153
6 4 10 255 204 153
7 4 10 255 204 153
8 4 10 255 204 153
-8 5 10 255 204 153
-7 5 10 255 204 153
-6 5 10 255 204 153
6 5 10 255 204 153
7 5 10 255 204 153
8 5 10 255 204 153
-8 6 10 255 204 153
-7 6 10 255 204 153
-6 6 10 255 204 153
-5 6 10 255 204 153
-4 6 10 255 204 153
-3 6 10 255 204 153
-2 6 10 255 204 153
-1 6 10 255 204 153
0 6 10 255 204 153
1 6 10 255 204 153
2 6 10 255 204 153
3 6 10 255 204 153
4 6 10 255 204 153
5 6 10 255 204 153
6 6 10 255 204 153
7 6 10 255 204 153
8 6 10 255 204 153
-8 7 10 255 204 153
-7 7 10 255 204 153
-6 7 10 255 204 153
-5 7 10 255 204 153
-4 7 10 255 204 153
-3 7 10 255 204 153
-2 7 10 255 204 153
-1 7 10 255 204 153
0 7 10 255 204 153
1 7 10 255 204 153
2 7 10 255 204 153
3 7 10 255 204 153
4 7 10 255 204 153
5 7 10 255 204 153
6 7 10 255 204 153
7 7 10 255 204 153
8 7 10 255 204 153
-8 8 10 255 204 153
-7 8 10 255 204 153
-6 8 10 255 204 153
-5 8 10 255 204 153
-4 8 10 255 204 153
-3 8 10 255 204 153
-2 8 10 255 204 153
-1 8 10 255 204 153
0 8 10 255 204 153
1 8 10 255 204 153
2 8 10 255 204 153
3 8 10 255 204 153
4 8 10 255 204 153
5 8 10 255 204 153
6 8 10 255 204 153
7 8 10 255 204 153
8 8 10 255 204 153
-8 9 10 255 204 153
-7 9 10 255 204 153
-6 9 10 255 204 153
-5 9 10 255 204 153
-4 9 10 255 204 153
-3 9 10 255 204 153
-2 9 10 255 204 153
2 9 10 255 204 153
3 9 10 255 204 153
4 9 10 255 204 153
5 9 10 255 204 153
6 9 10 255 204 153
7 9 10 255 204 153
8 9 10 255 204 153
-8 -9 11 255 204 153
-6 -9 11 255 204 153
-4 -9 11 255 204 153
-3 -9 11 255 204 153
-2 -9 11 255 204 153
-1 -9 11 255 204 153
0 -9 11 255 204 153
1 -9 11 255 204 153
2 -9 11 255 204 153
3 -9 11 255 204 153
4 -9 11 255 204 153
6 -9 11 255 204 153
8 -9 11 255 204 153
-8 -8 11 255 204 153
-7 -8 11 255 204 153
-6 -8 11 255 204 153
-5 -8 11 255 204 153
-4 -8 11 255 204 153
-3 -8 11 255 204 153
-2 -8 11 255 204 153
-1 -8 11 255 204 153
0 -8 11 255 204 153
1 -8 11 255 204 153
2 -8 11 255 204 153
3 -8 11 255 204 153
4 -8 11 255 204 153
5 -8 11 255 204 153
6 -8 11 255 204 153
7 -8 11 255 204 153
8 -8 11 255 204 153
-7 -7 11 255 204 153
-6 -7 11 255 204 153
-5 -7 11 255 204 153
-4 -7 11 255 204 153
-3 -7 11 255 204 153
-2 -7 11 255 204 153
-1 -7 11 255 204 153
0 -7 11 255 204 153
1 -7 11 255 204 153
2 -7 11 255 204 153
3 -7 11 255 204 153
4 -7 11 255 204 153
5 -7 11 255 204 153
6 -7 11 255 204 153
7 -7 11 255 204 153
-8 -6 11 255 204 153
-7 -6 11 255 204 153
-6 -6 11 255 204 153
-5 -6 11 255 204 153
-4 -6 11 255 204 153
-3 -6 11 255 204 153
-2 -6 11 255 204 153
-1 -6 11 255 204 153
0 -6 11 255 204 153
1 -6 11 255 204 153
2 -6 11 255 204 153
3 -6 11 255 204 153
4 -6 11 255 204 153
5 -6 11 255 204 153
6 -6 11 255 204 153
7 -6 11 255 204 153
8 -6 11 255 204 153
-7 -5 11 255 204 153
-6 -5 11 255 204 153
6 -5 11 255 204 153
7 -5 11 255 204 153
-8 -4 11 255 204 153
-7 -4 11 255 204 153
-6 -4 11 255 204 153
6 -4 11 255 204 153
7 -4 11 255 204 153
8 -4 11 255 204 153
-7 -3 11 255 204 153
-6 -3 11 255 204 153
6 -3 11 255 204 153
7 -3 11 255 204 153
-8 -2 11 255 204 153
-7 -2 11 255 204 153
-6 -2 11 255 204 153
6 -2 11 255 204 153
7 -2 11 255 204 153
8 -2 11 255 204 153
-7 -1 11 255 204 153
-6 -1 11 255 204 153
6 -1 11 255 204 153
7 -1 11 255 204 153
-8 0 11 255 204 153
-7 0 11 255 204 153
-6 0 11 255 204 153
6 0 11 255 204 153
7 0 11 255 204 153
8 0 11 255 204 153
-7 1 11 255 204 153
-6 1 11 255 204 153
6 1 11 255 204 153
7 1 11 255 204 153
-8 2 11 255 204 153
-7 2 11 255 204 153
-6 2 11 255 204 153
6 2 11 255 204 153
7 2 11 255 204 153
8 2 11 255 204 153
-7 3 11 255 204 153
-6 3 11 255 204 153
6 3 11 255 204 153
7 3 11 255 204 153
-8 4 11 255 204 153
-7 4 11 255 204 153
-6 4 11 255 204 153
6 4 11 255 204 153
7 4 11 255 204 153
8 4 11 255 204 153
-7 5 11 255 204 153
-6 5 11 255 204 153
6 5 11 255 204 153
7 5 11 255 204 153
-8 6 11 255 204 153
-7 6 11 255 204 153
-6 6 11 255 204 153
-5 6 11 255 204 153
-4 6 11 255 204 153
-3 6 11 255 204 153
-2 6 11 255 204 153
-1 6 11 255 204 153
0 6 11 255 204 153
1 6 11 255 204 153
2 6 11 255 204 153
3 6 11 255 204 153
4 6 11 255 204 153
5 6 11 255 204 153
6 6 11 255 204 153
7 6 11 255 204 153
8 6 11 255 204 153
-7 7 11 255 204 153
-6 7 11 255 204 153
-5 7 11 255 204 153
-4 7 11 255 204 153
-3 7 11 255 204 153
-2 7 11 255 204 153
-1 7 11 255 204 153
0 7 11 255 204 153
1 7 11 255 204 153
2 7 11 255 204 153
3 7 11 255 204 153
4 7 11 255 204 153
5 7 11 255 204 153
6 7 11 255 204 153
7 7 11 255 204 153
-8 8 11 255 204 153
-7 8 11 255 204 153
-6 8 11 255 204 153
-5 8 11 255 204 153
-4 8 11 255 204 153
-3 8 11 255 204 153
-2 8 11 255 204 153
-1 8 11 255 204 153
0 8 11 255 204 153
1 8 11 255 204 153
2 8 11 255 204 153
3 8 11 255 204 153
4 8 11 255 204 153
5 8 11 255 204 153
6 8 11 255 204 153
7 8 11 255 204 153
8 8 11 255 204 153
-8 9 11 255 204 153
-6 9 11 255 204 153
-4 9 11 255 204 153
-3 9 11 255 204 153
-2 9 11 255 204 153
-1 9 11 255 204 153
0 9 11 255 204 153
1 9 11 255 204 153
2 9 11 255 204 153
3 9 11 255 204 153
4 9 11 255 204 153
6 9 11 255 204 153
8 9 11 255 204 153
-8 -9 12 255 204 153
-7 -9 12 255 204 153
-6 -9 12 255 204 153
-5 -9 12 255 204 153
-4 -9 12 255 204 153
-3 -9 12 255 204 153
-2 -9 12 255 204 153
-1 -9 12 255 204 153
0 -9 12 255 204 153
1 -9 12 255 204 153
2 -9 12 255 204 153
3 -9 12 255 204 153
4 -9 12 255 204 153
5 -9 12 255 204 153
6 -9 12 255 204 153
7 -9 12 255 204 153
8 -9 12 255 204 153
-8 -8 12 255 204 153
-7 -8 12 255 204 153
-6 -8 12 255 204 153
-5 -8 12 255 204 153
-4 -8 12 255 204 153
-3 -8 12 255 204 153
-2 -8 12 255 204 153
-1 -8 12 255 204 153
0 -8 12 255 204 153
1 -8 12 255 204 153
2 -8 12 255 204 153
3 -8 12 255 204 153
4 -8 12 255 204 153
5 -8 12 255 204 153
6 -8 12 255 204 153
7 -8 12 255 204 153
8 -8 12 255 204 153
-8 -7 12 255 204 153
-7 -7 12 255 204 153
-6 -7 12 255 204 153
-5 -7 12 255 204 153
-4 -7 12 255 204 153
-3 -7 12 255 204 153
-2 -7 12 255 204 153
-1 -7 12 255 204 153
0 -7 12 255 204 153
1 -7 12 255 204 153
2 -7 12 255 204 153
3 -7 12 255 204 153
4 -7 12 255 204 153
5 -7 12 255 204 153
6 -7 12 255 204 153
7 -7 12 255 204 153
8 -7 12 255 204 153
-8 -6 12 255 204 153
-7 -6 12 255 204 153
-6 -6 12 255 204 153
-5 -6 12 255 204 153
-4 -6 12 255 204 153
-2 -6 12 255 204 153
-1 -6 12 255 204 153
0 -6 12 255 204 153
1 -6 12 255 204 153
2 -6 12 255 204 153
4 -6 12 255 204 153
5 -6 12 255 204 153
6 -6 12 255 204 153
7 -6 12 255 204 153
8 -6 12 255 204 153
-8 -5 12 255 204 153
-7 -5 12 255 204 153
-6 -5 12 255 204 153
6 -5 12 255 204 153
7 -5 12 255 204 153
8 -5 12 255 204 153
-8 -4 12 255 204 153
-7 -4 12 255 204 153
-6 -4 12 255 204 153
6 -4 12 255 204 153
7 -4 12 255 204 153
8 -4 12 255 204 153
-8 -3 12 255 204 153
-7 -3 12 255 204 153
7 -3 12 255 204 153
8 -3 12 255 204 153
-8 -2 12 255 204 153
-7 -2 12 255 204 153
-6 -2 12 255 204 153
6 -2 12 255 204 153
7 -2 12 255 204 153
8 -2 12 255 204 153
-8 -1 12 255 204 153
-7 -1 12 255 204 153
-6 -1 12 255 204 153
6 -1 12 255 204 153
7 -1 12 255 204 153
8 -1 12 255 204 153
-8 0 12 255 204 153
-7 0 12 255 204 153
-6 0 12 255 204 153
6 0 12 255 204 153
7 0 12 255 204 153
8 0 12 255 204 153
-8 1 12 255 204 153
-7 1 12 255 204 153
-6 1 12 255 204 153
6 1 12 255 204 153
7 1 12 255 204 153
8 1 12 255 204 153
-8 2 12 255 204 153
-7 2 12 255 204 153
-6 2 12 255 204 153
6 2 12 255 204 153
7 2 12 255 204 153
8 2 12 255 204 153
-8 3 12 255 204 153
-7 3 12 255 204 153
7 3 12 255 204 153
8 3 12 255 204 153
-8 4 12 255 204 153
-7 4 12 255 204 153
-6 4 12 255 204 153
6 4 12 255 204 153
7 4 12 255 204 153
8 4 12 255 204 153
-8 5 12 255 204 153
-7 5 12 255 204 153
-6 5 12 255 204 153
6 5 12 255 204 153
7 5 12 255 204 153
8 5 12 255 204 153
-8 6 12 255 204 153
-7 6 12 255 204 153
-6 6 12 255 204 153
-5 6 12 255 204 153
-4 6 12 255 204 153
-2 6 12 255 204 153
-1 6 12 255 204 153
0 6 12 255 204 153
1 6 12 255 204 153
2 6 12 255 204 153
4 6 12 255 204 153
5 6 12 255 204 153
6 6 12 255 204 153
7 6 12 255 204 153
8 6 12 255 204 153
-8 7 12 255 204 153
-7 7 12 255 204 153
-6 7 12 255 204 153
-5 7 12 255 204 153
-4 7 12 255 204 153
-3 7 12 255 204 153
-2 7 12 255 204 153
-1 7 12 255 204 153
0 7 12 255 204 153
1 7 12 255 204 153
2 7 12 255 204 153
3 7 12 255 204 153
4 7 12 255 204 153
5 7 12 255 204 153
6 7 12 255 204 153
7 7 12 255 204 153
8 7 12 255 204 153
-8 8 12 255 204 153
-7 8 12 255 204 153
-6 8 12 255 204 153
-5 8 12 255 204 153
-4 8 12 255 204 153
-3 8 12 255 204 153
-2 8 12 255 204 153
-1 8 12 255 204 153
0 8 12 255 204 153
1 8 12 255 204 153
2 8 12 255 204 153
3 8 12 255 204 153
4 8 12 255 204 153
5 8 12 255 204 153
6 8 12 255 204 153
7 8 12 255 204 153
8 8 12 255 204 153
-8 9 12 255 204 153
-7 9 12 255 204 153
-6 9 12 255 204 153
-5 9 12 255 204 153
-4 9 12 255 204 153
-3 9 12 255 204 153
-2 9 12 255 204 153
-1 9 12 255 204 153
0 9 12 255 204 153
1 9 12 255 204 153
2 9 12 255 204 153
3 9 12 255 204 153
4 9 12 255 204 153
5 9 12 255 204 153
6 9 12 255 204 153
7 9 12 255 204 153
8 9 12 255 204 153
-9 -10 13 255 204 153
-8 -10 13 255 204 153
-7 -10 13 255 204 153
-6 -10 13 255 204 153
-5 -10 13 255 204 153
-4 -10 13 255 204 153
-3 -10 13 255 204 153
-2 -10 13 255 204 153
-1 -10 13 255 204 153
0 -10 13 255 204 153
1 -10 13 255 204 153
2 -10 13 255 204 153
3 -10 13 255 204 153
4 -10 13 255 204 153
5 -10 13 255 204 153
6 -10 13 255 204 153
7 -10 13 255 204 153
8 -10 13 255 204 153
9 -10 13 255 204 153
-9 -9 13 255 204 153
-8 -9 13 255 204 153
-7 -9 13 255 204 153
7 -9 13 255 204 153
8 -9 13 255 204 153
9 -9 13 255 204 153
-9 -8 13 255 204 153
-8 -8 13 255 204 153
-7 -8 13 255 204 153
7 -8 13 255 204 153
8 -8 13 255 204 153
9 -8 13 255 204 153
-9 -7 13 255 204 153
-8 -7 13 255 204 153
-7 -7 13 255 204 153
7 -7 13 255 204 153
8 -7 13 255 204 153
9 -7 13 255 204 153
-9 -6 13 255 204 153
-6 -6 13 255 204 153
-5 -6 13 255 204 153
-4 -6 13 255 204 153
-3 -6 13 255 204 153
-2 -6 13 255 204 153
-1 -6 13 255 204 153
0 -6 13 255 204 153
1 -6 13 255 204 153
2 -6 13 255 204 153
3 -6 13 255 204 153
4 -6 13 255 204 153
5 -6 13 255 204 153
6 -6 13 255 204 153
9 -6 13 255 204 153
-9 -5 13 255 204 153
-6 -5 13 255 204 153
6 -5 13 255 204 153
9 -5 13 255 204 153
-9 -4 13 255 204 153
-6 -4 13 255 204 153
6 -4 13 255 204 153
9 -4 13 255 204 153
-9 -3 13 255 204 153
-6 -3 13 255 204 153
6 -3 13 255 204 153
9 -3 13 255 204 153
-9 -2 13 255 204 153
-6 -2 13 255 204 153
6 -2 13 255 204 153
9 -2 13 255 204 153
-9 -1 13 255 204 153
-6 -1 13 255 204 153
6 -1 13 255 204 153
9 -1 13 255 204 153
-9 0 13 255 204 153
-6 0 13 255 204 153
6 0 13 255 204 153
9 0 13 255 204 153
-9 1 13 255 204 153
-6 1 13 255 204 153
6 1 13 255 204 153
9 1 13 255 204 153
-9 2 13 255 204 153
-6 2 13 255 204 153
6 2 13 255 204 153
9 2 13 255 204 153
-9 3 13 255 204 153
-6 3 13 255 204 153
6 3 13 255 204 153
9 3 13 255 204 153
-9 4 13 255 204 153
-6 4 13 255 204 153
6 4 13 255 204 153
9 4 13 255 204 153
-9 5 13 255 204 153
-6 5 13 255 204 153
6 5 13 255 204 153
9 5 13 255 204 153
-9 6 13 255 204 153
-6 6 13 255 204 153
-5 6 13 255 204 153
-4 6 13 255 204 153
-3 6 13 255 204 153
-2 6 13 255 204 153
-1 6 13 255 204 153
0 6 13 255 204 153
1 6 13 255 204 153
2 6 13 255 204 153
3 6 13 255 204 153
4 6 13 255 204 153
5 6 13 255 204 153
6 6 13 255 204 153
9 6 13 255 204 153
-9 7 13 255 204 153
-8 7 13 255 204 153
-7 7 13 255 204 153
7 7 13 255 204 153
8 7 13 255 204 153
9 7 13 255 204 153
-9 8 13 255 204 153
-8 8 13 255 204 153
-7 8 13 255 204 153
7 8 13 255 204 153
8 8 13 255 204 153
9 8 13 255 204 153
-9 9 13 255 204 153
-8 9 13 255 204 153
-7 9 13 255 204 153
7 9 13 255 204 153
8 9 13 255 204 153
9 9 13 255 204 153
-9 10 13 255 204 153
-8 10 13 255 204 153
-7 10 13 255 204 153
-6 10 13 255 204 153
-5 10 13 255 204 153
-4 10 13 255 204 153
-3 10 13 255 204 153
-2 10 13 255 204 153
-1 10 13 255 204 153
0 10 13 255 204 153
1 10 13 255 204 153
2 10 13 255 204 153
3 10 13 255 204 153
4 10 13 255 204 153
5 10 13 255 204 153
6 10 13 255 204 153
7 10 13 255 204 153
8 10 13 255 204 153
9 10 13 255 204 153
-8 -10 14 255 204 153
-6 -10 14 255 204 153
-4 -10 14 255 204 153
-2 -10 14 255 204 153
0 -10 14 255 204 153
2 -10 14 255 204 153
4 -10 14 255 204 153
6 -10 14 255 204 153
8 -10 14 255 204 153
-9 -9 14 255 204 153
-8 -9 14 255 204 153
-7 -9 14 255 204 153
7 -9 14 255 204 153
8 -9 14 255 204 153
9 -9 14 255 204 153
-9 -8 14 255 204 153
-8 -8 14 255 204 153
-7 -8 14 255 204 153
7 -8 14 255 204 153
8 -8 14 255 204 153
9 -8 14 255 204 153
-9 -7 14 255 204 153
-8 -7 14 255 204 153
-7 -7 14 255 204 153
7 -7 14 255 204 153
8 -7 14 255 204 153
9 -7 14 255 204 153
-6 -6 14 255 204 153
-4 -6 14 255 204 153
-2 -6 14 255 204 153
0 -6 14 255 204 153
2 -6 14 255 204 153
4 -6 14 255 204 153
6 -6 14 255 204 153
-9 -5 14 255 204 153
9 -5 14 255 204 153
-6 -4 14 255 204 153
6 -4 14 255 204 153
-9 -3 14 255 204 153
9 -3 14 255 204 153
-6 -2 14 255 204 153
6 -2 14 255 204 153
-9 -1 14 255 204 153
9 -1 14 255 204 153
-6 0 14 255 204 153
6 0 14 255 204 153
-9 1 14 255 204 153
9 1 14 255 204 153
-6 2 14 255 204 153
6 2 14 255 204 153
-9 3 14 255 204 153
9 3 14 255 204 153
-6 4 14 255 204 153
6 4 14 255 204 153
-9 5 14 255 204 153
9 5 14 255 204 153
-6 6 14 255 204 153
-4 6 14 255 204 153
-2 6 14 255 204 153
0 6 14 255 204 153
2 6 14 255 204 153
4 6 14 255 204 153
6 6 14 255 204 153
-9 7 14 255 204 153
-8 7 14 255 204 153
-7 7 14 255 204 153
7 7 14 255 204 153
8 7 14 255 204 153
9 7 14 255 204 153
-9 8 14 255 204 153
-8 8 14 255 204 153
-7 8 14 255 204 153
7 8 14 255 204 153
8 8 14 255 204 153
9 8 14 255 204 153
-9 9 14 255 204 153
-8 9 14 255 204 153
-7 9 14 255 204 153
7 9 14 255 204 153
8 9 14 255 204 153
9 9 14 255 204 153
-8 10 14 255 204 153
-6 10 14 255 204 153
-4 10 14 255 204 153
-2 10 14 255 204 153
0 10 14 255 204 153
2 10 14 255 204 153
4 10 14 255 204 153
6 10 14 255 204 153
8 10 14 255 204 153
-8 -9 15 255 204 153
8 -9 15 255 204 153
-9 -8 15 255 204 153
-8 -8 15 255 204 153
-7 -8 15 255 204 153
7 -8 15 255 204 153
8 -8 15 255 204 153
9 -8 15 255 204 153
-8 -7 15 255 204 153
8 -7 15 255 204 153
-8 7 15 255 204 153
8 7 15 255 204 153
-9 8 15 255 204 153
-8 8 15 255 204 153
-7 8 15 255 204 153
7 8 15 255 204 153
8 8 15 255 204 153
9 8 15 255 204 153
-8 9 15 255 204 153
8 9 15 255 204 153
-10 -10 16 255 204 153
-9 -10 16 255 204 153
-8 -10 16 255 204 153
-7 -10 16 255 204 153
-6 -10 16 255 204 153
6 -10 16 255 204 153
7 -10 16 255 204 153
8 -10 16 255 204 153
9 -10 16 255 204 153
10 -10 16 255 204 153
-10 -9 16 255 204 153
-9 -9 16 255 204 153
-8 -9 16 255 204 153
-7 -9 16 255 204 153
-6 -9 16 255 204 153
6 -9 16 255 204 153
7 -9 16 255 204 153
8 -9 16 255 204 153
9 -9 16 255 204 153
10 -9 16 255 204 153
-10 -8 16 255 204 153
-9 -8 16 255 204 153
-8 -8 16 255 204 153
-7 -8 16 255 204 153
-6 -8 16 255 204 153
6 -8 16 255 204 153
7 -8 16 255 204 153
8 -8 16 255 204 153
9 -8 16 255 204 153
10 -8 16 255 204 153
-10 -7 16 255 204 153
-9 -7 16 255 204 153
-8 -7 16 255 204 153
-7 -7 16 255 204 153
-6 -7 16 255 204 153
6 -7 16 255 204 153
7 -7 16 255 204 153
8 -7 16 255 204 153
9 -7 16 255 204 153
10 -7 16 255 204 153
-10 -6 16 255 204 153
-9 -6 16 255 204 153
-8 -6 16 255 204 153
-7 -6 16 255 204 153
-6 -6 16 255 204 153
6 -6 16 255 204 153
7 -6 16 255 204 153
8 -6 16 255 204 153
9 -6 16 255 204 153
10 -6 16 255 204 153
-10 6 16 255 204 153
-9 6 16 255 204 153
-8 6 16 255 204 153
-7 6 16 255 204 153
-6 6 16 255 204 153
6 6 16 255 204 153
7 6 16 255 204 153
8 6 16 255 204 153
9 6 16 255 204 153
10 6 16 255 204 153
-10 7 16 255 204 153
-9 7 16 255 204 153
-8 7 16 255 204 153
-7 7 16 255 204 153
-6 7 16 255 204 153
6 7 16 255 204 153
7 7 16 255 204 153
8 7 16 255 204 153
9 7 16 255 204 153
10 7 16 255 204 153
-10 8 16 255 204 153
-9 8 16 255 204 153
-8 8 16 255 204 153
-7 8 16 255 204 153
-6 8 16 255 204 153
6 8 16 255 204 153
7 8 16 255 204 153
8 8 16 255 204 153
9 8 16 255 204 153
10 8 16 255 204 153
-10 9 16 255 204 153
-9 9 16 255 204 153
-8 9 16 255 204 153
-7 9 16 255 204 153
-6 9 16 255 204 153
6 9 16 255 204 153
7 9 16 255 204 153
8 9 16 255 204 153
9 9 16 255 204 153
10 9 16 255 204 153
-10 10 16 255 204 153
-9 10 16 255 204 153
-8 10 16 255 204 153
-7 10 16 255 204 153
-6 10 16 255 204 153
6 10 16 255 204 153
7 10 16 255 204 153
8 10 16 255 204 153
9 10 16 255 204 153
10 10 16 255 204 153
-10 -10 17 255 204 153
-9 -10 17 255 204 153
-8 -10 17 255 204 153
-7 -10 17 255 204 153
-6 -10 17 255 204 153
6 -10 17 255 204 153
7 -10 17 255 204 153
8 -10 17 255 204 153
9 -10 17 255 204 153
10 -10 17 255 204 153
-10 -9 17 255 204 153
-6 -9 17 255 204 153
6 -9 17 255 204 153
10 -9 17 255 204 153
-10 -8 17 255 204 153
-6 -8 17 255 204 153
6 -8 17 255 204 153
10 -8 17 255 204 153
-10 -7 17 255 204 153
-6 -7 17 255 204 153
6 -7 17 255 204 153
10 -7 17 255 204 153
-10 -6 17 255 204 153
-9 -6 17 255 204 153
-8 -6 17 255 204 153
-7 -6 17 255 204 153
-6 -6 17 255 204 153
6 -6 17 255 204 153
7 -6 17 255 204 153
8 -6 17 255 204 153
9 -6 17 255 204 153
10 -6 17 255 204 153
-10 6 17 255 204 153
-9 6 17 255 204 153
-8 6 17 255 204 153
-7 6 17 255 204 153
-6 6 17 255 204 153
6 6 17 255 204 153
7 6 17 255 204 153
8 6 17 255 204 153
9 6 17 255 204 153
10 6 17 255 204 153
-10 7 17 255 204 153
-6 7 17 255 204 153
6 7 17 255 204 153
10 7 17 255 204 153
-10 8 17 255 204 153
-6 8 17 255 204 153
6 8 17 255 204 153
10 8 17 255 204 153
-10 9 17 255 204 153
-6 9 17 255 204 153
6 9 17 255 204 153
10 9 17 255 204 153
-10 10 17 255 204 153
-9 10 17 255 204 153
-8 10 17 255 204 153
-7 10 17 255 204 153
-6 10 17 255 204 153
6 10 17 255 204 153
7 10 17 255 204 153
8 10 17 255 204 153
9 10 17 255 204 153
10 10 17 255 204 153
-10 -10 18 255 204 153
-8 -10 18 255 204 153
-6 -10 18 255 204 153
6 -10 18 255 204 153
8 -10 18 255 204 153
10 -10 18 255 204 153
-10 -8 18 255 204 153
-6 -8 18 255 204 153
6 -8 18 255 204 153
10 -8 18 255 204 153
-10 -6 18 255 204 153
-8 -6 18 255 204 153
-6 -6 18 255 204 153
6 -6 18 255 204 153
8 -6 18 255 204 153
10 -6 18 255 204 153
-10 6 18 255 204 153
-8 6 18 255 204 153
-6 6 18 255 204 153
6 6 18 255 204 153
8 6 18 255 204 153
10 6 18 255 204 153
-10 8 18 255 204 153
-6 8 18 255 204 153
6 8 18 255 204 153
10 8 18 255 204 153
-10 10 18 255 204 153
-8 10 18 255 204 153
-6 10 18 255 204 153
6 10 18 255 204 153
8 10 18 255 204 153
10 10 18 255 204 153
-10 -10 19 255 204 153
-9 -10 19 255 204 153
-8 -10 19 255 204 153
-7 -10 19 255 204 153
-6 -10 19 255 204 153
6 -10 19 255 204 153
7 -10 19 255 204 153
8 -10 19 255 204 153
9 -10 19 255 204 153
10 -10 19 255 204 153
-10 -9 19 255 204 153
-6 -9 19 255 204 153
6 -9 19 255 204 153
10 -9 19 255 204 153
-10 -8 19 255 204 153
-6 -8 19 255 204 153
6 -8 19 255 204 153
10 -8 19 255 204 153
-10 -7 19 255 204 153
-6 -7 19 255 204 153
6 -7 19 255 204 153
10 -7 19 255 204 153
-10 -6 19 255 204 153
-9 -6 19 255 204 153
-8 -6 19 255 204 153
-7 -6 19 255 204 153
-6 -6 19 255 204 153
6 -6 19 255 204 153
7 -6 19 255 204 153
8 -6 19 255 204 153
9 -6 19 255 204 153
10 -6 19 255 204 153
-10 6 19 255 204 153
-9 6 19 255 204 153
-8 6 19 255 204 153
-7 6 19 255 204 153
-6 6 19 255 204 153
6 6 19 255 204 153
7 6 19 255 204 153
8 6 19 255 204 153
9 6 19 255 204 153
10 6 19 255 204 153
-10 7 19 255 204 153
-6 7 19 255 204 153
6 7 19 255 204 153
10 7 19 255 204 153
-10 8 19 255 204 153
-6 8 19 255 204 153
6 8 19 255 204 153
10 8 19 255 204 153
-10 9 19 255 204 153
-6 9 19 255 204 153
6 9 19 255 204 153
10 9 19 255 204 153
-10 10 19 255 204 153
-9 10 19 255 204 153
-8 10 19 255 204 153
-7 10 19 255 204 153
-6 10 19 255 204 153
6 10 19 255 204 153
7 10 19 255 204 153
8 10 19 255 204 153
9 10 19 255 204 153
10 10 19 255 204 153
-10 -10 20 255 204 153
-8 -10 20 255 204 153
-6 -10 20 255 204 153
6 -10 20 255 204 153
8 -10 20 255 204 153
10 -10 20 255 204 153
-10 -8 20 255 204 153
-6 -8 20 255 204 153
6 -8 20 255 204 153
10 -8 20 255 204 153
-10 -6 20 255 204 153
-8 -6 20 255 204 153
-6 -6 20 255 204 153
6 -6 20 255 204 153
8 -6 20 255 204 153
10 -6 20 255 204 153
-10 6 20 255 204 153
-8 6 20 255 204 153
-6 6 20 255 204 153
6 6 20 255 204 153
8 6 20 255 204 153
10 6 20 255 204 153
-10 8 20 255 204 153
-6 8 20 255 204 153
6 8 20 255 204 153
10 8 20 255 204 153
-10 10 20 255 204 153
-8 10 20 255 204 153
-6 10 20 255 204 153
6 10 20 255 204 153
8 10 20 255 204 153
10 10 20 255 204 153
