ply
format ascii 1.0
comment : MagicaVoxel @ Ephtracy
element vertex 8518
property float x
property float y
property float z
property uchar red
property uchar green
property uchar blue
end_header
-28 -28 16 178 197 83
-27 -28 16 178 197 83
-26 -28 16 178 197 83
-25 -28 16 178 197 83
-24 -28 16 178 197 83
-23 -28 16 178 197 83
-22 -28 16 178 197 83
-21 -28 16 178 197 83
-20 -28 16 178 197 83
-19 -28 16 178 197 83
-18 -28 16 178 197 83
-17 -28 16 178 197 83
-16 -28 16 178 197 83
-15 -28 16 178 197 83
-14 -28 16 178 197 83
-13 -28 16 178 197 83
-12 -28 16 178 197 83
-11 -28 16 178 197 83
-10 -28 16 178 197 83
-9 -28 16 178 197 83
-8 -28 16 178 197 83
-7 -28 16 178 197 83
-6 -28 16 178 197 83
-5 -28 16 178 197 83
-4 -28 16 178 197 83
-3 -28 16 178 197 83
-2 -28 16 178 197 83
-1 -28 16 178 197 83
0 -28 16 178 197 83
1 -28 16 178 197 83
2 -28 16 178 197 83
3 -28 16 178 197 83
4 -28 16 178 197 83
5 -28 16 178 197 83
6 -28 16 178 197 83
7 -28 16 178 197 83
8 -28 16 178 197 83
9 -28 16 178 197 83
10 -28 16 178 197 83
11 -28 16 178 197 83
12 -28 16 178 197 83
13 -28 16 178 197 83
14 -28 16 178 197 83
15 -28 16 178 197 83
16 -28 16 178 197 83
17 -28 16 178 197 83
18 -28 16 178 197 83
19 -28 16 178 197 83
20 -28 16 178 197 83
21 -28 16 178 197 83
22 -28 16 178 197 83
23 -28 16 178 197 83
24 -28 16 178 197 83
25 -28 16 178 197 83
26 -28 16 178 197 83
27 -28 16 178 197 83
28 -28 16 178 197 83
-28 -27 16 178 197 83
-27 -27 16 178 197 83
-26 -27 16 178 197 83
-25 -27 16 178 197 83
-24 -27 16 178 197 83
-23 -27 16 178 197 83
-22 -27 16 178 197 83
-21 -27 16 178 197 83
-20 -27 16 178 197 83
-19 -27 16 178 197 83
-18 -27 16 178 197 83
-17 -27 16 178 197 83
-16 -27 16 178 197 83
-15 -27 16 178 197 83
-14 -27 16 178 197 83
-13 -27 16 178 197 83
-12 -27 16 178 197 83
-11 -27 16 178 197 83
-10 -27 16 178 197 83
-9 -27 16 178 197 83
-8 -27 16 178 197 83
-7 -27 16 178 197 83
-6 -27 16 178 197 83
-5 -27 16 178 197 83
-4 -27 16 178 197 83
-3 -27 16 178 197 83
-2 -27 16 178 197 83
-1 -27 16 178 197 83
0 -27 16 178 197 83
1 -27 16 178 197 83
2 -27 16 178 197 83
3 -27 16 178 197 83
4 -27 16 178 197 83
5 -27 16 178 197 83
6 -27 16 178 197 83
7 -27 16 178 197 83
8 -27 16 178 197 83
9 -27 16 178 197 83
10 -27 16 178 197 83
11 -27 16 178 197 83
12 -27 16 178 197 83
13 -27 16 178 197 83
14 -27 16 178 197 83
15 -27 16 178 197 83
16 -27 16 178 197 83
17 -27 16 178 197 83
18 -27 16 178 197 83
19 -27 16 178 197 83
20 -27 16 178 197 83
21 -27 16 178 197 83
22 -27 16 178 197 83
23 -27 16 178 197 83
24 -27 16 178 197 83
25 -27 16 178 197 83
26 -27 16 178 197 83
27 -27 16 178 197 83
28 -27 16 178 197 83
-28 -26 16 178 197 83
-27 -26 16 178 197 83
-26 -26 16 178 197 83
-25 -26 16 178 197 83
-24 -26 16 178 197 83
-23 -26 16 178 197 83
-22 -26 16 178 197 83
-21 -26 16 178 197 83
-20 -26 16 178 197 83
-19 -26 16 178 197 83
-18 -26 16 178 197 83
-17 -26 16 178 197 83
-16 -26 16 178 197 83
-15 -26 16 178 197 83
-14 -26 16 178 197 83
-13 -26 16 178 197 83
-12 -26 16 178 197 83
-11 -26 16 178 197 83
-10 -26 16 178 197 83
-9 -26 16 178 197 83
-8 -26 16 178 197 83
-7 -26 16 178 197 83
-6 -26 16 178 197 83
-5 -26 16 178 197 83
-4 -26 16 178 197 83
-3 -26 16 178 197 83
-2 -26 16 178 197 83
-1 -26 16 178 197 83
0 -26 16 178 197 83
1 -26 16 178 197 83
2 -26 16 178 197 83
3 -26 16 178 197 83
4 -26 16 178 197 83
5 -26 16 178 197 83
6 -26 16 178 197 83
7 -26 16 178 197 83
8 -26 16 178 197 83
9 -26 16 178 197 83
10 -26 16 178 197 83
11 -26 16 178 197 83
12 -26 16 178 197 83
13 -26 16 178 197 83
14 -26 16 178 197 83
15 -26 16 178 197 83
16 -26 16 178 197 83
17 -26 16 178 197 83
18 -26 16 178 197 83
19 -26 16 178 197 83
20 -26 16 178 197 83
21 -26 16 178 197 83
22 -26 16 178 197 83
23 -26 16 178 197 83
24 -26 16 178 197 83
25 -26 16 178 197 83
26 -26 16 178 197 83
27 -26 16 178 197 83
28 -26 16 178 197 83
-28 -25 16 178 197 83
-27 -25 16 178 197 83
-26 -25 16 178 197 83
-25 -25 16 178 197 83
-24 -25 16 178 197 83
-23 -25 16 178 197 83
-22 -25 16 178 197 83
-21 -25 16 178 197 83
-20 -25 16 178 197 83
-19 -25 16 178 197 83
-18 -25 16 178 197 83
-17 -25 16 178 197 83
-16 -25 16 178 197 83
-15 -25 16 178 197 83
-14 -25 16 178 197 83
-13 -25 16 178 197 83
-12 -25 16 178 197 83
-11 -25 16 178 197 83
-10 -25 16 178 197 83
-9 -25 16 178 197 83
-8 -25 16 178 197 83
-7 -25 16 178 197 83
-6 -25 16 178 197 83
-5 -25 16 178 197 83
-4 -25 16 178 197 83
-3 -25 16 178 197 83
-2 -25 16 178 197 83
-1 -25 16 178 197 83
0 -25 16 178 197 83
1 -25 16 178 197 83
2 -25 16 178 197 83
3 -25 16 178 197 83
4 -25 16 178 197 83
5 -25 16 178 197 83
6 -25 16 178 197 83
7 -25 16 178 197 83
8 -25 16 178 197 83
9 -25 16 178 197 83
10 -25 16 178 197 83
11 -25 16 178 197 83
12 -25 16 178 197 83
13 -25 16 178 197 83
14 -25 16 178 197 83
15 -25 16 178 197 83
16 -25 16 178 197 83
17 -25 16 178 197 83
18 -25 16 178 197 83
19 -25 16 178 197 83
20 -25 16 178 197 83
21 -25 16 178 197 83
22 -25 16 178 197 83
23 -25 16 178 197 83
24 -25 16 178 197 83
25 -25 16 178 197 83
26 -25 16 178 197 83
27 -25 16 178 197 83
28 -25 16 178 197 83
-28 -24 16 178 197 83
-27 -24 16 178 197 83
-26 -24 16 178 197 83
-25 -24 16 178 197 83
-24 -24 16 178 197 83
-23 -24 16 178 197 83
-22 -24 16 178 197 83
-21 -24 16 178 197 83
-20 -24 16 178 197 83
-19 -24 16 178 197 83
-18 -24 16 178 197 83
-17 -24 16 178 197 83
-16 -24 16 178 197 83
-15 -24 16 178 197 83
-14 -24 16 178 197 83
-13 -24 16 178 197 83
-12 -24 16 178 197 83
-11 -24 16 178 197 83
-10 -24 16 178 197 83
-9 -24 16 178 197 83
-8 -24 16 178 197 83
-7 -24 16 178 197 83
-6 -24 16 178 197 83
-5 -24 16 178 197 83
-4 -24 16 178 197 83
-3 -24 16 178 197 83
-2 -24 16 178 197 83
-1 -24 16 178 197 83
0 -24 16 178 197 83
1 -24 16 178 197 83
2 -24 16 178 197 83
3 -24 16 178 197 83
4 -24 16 178 197 83
5 -24 16 178 197 83
6 -24 16 178 197 83
7 -24 16 178 197 83
8 -24 16 178 197 83
9 -24 16 178 197 83
10 -24 16 178 197 83
11 -24 16 178 197 83
12 -24 16 178 197 83
13 -24 16 178 197 83
14 -24 16 178 197 83
15 -24 16 178 197 83
16 -24 16 178 197 83
17 -24 16 178 197 83
18 -24 16 178 197 83
19 -24 16 178 197 83
20 -24 16 178 197 83
21 -24 16 178 197 83
22 -24 16 178 197 83
23 -24 16 178 197 83
24 -24 16 178 197 83
25 -24 16 178 197 83
26 -24 16 178 197 83
27 -24 16 178 197 83
28 -24 16 178 197 83
-28 -23 16 178 197 83
-27 -23 16 178 197 83
-26 -23 16 178 197 83
-25 -23 16 178 197 83
-24 -23 16 178 197 83
-23 -23 16 178 197 83
-22 -23 16 178 197 83
-21 -23 16 178 197 83
-20 -23 16 178 197 83
-19 -23 16 178 197 83
-18 -23 16 178 197 83
-17 -23 16 178 197 83
-16 -23 16 178 197 83
-15 -23 16 178 197 83
-14 -23 16 178 197 83
-13 -23 16 178 197 83
-12 -23 16 178 197 83
-11 -23 16 178 197 83
-10 -23 16 178 197 83
-9 -23 16 178 197 83
-8 -23 16 178 197 83
-7 -23 16 178 197 83
-6 -23 16 178 197 83
-5 -23 16 178 197 83
-4 -23 16 178 197 83
-3 -23 16 178 197 83
-2 -23 16 178 197 83
-1 -23 16 178 197 83
0 -23 16 178 197 83
1 -23 16 178 197 83
2 -23 16 178 197 83
3 -23 16 178 197 83
4 -23 16 178 197 83
5 -23 16 178 197 83
6 -23 16 178 197 83
7 -23 16 178 197 83
8 -23 16 178 197 83
9 -23 16 178 197 83
10 -23 16 178 197 83
11 -23 16 178 197 83
12 -23 16 178 197 83
13 -23 16 178 197 83
14 -23 16 178 197 83
15 -23 16 178 197 83
16 -23 16 178 197 83
17 -23 16 178 197 83
18 -23 16 178 197 83
19 -23 16 178 197 83
20 -23 16 178 197 83
21 -23 16 178 197 83
22 -23 16 178 197 83
23 -23 16 178 197 83
24 -23 16 178 197 83
25 -23 16 178 197 83
26 -23 16 178 197 83
27 -23 16 178 197 83
28 -23 16 178 197 83
-28 -22 16 178 197 83
-27 -22 16 178 197 83
-26 -22 16 178 197 83
-25 -22 16 178 197 83
-24 -22 16 178 197 83
-23 -22 16 178 197 83
-22 -22 16 178 197 83
-21 -22 16 178 197 83
-20 -22 16 178 197 83
-19 -22 16 178 197 83
-18 -22 16 178 197 83
-17 -22 16 178 197 83
-16 -22 16 178 197 83
-15 -22 16 178 197 83
-14 -22 16 178 197 83
-13 -22 16 178 197 83
-12 -22 16 178 197 83
-11 -22 16 178 197 83
-10 -22 16 178 197 83
-9 -22 16 178 197 83
-8 -22 16 178 197 83
-7 -22 16 178 197 83
-6 -22 16 178 197 83
-5 -22 16 178 197 83
-4 -22 16 178 197 83
-3 -22 16 178 197 83
-2 -22 16 178 197 83
-1 -22 16 178 197 83
0 -22 16 178 197 83
1 -22 16 178 197 83
2 -22 16 178 197 83
3 -22 16 178 197 83
4 -22 16 178 197 83
5 -22 16 178 197 83
6 -22 16 178 197 83
7 -22 16 178 197 83
8 -22 16 178 197 83
9 -22 16 178 197 83
10 -22 16 178 197 83
11 -22 16 178 197 83
12 -22 16 178 197 83
13 -22 16 178 197 83
14 -22 16 178 197 83
15 -22 16 178 197 83
16 -22 16 178 197 83
17 -22 16 178 197 83
18 -22 16 178 197 83
19 -22 16 178 197 83
20 -22 16 178 197 83
21 -22 16 178 197 83
22 -22 16 178 197 83
23 -22 16 178 197 83
24 -22 16 178 197 83
25 -22 16 178 197 83
26 -22 16 178 197 83
27 -22 16 178 197 83
28 -22 16 178 197 83
-28 -21 16 178 197 83
-27 -21 16 178 197 83
-26 -21 16 178 197 83
-25 -21 16 178 197 83
-24 -21 16 178 197 83
-23 -21 16 178 197 83
-22 -21 16 178 197 83
-21 -21 16 178 197 83
-20 -21 16 178 197 83
-19 -21 16 178 197 83
-18 -21 16 178 197 83
-17 -21 16 178 197 83
-16 -21 16 178 197 83
-15 -21 16 178 197 83
-14 -21 16 178 197 83
-13 -21 16 178 197 83
-12 -21 16 178 197 83
-11 -21 16 178 197 83
-10 -21 16 178 197 83
-9 -21 16 178 197 83
-8 -21 16 178 197 83
-7 -21 16 178 197 83
-6 -21 16 178 197 83
-5 -21 16 178 197 83
-4 -21 16 178 197 83
-3 -21 16 178 197 83
-2 -21 16 178 197 83
-1 -21 16 178 197 83
0 -21 16 178 197 83
1 -21 16 178 197 83
2 -21 16 178 197 83
3 -21 16 178 197 83
4 -21 16 178 197 83
5 -21 16 178 197 83
6 -21 16 178 197 83
7 -21 16 178 197 83
8 -21 16 178 197 83
9 -21 16 178 197 83
10 -21 16 178 197 83
11 -21 16 178 197 83
12 -21 16 178 197 83
13 -21 16 178 197 83
14 -21 16 178 197 83
15 -21 16 178 197 83
16 -21 16 178 197 83
17 -21 16 178 197 83
18 -21 16 178 197 83
19 -21 16 178 197 83
20 -21 16 178 197 83
21 -21 16 178 197 83
22 -21 16 178 197 83
23 -21 16 178 197 83
24 -21 16 178 197 83
25 -21 16 178 197 83
26 -21 16 178 197 83
27 -21 16 178 197 83
28 -21 16 178 197 83
-28 -20 16 178 197 83
-27 -20 16 178 197 83
-26 -20 16 178 197 83
-25 -20 16 178 197 83
-24 -20 16 178 197 83
-23 -20 16 178 197 83
-22 -20 16 178 197 83
-21 -20 16 178 197 83
-20 -20 16 178 197 83
-19 -20 16 178 197 83
-18 -20 16 178 197 83
-17 -20 16 178 197 83
-16 -20 16 178 197 83
-15 -20 16 178 197 83
-14 -20 16 178 197 83
-13 -20 16 178 197 83
-12 -20 16 178 197 83
-11 -20 16 178 197 83
-10 -20 16 178 197 83
-9 -20 16 178 197 83
-8 -20 16 178 197 83
-7 -20 16 178 197 83
-6 -20 16 178 197 83
-5 -20 16 178 197 83
-4 -20 16 178 197 83
-3 -20 16 178 197 83
-2 -20 16 178 197 83
-1 -20 16 178 197 83
0 -20 16 178 197 83
1 -20 16 178 197 83
2 -20 16 178 197 83
3 -20 16 178 197 83
4 -20 16 178 197 83
5 -20 16 178 197 83
6 -20 16 178 197 83
7 -20 16 178 197 83
8 -20 16 178 197 83
9 -20 16 178 197 83
10 -20 16 178 197 83
11 -20 16 178 197 83
12 -20 16 178 197 83
13 -20 16 178 197 83
14 -20 16 178 197 83
15 -20 16 178 197 83
16 -20 16 178 197 83
17 -20 16 178 197 83
18 -20 16 178 197 83
19 -20 16 178 197 83
20 -20 16 178 197 83
21 -20 16 178 197 83
22 -20 16 178 197 83
23 -20 16 178 197 83
24 -20 16 178 197 83
25 -20 16 178 197 83
26 -20 16 178 197 83
27 -20 16 178 197 83
28 -20 16 178 197 83
-28 -19 16 178 197 83
-27 -19 16 178 197 83
-26 -19 16 178 197 83
-25 -19 16 178 197 83
-24 -19 16 178 197 83
-23 -19 16 178 197 83
-22 -19 16 178 197 83
-21 -19 16 178 197 83
-20 -19 16 178 197 83
-19 -19 16 178 197 83
-18 -19 16 178 197 83
-17 -19 16 178 197 83
-16 -19 16 178 197 83
-15 -19 16 178 197 83
-14 -19 16 178 197 83
-13 -19 16 178 197 83
-12 -19 16 178 197 83
-11 -19 16 178 197 83
-10 -19 16 178 197 83
-9 -19 16 178 197 83
-8 -19 16 178 197 83
-7 -19 16 178 197 83
-6 -19 16 178 197 83
-5 -19 16 178 197 83
-4 -19 16 178 197 83
-3 -19 16 178 197 83
-2 -19 16 178 197 83
-1 -19 16 178 197 83
0 -19 16 178 197 83
1 -19 16 178 197 83
2 -19 16 178 197 83
3 -19 16 178 197 83
4 -19 16 178 197 83
5 -19 16 178 197 83
6 -19 16 178 197 83
7 -19 16 178 197 83
8 -19 16 178 197 83
9 -19 16 178 197 83
10 -19 16 178 197 83
11 -19 16 178 197 83
12 -19 16 178 197 83
13 -19 16 178 197 83
14 -19 16 178 197 83
15 -19 16 178 197 83
16 -19 16 178 197 83
17 -19 16 178 197 83
18 -19 16 178 197 83
19 -19 16 178 197 83
20 -19 16 178 197 83
21 -19 16 178 197 83
22 -19 16 178 197 83
23 -19 16 178 197 83
24 -19 16 178 197 83
25 -19 16 178 197 83
26 -19 16 178 197 83
27 -19 16 178 197 83
28 -19 16 178 197 83
-28 -18 16 178 197 83
-27 -18 16 178 197 83
-26 -18 16 178 197 83
-25 -18 16 178 197 83
-24 -18 16 178 197 83
-23 -18 16 178 197 83
-22 -18 16 178 197 83
-21 -18 16 178 197 83
-20 -18 16 178 197 83
-19 -18 16 178 197 83
-18 -18 16 178 197 83
-17 -18 16 178 197 83
-16 -18 16 178 197 83
-15 -18 16 178 197 83
-14 -18 16 178 197 83
-13 -18 16 178 197 83
-12 -18 16 178 197 83
-11 -18 16 178 197 83
-10 -18 16 178 197 83
-9 -18 16 178 197 83
-8 -18 16 178 197 83
-7 -18 16 178 197 83
-6 -18 16 178 197 83
-5 -18 16 178 197 83
-4 -18 16 178 197 83
-3 -18 16 178 197 83
-2 -18 16 178 197 83
-1 -18 16 178 197 83
0 -18 16 178 197 83
1 -18 16 178 197 83
2 -18 16 178 197 83
3 -18 16 178 197 83
4 -18 16 178 197 83
5 -18 16 178 197 83
6 -18 16 178 197 83
7 -18 16 178 197 83
8 -18 16 178 197 83
9 -18 16 178 197 83
10 -18 16 178 197 83
11 -18 16 178 197 83
12 -18 16 178 197 83
13 -18 16 178 197 83
14 -18 16 178 197 83
15 -18 16 178 197 83
16 -18 16 178 197 83
17 -18 16 178 197 83
18 -18 16 178 197 83
19 -18 16 178 197 83
20 -18 16 178 197 83
21 -18 16 178 197 83
22 -18 16 178 197 83
23 -18 16 178 197 83
24 -18 16 178 197 83
25 -18 16 178 197 83
26 -18 16 178 197 83
27 -18 16 178 197 83
28 -18 16 178 197 83
-28 -17 16 178 197 83
-27 -17 16 178 197 83
-26 -17 16 178 197 83
-25 -17 16 178 197 83
-24 -17 16 178 197 83
-23 -17 16 178 197 83
-22 -17 16 178 197 83
-21 -17 16 178 197 83
-20 -17 16 178 197 83
-19 -17 16 178 197 83
-18 -17 16 178 197 83
-17 -17 16 178 197 83
-16 -17 16 178 197 83
-15 -17 16 178 197 83
-14 -17 16 178 197 83
-13 -17 16 178 197 83
-12 -17 16 178 197 83
-11 -17 16 178 197 83
-10 -17 16 178 197 83
-9 -17 16 178 197 83
-8 -17 16 178 197 83
-7 -17 16 178 197 83
-6 -17 16 178 197 83
-5 -17 16 178 197 83
-4 -17 16 178 197 83
-3 -17 16 178 197 83
-2 -17 16 178 197 83
-1 -17 16 178 197 83
0 -17 16 178 197 83
1 -17 16 178 197 83
2 -17 16 178 197 83
3 -17 16 178 197 83
4 -17 16 178 197 83
5 -17 16 178 197 83
6 -17 16 178 197 83
7 -17 16 178 197 83
8 -17 16 178 197 83
9 -17 16 178 197 83
10 -17 16 178 197 83
11 -17 16 178 197 83
12 -17 16 178 197 83
13 -17 16 178 197 83
14 -17 16 178 197 83
15 -17 16 178 197 83
16 -17 16 178 197 83
17 -17 16 178 197 83
18 -17 16 178 197 83
19 -17 16 178 197 83
20 -17 16 178 197 83
21 -17 16 178 197 83
22 -17 16 178 197 83
23 -17 16 178 197 83
24 -17 16 178 197 83
25 -17 16 178 197 83
26 -17 16 178 197 83
27 -17 16 178 197 83
28 -17 16 178 197 83
-28 -16 16 178 197 83
-27 -16 16 178 197 83
-26 -16 16 178 197 83
-25 -16 16 178 197 83
-24 -16 16 178 197 83
-23 -16 16 178 197 83
-22 -16 16 178 197 83
-21 -16 16 178 197 83
-20 -16 16 178 197 83
-19 -16 16 178 197 83
-18 -16 16 178 197 83
-17 -16 16 178 197 83
-16 -16 16 178 197 83
-15 -16 16 178 197 83
-14 -16 16 178 197 83
-13 -16 16 178 197 83
-12 -16 16 178 197 83
-11 -16 16 178 197 83
-10 -16 16 178 197 83
-9 -16 16 178 197 83
-8 -16 16 178 197 83
-7 -16 16 178 197 83
-6 -16 16 178 197 83
-5 -16 16 178 197 83
-4 -16 16 178 197 83
-3 -16 16 178 197 83
-2 -16 16 178 197 83
-1 -16 16 178 197 83
0 -16 16 178 197 83
1 -16 16 178 197 83
2 -16 16 178 197 83
3 -16 16 178 197 83
4 -16 16 178 197 83
5 -16 16 178 197 83
6 -16 16 178 197 83
7 -16 16 178 197 83
8 -16 16 178 197 83
9 -16 16 178 197 83
10 -16 16 178 197 83
11 -16 16 178 197 83
12 -16 16 178 197 83
13 -16 16 178 197 83
14 -16 16 178 197 83
15 -16 16 178 197 83
16 -16 16 178 197 83
17 -16 16 178 197 83
18 -16 16 178 197 83
19 -16 16 178 197 83
20 -16 16 178 197 83
21 -16 16 178 197 83
22 -16 16 178 197 83
23 -16 16 178 197 83
24 -16 16 178 197 83
25 -16 16 178 197 83
26 -16 16 178 197 83
27 -16 16 178 197 83
28 -16 16 178 197 83
-28 -15 16 178 197 83
-27 -15 16 178 197 83
-26 -15 16 178 197 83
-25 -15 16 178 197 83
-24 -15 16 178 197 83
-23 -15 16 178 197 83
-22 -15 16 178 197 83
-21 -15 16 178 197 83
-20 -15 16 178 197 83
-19 -15 16 178 197 83
-18 -15 16 178 197 83
-17 -15 16 178 197 83
-16 -15 16 178 197 83
-15 -15 16 178 197 83
-14 -15 16 178 197 83
-13 -15 16 178 197 83
-12 -15 16 178 197 83
-11 -15 16 178 197 83
-10 -15 16 178 197 83
-9 -15 16 178 197 83
-8 -15 16 178 197 83
-7 -15 16 178 197 83
-6 -15 16 178 197 83
-5 -15 16 178 197 83
-4 -15 16 178 197 83
-3 -15 16 178 197 83
-2 -15 16 178 197 83
-1 -15 16 178 197 83
0 -15 16 178 197 83
1 -15 16 178 197 83
2 -15 16 178 197 83
3 -15 16 178 197 83
4 -15 16 178 197 83
5 -15 16 178 197 83
6 -15 16 178 197 83
7 -15 16 178 197 83
8 -15 16 178 197 83
9 -15 16 178 197 83
10 -15 16 178 197 83
11 -15 16 178 197 83
12 -15 16 178 197 83
13 -15 16 178 197 83
14 -15 16 178 197 83
15 -15 16 178 197 83
16 -15 16 178 197 83
17 -15 16 178 197 83
18 -15 16 178 197 83
19 -15 16 178 197 83
20 -15 16 178 197 83
21 -15 16 178 197 83
22 -15 16 178 197 83
23 -15 16 178 197 83
24 -15 16 178 197 83
25 -15 16 178 197 83
26 -15 16 178 197 83
27 -15 16 178 197 83
28 -15 16 178 197 83
-28 -14 16 178 197 83
-27 -14 16 178 197 83
-26 -14 16 178 197 83
-25 -14 16 178 197 83
-24 -14 16 178 197 83
-23 -14 16 178 197 83
-22 -14 16 178 197 83
-21 -14 16 178 197 83
-20 -14 16 178 197 83
-19 -14 16 178 197 83
-18 -14 16 178 197 83
-17 -14 16 178 197 83
-16 -14 16 178 197 83
-15 -14 16 178 197 83
-14 -14 16 178 197 83
-13 -14 16 178 197 83
-12 -14 16 178 197 83
-11 -14 16 178 197 83
-10 -14 16 178 197 83
-9 -14 16 178 197 83
-8 -14 16 178 197 83
-7 -14 16 178 197 83
-6 -14 16 178 197 83
-5 -14 16 178 197 83
-4 -14 16 178 197 83
-3 -14 16 178 197 83
-2 -14 16 178 197 83
-1 -14 16 178 197 83
0 -14 16 178 197 83
1 -14 16 178 197 83
2 -14 16 178 197 83
3 -14 16 178 197 83
4 -14 16 178 197 83
5 -14 16 178 197 83
6 -14 16 178 197 83
7 -14 16 178 197 83
8 -14 16 178 197 83
9 -14 16 178 197 83
10 -14 16 178 197 83
11 -14 16 178 197 83
12 -14 16 178 197 83
13 -14 16 178 197 83
14 -14 16 178 197 83
15 -14 16 178 197 83
16 -14 16 178 197 83
17 -14 16 178 197 83
18 -14 16 178 197 83
19 -14 16 178 197 83
20 -14 16 178 197 83
21 -14 16 178 197 83
22 -14 16 178 197 83
23 -14 16 178 197 83
24 -14 16 178 197 83
25 -14 16 178 197 83
26 -14 16 178 197 83
27 -14 16 178 197 83
28 -14 16 178 197 83
-28 -13 16 178 197 83
-27 -13 16 178 197 83
-26 -13 16 178 197 83
-25 -13 16 178 197 83
-24 -13 16 178 197 83
-23 -13 16 178 197 83
-22 -13 16 178 197 83
-21 -13 16 178 197 83
-20 -13 16 178 197 83
-19 -13 16 178 197 83
-18 -13 16 178 197 83
-17 -13 16 178 197 83
-16 -13 16 178 197 83
-15 -13 16 178 197 83
-14 -13 16 178 197 83
-13 -13 16 178 197 83
-12 -13 16 178 197 83
-11 -13 16 178 197 83
-10 -13 16 178 197 83
-9 -13 16 178 197 83
-8 -13 16 178 197 83
-7 -13 16 178 197 83
-6 -13 16 178 197 83
-5 -13 16 178 197 83
-4 -13 16 178 197 83
-3 -13 16 178 197 83
-2 -13 16 178 197 83
-1 -13 16 178 197 83
0 -13 16 178 197 83
1 -13 16 178 197 83
2 -13 16 178 197 83
3 -13 16 178 197 83
4 -13 16 178 197 83
5 -13 16 178 197 83
6 -13 16 178 197 83
7 -13 16 178 197 83
8 -13 16 178 197 83
9 -13 16 178 197 83
10 -13 16 178 197 83
11 -13 16 178 197 83
12 -13 16 178 197 83
13 -13 16 178 197 83
14 -13 16 178 197 83
15 -13 16 178 197 83
16 -13 16 178 197 83
17 -13 16 178 197 83
18 -13 16 178 197 83
19 -13 16 178 197 83
20 -13 16 178 197 83
21 -13 16 178 197 83
22 -13 16 178 197 83
23 -13 16 178 197 83
24 -13 16 178 197 83
25 -13 16 178 197 83
26 -13 16 178 197 83
27 -13 16 178 197 83
28 -13 16 178 197 83
-28 -12 16 178 197 83
-27 -12 16 178 197 83
-26 -12 16 178 197 83
-25 -12 16 178 197 83
-24 -12 16 178 197 83
-23 -12 16 178 197 83
-22 -12 16 178 197 83
-21 -12 16 178 197 83
-20 -12 16 178 197 83
-19 -12 16 178 197 83
-18 -12 16 178 197 83
-17 -12 16 178 197 83
-16 -12 16 178 197 83
-15 -12 16 178 197 83
-14 -12 16 178 197 83
-13 -12 16 178 197 83
-12 -12 16 178 197 83
-11 -12 16 178 197 83
-10 -12 16 178 197 83
-9 -12 16 178 197 83
-8 -12 16 178 197 83
-7 -12 16 178 197 83
-6 -12 16 178 197 83
-5 -12 16 178 197 83
-4 -12 16 178 197 83
-3 -12 16 178 197 83
-2 -12 16 178 197 83
-1 -12 16 178 197 83
0 -12 16 178 197 83
1 -12 16 178 197 83
2 -12 16 178 197 83
3 -12 16 178 197 83
4 -12 16 178 197 83
5 -12 16 178 197 83
6 -12 16 178 197 83
7 -12 16 178 197 83
8 -12 16 178 197 83
9 -12 16 178 197 83
10 -12 16 178 197 83
11 -12 16 178 197 83
12 -12 16 178 197 83
13 -12 16 178 197 83
14 -12 16 178 197 83
15 -12 16 178 197 83
16 -12 16 178 197 83
17 -12 16 178 197 83
18 -12 16 178 197 83
19 -12 16 178 197 83
20 -12 16 178 197 83
21 -12 16 178 197 83
22 -12 16 178 197 83
23 -12 16 178 197 83
24 -12 16 178 197 83
25 -12 16 178 197 83
26 -12 16 178 197 83
27 -12 16 178 197 83
28 -12 16 178 197 83
-28 -11 16 178 197 83
-27 -11 16 178 197 83
-26 -11 16 178 197 83
-25 -11 16 178 197 83
-24 -11 16 178 197 83
-23 -11 16 178 197 83
-22 -11 16 178 197 83
-21 -11 16 178 197 83
-20 -11 16 178 197 83
-19 -11 16 178 197 83
-18 -11 16 178 197 83
-17 -11 16 178 197 83
-16 -11 16 178 197 83
-15 -11 16 178 197 83
-14 -11 16 178 197 83
-13 -11 16 178 197 83
-12 -11 16 178 197 83
-11 -11 16 178 197 83
-10 -11 16 178 197 83
-9 -11 16 178 197 83
-8 -11 16 178 197 83
-7 -11 16 178 197 83
-6 -11 16 178 197 83
-5 -11 16 178 197 83
-4 -11 16 178 197 83
-3 -11 16 178 197 83
-2 -11 16 178 197 83
-1 -11 16 178 197 83
0 -11 16 178 197 83
1 -11 16 178 197 83
2 -11 16 178 197 83
3 -11 16 178 197 83
4 -11 16 178 197 83
5 -11 16 178 197 83
6 -11 16 178 197 83
7 -11 16 178 197 83
8 -11 16 178 197 83
9 -11 16 178 197 83
10 -11 16 178 197 83
11 -11 16 178 197 83
12 -11 16 178 197 83
13 -11 16 178 197 83
14 -11 16 178 197 83
15 -11 16 178 197 83
16 -11 16 178 197 83
17 -11 16 178 197 83
18 -11 16 178 197 83
19 -11 16 178 197 83
20 -11 16 178 197 83
21 -11 16 178 197 83
22 -11 16 178 197 83
23 -11 16 178 197 83
24 -11 16 178 197 83
25 -11 16 178 197 83
26 -11 16 178 197 83
27 -11 16 178 197 83
28 -11 16 178 197 83
-28 -10 16 178 197 83
-27 -10 16 178 197 83
-26 -10 16 178 197 83
-25 -10 16 178 197 83
-24 -10 16 178 197 83
-23 -10 16 178 197 83
-22 -10 16 178 197 83
-21 -10 16 178 197 83
-20 -10 16 178 197 83
-19 -10 16 178 197 83
-18 -10 16 178 197 83
-17 -10 16 178 197 83
-16 -10 16 178 197 83
-15 -10 16 178 197 83
-14 -10 16 178 197 83
-13 -10 16 178 197 83
-12 -10 16 178 197 83
-11 -10 16 178 197 83
-10 -10 16 178 197 83
-9 -10 16 178 197 83
-8 -10 16 178 197 83
-7 -10 16 178 197 83
-6 -10 16 178 197 83
-5 -10 16 178 197 83
-4 -10 16 178 197 83
-3 -10 16 178 197 83
-2 -10 16 178 197 83
-1 -10 16 178 197 83
0 -10 16 178 197 83
1 -10 16 178 197 83
2 -10 16 178 197 83
3 -10 16 178 197 83
4 -10 16 178 197 83
5 -10 16 178 197 83
6 -10 16 178 197 83
7 -10 16 178 197 83
8 -10 16 178 197 83
9 -10 16 178 197 83
10 -10 16 178 197 83
11 -10 16 178 197 83
12 -10 16 178 197 83
13 -10 16 178 197 83
14 -10 16 178 197 83
15 -10 16 178 197 83
16 -10 16 178 197 83
17 -10 16 178 197 83
18 -10 16 178 197 83
19 -10 16 178 197 83
20 -10 16 178 197 83
21 -10 16 178 197 83
22 -10 16 178 197 83
23 -10 16 178 197 83
24 -10 16 178 197 83
25 -10 16 178 197 83
26 -10 16 178 197 83
27 -10 16 178 197 83
28 -10 16 178 197 83
-28 -9 16 178 197 83
-27 -9 16 178 197 83
-26 -9 16 178 197 83
-25 -9 16 178 197 83
-24 -9 16 178 197 83
-23 -9 16 178 197 83
-22 -9 16 178 197 83
-21 -9 16 178 197 83
-20 -9 16 178 197 83
-19 -9 16 178 197 83
-18 -9 16 178 197 83
-17 -9 16 178 197 83
-16 -9 16 178 197 83
-15 -9 16 178 197 83
-14 -9 16 178 197 83
-13 -9 16 178 197 83
-12 -9 16 178 197 83
-11 -9 16 178 197 83
-10 -9 16 178 197 83
-9 -9 16 178 197 83
-8 -9 16 178 197 83
-7 -9 16 178 197 83
-6 -9 16 178 197 83
-5 -9 16 178 197 83
-4 -9 16 178 197 83
-3 -9 16 178 197 83
-2 -9 16 178 197 83
-1 -9 16 178 197 83
0 -9 16 178 197 83
1 -9 16 178 197 83
2 -9 16 178 197 83
3 -9 16 178 197 83
4 -9 16 178 197 83
5 -9 16 178 197 83
6 -9 16 178 197 83
7 -9 16 178 197 83
8 -9 16 178 197 83
9 -9 16 178 197 83
10 -9 16 178 197 83
11 -9 16 178 197 83
12 -9 16 178 197 83
13 -9 16 178 197 83
14 -9 16 178 197 83
15 -9 16 178 197 83
16 -9 16 178 197 83
17 -9 16 178 197 83
18 -9 16 178 197 83
19 -9 16 178 197 83
20 -9 16 178 197 83
21 -9 16 178 197 83
22 -9 16 178 197 83
23 -9 16 178 197 83
24 -9 16 178 197 83
25 -9 16 178 197 83
26 -9 16 178 197 83
27 -9 16 178 197 83
28 -9 16 178 197 83
-28 -8 16 178 197 83
-27 -8 16 178 197 83
-26 -8 16 178 197 83
-25 -8 16 178 197 83
-24 -8 16 178 197 83
-23 -8 16 178 197 83
-22 -8 16 178 197 83
-21 -8 16 178 197 83
-20 -8 16 178 197 83
-19 -8 16 178 197 83
-18 -8 16 178 197 83
-17 -8 16 178 197 83
-16 -8 16 178 197 83
-15 -8 16 178 197 83
-14 -8 16 178 197 83
-13 -8 16 178 197 83
-12 -8 16 178 197 83
-11 -8 16 178 197 83
-10 -8 16 178 197 83
-9 -8 16 178 197 83
-8 -8 16 178 197 83
-7 -8 16 178 197 83
-6 -8 16 178 197 83
-5 -8 16 178 197 83
-4 -8 16 178 197 83
-3 -8 16 178 197 83
-2 -8 16 178 197 83
-1 -8 16 178 197 83
0 -8 16 178 197 83
1 -8 16 178 197 83
2 -8 16 178 197 83
3 -8 16 178 197 83
4 -8 16 178 197 83
5 -8 16 178 197 83
6 -8 16 178 197 83
7 -8 16 178 197 83
8 -8 16 178 197 83
9 -8 16 178 197 83
10 -8 16 178 197 83
11 -8 16 178 197 83
12 -8 16 178 197 83
13 -8 16 178 197 83
14 -8 16 178 197 83
15 -8 16 178 197 83
16 -8 16 178 197 83
17 -8 16 178 197 83
18 -8 16 178 197 83
19 -8 16 178 197 83
20 -8 16 178 197 83
21 -8 16 178 197 83
22 -8 16 178 197 83
23 -8 16 178 197 83
24 -8 16 178 197 83
25 -8 16 178 197 83
26 -8 16 178 197 83
27 -8 16 178 197 83
28 -8 16 178 197 83
-28 -7 16 178 197 83
-27 -7 16 178 197 83
-26 -7 16 178 197 83
-25 -7 16 178 197 83
-24 -7 16 178 197 83
-23 -7 16 178 197 83
-22 -7 16 178 197 83
-21 -7 16 178 197 83
-20 -7 16 178 197 83
-19 -7 16 178 197 83
-18 -7 16 178 197 83
-17 -7 16 178 197 83
-16 -7 16 178 197 83
-15 -7 16 178 197 83
-14 -7 16 178 197 83
-13 -7 16 178 197 83
-12 -7 16 178 197 83
-11 -7 16 178 197 83
-10 -7 16 178 197 83
-9 -7 16 178 197 83
-8 -7 16 178 197 83
-7 -7 16 178 197 83
-6 -7 16 178 197 83
-5 -7 16 178 197 83
-4 -7 16 178 197 83
-3 -7 16 178 197 83
-2 -7 16 178 197 83
-1 -7 16 178 197 83
0 -7 16 178 197 83
1 -7 16 178 197 83
2 -7 16 178 197 83
3 -7 16 178 197 83
4 -7 16 178 197 83
5 -7 16 178 197 83
6 -7 16 178 197 83
7 -7 16 178 197 83
8 -7 16 178 197 83
9 -7 16 178 197 83
10 -7 16 178 197 83
11 -7 16 178 197 83
12 -7 16 178 197 83
13 -7 16 178 197 83
14 -7 16 178 197 83
15 -7 16 178 197 83
16 -7 16 178 197 83
17 -7 16 178 197 83
18 -7 16 178 197 83
19 -7 16 178 197 83
20 -7 16 178 197 83
21 -7 16 178 197 83
22 -7 16 178 197 83
23 -7 16 178 197 83
24 -7 16 178 197 83
25 -7 16 178 197 83
26 -7 16 178 197 83
27 -7 16 178 197 83
28 -7 16 178 197 83
-28 -6 16 178 197 83
-27 -6 16 178 197 83
-26 -6 16 178 197 83
-25 -6 16 178 197 83
-24 -6 16 178 197 83
-23 -6 16 178 197 83
-22 -6 16 178 197 83
-21 -6 16 178 197 83
-20 -6 16 178 197 83
-19 -6 16 178 197 83
-18 -6 16 178 197 83
-17 -6 16 178 197 83
-16 -6 16 178 197 83
-15 -6 16 178 197 83
-14 -6 16 178 197 83
-13 -6 16 178 197 83
-12 -6 16 178 197 83
-11 -6 16 178 197 83
-10 -6 16 178 197 83
-9 -6 16 178 197 83
-8 -6 16 178 197 83
-7 -6 16 178 197 83
-6 -6 16 178 197 83
-5 -6 16 178 197 83
-4 -6 16 178 197 83
-3 -6 16 178 197 83
-2 -6 16 178 197 83
-1 -6 16 178 197 83
0 -6 16 178 197 83
1 -6 16 178 197 83
2 -6 16 178 197 83
3 -6 16 178 197 83
4 -6 16 178 197 83
5 -6 16 178 197 83
6 -6 16 178 197 83
7 -6 16 178 197 83
8 -6 16 178 197 83
9 -6 16 178 197 83
10 -6 16 178 197 83
11 -6 16 178 197 83
12 -6 16 178 197 83
13 -6 16 178 197 83
14 -6 16 178 197 83
15 -6 16 178 197 83
16 -6 16 178 197 83
17 -6 16 178 197 83
18 -6 16 178 197 83
19 -6 16 178 197 83
20 -6 16 178 197 83
21 -6 16 178 197 83
22 -6 16 178 197 83
23 -6 16 178 197 83
24 -6 16 178 197 83
25 -6 16 178 197 83
26 -6 16 178 197 83
27 -6 16 178 197 83
28 -6 16 178 197 83
-28 -5 16 178 197 83
-27 -5 16 178 197 83
-26 -5 16 178 197 83
-25 -5 16 178 197 83
-24 -5 16 178 197 83
-23 -5 16 178 197 83
-22 -5 16 178 197 83
-21 -5 16 178 197 83
-20 -5 16 178 197 83
-19 -5 16 178 197 83
-18 -5 16 178 197 83
-17 -5 16 178 197 83
-16 -5 16 178 197 83
-15 -5 16 178 197 83
-14 -5 16 178 197 83
-13 -5 16 178 197 83
-12 -5 16 178 197 83
-11 -5 16 178 197 83
-10 -5 16 178 197 83
-9 -5 16 178 197 83
-8 -5 16 178 197 83
-7 -5 16 178 197 83
-6 -5 16 178 197 83
-5 -5 16 178 197 83
-4 -5 16 178 197 83
-3 -5 16 178 197 83
-2 -5 16 178 197 83
-1 -5 16 178 197 83
0 -5 16 178 197 83
1 -5 16 178 197 83
2 -5 16 178 197 83
3 -5 16 178 197 83
4 -5 16 178 197 83
5 -5 16 178 197 83
6 -5 16 178 197 83
7 -5 16 178 197 83
8 -5 16 178 197 83
9 -5 16 178 197 83
10 -5 16 178 197 83
11 -5 16 178 197 83
12 -5 16 178 197 83
13 -5 16 178 197 83
14 -5 16 178 197 83
15 -5 16 178 197 83
16 -5 16 178 197 83
17 -5 16 178 197 83
18 -5 16 178 197 83
19 -5 16 178 197 83
20 -5 16 178 197 83
21 -5 16 178 197 83
22 -5 16 178 197 83
23 -5 16 178 197 83
24 -5 16 178 197 83
25 -5 16 178 197 83
26 -5 16 178 197 83
27 -5 16 178 197 83
28 -5 16 178 197 83
-28 -4 16 178 197 83
-27 -4 16 178 197 83
-26 -4 16 178 197 83
-25 -4 16 178 197 83
-24 -4 16 178 197 83
-23 -4 16 178 197 83
-22 -4 16 178 197 83
-21 -4 16 178 197 83
-20 -4 16 178 197 83
-19 -4 16 178 197 83
-18 -4 16 178 197 83
-17 -4 16 178 197 83
-16 -4 16 178 197 83
-15 -4 16 178 197 83
-14 -4 16 178 197 83
-13 -4 16 178 197 83
-12 -4 16 178 197 83
-11 -4 16 178 197 83
-10 -4 16 178 197 83
-9 -4 16 178 197 83
-8 -4 16 178 197 83
-7 -4 16 178 197 83
-6 -4 16 178 197 83
-5 -4 16 178 197 83
-4 -4 16 178 197 83
-3 -4 16 178 197 83
-2 -4 16 178 197 83
-1 -4 16 178 197 83
0 -4 16 178 197 83
1 -4 16 178 197 83
2 -4 16 178 197 83
3 -4 16 178 197 83
4 -4 16 178 197 83
5 -4 16 178 197 83
6 -4 16 178 197 83
7 -4 16 178 197 83
8 -4 16 178 197 83
9 -4 16 178 197 83
10 -4 16 178 197 83
11 -4 16 178 197 83
12 -4 16 178 197 83
13 -4 16 178 197 83
14 -4 16 178 197 83
15 -4 16 178 197 83
16 -4 16 178 197 83
17 -4 16 178 197 83
18 -4 16 178 197 83
19 -4 16 178 197 83
20 -4 16 178 197 83
21 -4 16 178 197 83
22 -4 16 178 197 83
23 -4 16 178 197 83
24 -4 16 178 197 83
25 -4 16 178 197 83
26 -4 16 178 197 83
27 -4 16 178 197 83
28 -4 16 178 197 83
-28 -3 16 178 197 83
-27 -3 16 178 197 83
-26 -3 16 178 197 83
-25 -3 16 178 197 83
-24 -3 16 178 197 83
-23 -3 16 178 197 83
-22 -3 16 178 197 83
-21 -3 16 178 197 83
-20 -3 16 178 197 83
-19 -3 16 178 197 83
-18 -3 16 178 197 83
-17 -3 16 178 197 83
-16 -3 16 178 197 83
-15 -3 16 178 197 83
-14 -3 16 178 197 83
-13 -3 16 178 197 83
-12 -3 16 178 197 83
-11 -3 16 178 197 83
-10 -3 16 178 197 83
-9 -3 16 178 197 83
-8 -3 16 178 197 83
-7 -3 16 178 197 83
-6 -3 16 178 197 83
-5 -3 16 178 197 83
-4 -3 16 178 197 83
-3 -3 16 178 197 83
-2 -3 16 178 197 83
-1 -3 16 178 197 83
0 -3 16 178 197 83
1 -3 16 178 197 83
2 -3 16 178 197 83
3 -3 16 178 197 83
4 -3 16 178 197 83
5 -3 16 178 197 83
6 -3 16 178 197 83
7 -3 16 178 197 83
8 -3 16 178 197 83
9 -3 16 178 197 83
10 -3 16 178 197 83
11 -3 16 178 197 83
12 -3 16 178 197 83
13 -3 16 178 197 83
14 -3 16 178 197 83
15 -3 16 178 197 83
16 -3 16 178 197 83
17 -3 16 178 197 83
18 -3 16 178 197 83
19 -3 16 178 197 83
20 -3 16 178 197 83
21 -3 16 178 197 83
22 -3 16 178 197 83
23 -3 16 178 197 83
24 -3 16 178 197 83
25 -3 16 178 197 83
26 -3 16 178 197 83
27 -3 16 178 197 83
28 -3 16 178 197 83
-28 -2 16 178 197 83
-27 -2 16 178 197 83
-26 -2 16 178 197 83
-25 -2 16 178 197 83
-24 -2 16 178 197 83
-23 -2 16 178 197 83
-22 -2 16 178 197 83
-21 -2 16 178 197 83
-20 -2 16 178 197 83
-19 -2 16 178 197 83
-18 -2 16 178 197 83
-17 -2 16 178 197 83
-16 -2 16 178 197 83
-15 -2 16 178 197 83
-14 -2 16 178 197 83
-13 -2 16 178 197 83
-12 -2 16 178 197 83
-11 -2 16 178 197 83
-10 -2 16 178 197 83
-9 -2 16 178 197 83
-8 -2 16 178 197 83
-7 -2 16 178 197 83
-6 -2 16 178 197 83
-5 -2 16 178 197 83
-4 -2 16 178 197 83
-3 -2 16 178 197 83
-2 -2 16 178 197 83
-1 -2 16 178 197 83
0 -2 16 178 197 83
1 -2 16 178 197 83
2 -2 16 178 197 83
3 -2 16 178 197 83
4 -2 16 178 197 83
5 -2 16 178 197 83
6 -2 16 178 197 83
7 -2 16 178 197 83
8 -2 16 178 197 83
9 -2 16 178 197 83
10 -2 16 178 197 83
11 -2 16 178 197 83
12 -2 16 178 197 83
13 -2 16 178 197 83
14 -2 16 178 197 83
15 -2 16 178 197 83
16 -2 16 178 197 83
17 -2 16 178 197 83
18 -2 16 178 197 83
19 -2 16 178 197 83
20 -2 16 178 197 83
21 -2 16 178 197 83
22 -2 16 178 197 83
23 -2 16 178 197 83
24 -2 16 178 197 83
25 -2 16 178 197 83
26 -2 16 178 197 83
27 -2 16 178 197 83
28 -2 16 178 197 83
-28 -1 16 178 197 83
-27 -1 16 178 197 83
-26 -1 16 178 197 83
-25 -1 16 178 197 83
-24 -1 16 178 197 83
-23 -1 16 178 197 83
-22 -1 16 178 197 83
-21 -1 16 178 197 83
-20 -1 16 178 197 83
-19 -1 16 178 197 83
-18 -1 16 178 197 83
-17 -1 16 178 197 83
-16 -1 16 178 197 83
-15 -1 16 178 197 83
-14 -1 16 178 197 83
-13 -1 16 178 197 83
-12 -1 16 178 197 83
-11 -1 16 178 197 83
-10 -1 16 178 197 83
-9 -1 16 178 197 83
-8 -1 16 178 197 83
-7 -1 16 178 197 83
-6 -1 16 178 197 83
-5 -1 16 178 197 83
-4 -1 16 178 197 83
-3 -1 16 178 197 83
-2 -1 16 178 197 83
-1 -1 16 178 197 83
0 -1 16 178 197 83
1 -1 16 178 197 83
2 -1 16 178 197 83
3 -1 16 178 197 83
4 -1 16 178 197 83
5 -1 16 178 197 83
6 -1 16 178 197 83
7 -1 16 178 197 83
8 -1 16 178 197 83
9 -1 16 178 197 83
10 -1 16 178 197 83
11 -1 16 178 197 83
12 -1 16 178 197 83
13 -1 16 178 197 83
14 -1 16 178 197 83
15 -1 16 178 197 83
16 -1 16 178 197 83
17 -1 16 178 197 83
18 -1 16 178 197 83
19 -1 16 178 197 83
20 -1 16 178 197 83
21 -1 16 178 197 83
22 -1 16 178 197 83
23 -1 16 178 197 83
24 -1 16 178 197 83
25 -1 16 178 197 83
26 -1 16 178 197 83
27 -1 16 178 197 83
28 -1 16 178 197 83
-28 0 16 178 197 83
-27 0 16 178 197 83
-26 0 16 178 197 83
-25 0 16 178 197 83
-24 0 16 178 197 83
-23 0 16 178 197 83
-22 0 16 178 197 83
-21 0 16 178 197 83
-20 0 16 178 197 83
-19 0 16 178 197 83
-18 0 16 178 197 83
-17 0 16 178 197 83
-16 0 16 178 197 83
-15 0 16 178 197 83
-14 0 16 178 197 83
-13 0 16 178 197 83
-12 0 16 178 197 83
-11 0 16 178 197 83
-10 0 16 178 197 83
-9 0 16 178 197 83
-8 0 16 178 197 83
-7 0 16 178 197 83
-6 0 16 178 197 83
-5 0 16 178 197 83
-4 0 16 178 197 83
-3 0 16 178 197 83
-2 0 16 178 197 83
-1 0 16 178 197 83
0 0 16 178 197 83
1 0 16 178 197 83
2 0 16 178 197 83
3 0 16 178 197 83
4 0 16 178 197 83
5 0 16 178 197 83
6 0 16 178 197 83
7 0 16 178 197 83
8 0 16 178 197 83
9 0 16 178 197 83
10 0 16 178 197 83
11 0 16 178 197 83
12 0 16 178 197 83
13 0 16 178 197 83
14 0 16 178 197 83
15 0 16 178 197 83
16 0 16 178 197 83
17 0 16 178 197 83
18 0 16 178 197 83
19 0 16 178 197 83
20 0 16 178 197 83
21 0 16 178 197 83
22 0 16 178 197 83
23 0 16 178 197 83
24 0 16 178 197 83
25 0 16 178 197 83
26 0 16 178 197 83
27 0 16 178 197 83
28 0 16 178 197 83
-28 1 16 178 197 83
-27 1 16 178 197 83
-26 1 16 178 197 83
-25 1 16 178 197 83
-24 1 16 178 197 83
-23 1 16 178 197 83
-22 1 16 178 197 83
-21 1 16 178 197 83
-20 1 16 178 197 83
-19 1 16 178 197 83
-18 1 16 178 197 83
-17 1 16 178 197 83
-16 1 16 178 197 83
-15 1 16 178 197 83
-14 1 16 178 197 83
-13 1 16 178 197 83
-12 1 16 178 197 83
-11 1 16 178 197 83
-10 1 16 178 197 83
-9 1 16 178 197 83
-8 1 16 178 197 83
-7 1 16 178 197 83
-6 1 16 178 197 83
-5 1 16 178 197 83
-4 1 16 178 197 83
-3 1 16 178 197 83
-2 1 16 178 197 83
-1 1 16 178 197 83
0 1 16 178 197 83
1 1 16 178 197 83
2 1 16 178 197 83
3 1 16 178 197 83
4 1 16 178 197 83
5 1 16 178 197 83
6 1 16 178 197 83
7 1 16 178 197 83
8 1 16 178 197 83
9 1 16 178 197 83
10 1 16 178 197 83
11 1 16 178 197 83
12 1 16 178 197 83
13 1 16 178 197 83
14 1 16 178 197 83
15 1 16 178 197 83
16 1 16 178 197 83
17 1 16 178 197 83
18 1 16 178 197 83
19 1 16 178 197 83
20 1 16 178 197 83
21 1 16 178 197 83
22 1 16 178 197 83
23 1 16 178 197 83
24 1 16 178 197 83
25 1 16 178 197 83
26 1 16 178 197 83
27 1 16 178 197 83
28 1 16 178 197 83
-28 2 16 178 197 83
-27 2 16 178 197 83
-26 2 16 178 197 83
-25 2 16 178 197 83
-24 2 16 178 197 83
-23 2 16 178 197 83
-22 2 16 178 197 83
-21 2 16 178 197 83
-20 2 16 178 197 83
-19 2 16 178 197 83
-18 2 16 178 197 83
-17 2 16 178 197 83
-16 2 16 178 197 83
-15 2 16 178 197 83
-14 2 16 178 197 83
-13 2 16 178 197 83
-12 2 16 178 197 83
-11 2 16 178 197 83
-10 2 16 178 197 83
-9 2 16 178 197 83
-8 2 16 178 197 83
-7 2 16 178 197 83
-6 2 16 178 197 83
-5 2 16 178 197 83
-4 2 16 178 197 83
-3 2 16 178 197 83
-2 2 16 178 197 83
-1 2 16 178 197 83
0 2 16 178 197 83
1 2 16 178 197 83
2 2 16 178 197 83
3 2 16 178 197 83
4 2 16 178 197 83
5 2 16 178 197 83
6 2 16 178 197 83
7 2 16 178 197 83
8 2 16 178 197 83
9 2 16 178 197 83
10 2 16 178 197 83
11 2 16 178 197 83
12 2 16 178 197 83
13 2 16 178 197 83
14 2 16 178 197 83
15 2 16 178 197 83
16 2 16 178 197 83
17 2 16 178 197 83
18 2 16 178 197 83
19 2 16 178 197 83
20 2 16 178 197 83
21 2 16 178 197 83
22 2 16 178 197 83
23 2 16 178 197 83
24 2 16 178 197 83
25 2 16 178 197 83
26 2 16 178 197 83
27 2 16 178 197 83
28 2 16 178 197 83
-28 3 16 178 197 83
-27 3 16 178 197 83
-26 3 16 178 197 83
-25 3 16 178 197 83
-24 3 16 178 197 83
-23 3 16 178 197 83
-22 3 16 178 197 83
-21 3 16 178 197 83
-20 3 16 178 197 83
-19 3 16 178 197 83
-18 3 16 178 197 83
-17 3 16 178 197 83
-16 3 16 178 197 83
-15 3 16 178 197 83
-14 3 16 178 197 83
-13 3 16 178 197 83
-12 3 16 178 197 83
-11 3 16 178 197 83
-10 3 16 178 197 83
-9 3 16 178 197 83
-8 3 16 178 197 83
-7 3 16 178 197 83
-6 3 16 178 197 83
-5 3 16 178 197 83
-4 3 16 178 197 83
-3 3 16 178 197 83
-2 3 16 178 197 83
-1 3 16 178 197 83
0 3 16 178 197 83
1 3 16 178 197 83
2 3 16 178 197 83
3 3 16 178 197 83
4 3 16 178 197 83
5 3 16 178 197 83
6 3 16 178 197 83
7 3 16 178 197 83
8 3 16 178 197 83
9 3 16 178 197 83
10 3 16 178 197 83
11 3 16 178 197 83
12 3 16 178 197 83
13 3 16 178 197 83
14 3 16 178 197 83
15 3 16 178 197 83
16 3 16 178 197 83
17 3 16 178 197 83
18 3 16 178 197 83
19 3 16 178 197 83
20 3 16 178 197 83
21 3 16 178 197 83
22 3 16 178 197 83
23 3 16 178 197 83
24 3 16 178 197 83
25 3 16 178 197 83
26 3 16 178 197 83
27 3 16 178 197 83
28 3 16 178 197 83
-28 4 16 178 197 83
-27 4 16 178 197 83
-26 4 16 178 197 83
-25 4 16 178 197 83
-24 4 16 178 197 83
-23 4 16 178 197 83
-22 4 16 178 197 83
-21 4 16 178 197 83
-20 4 16 178 197 83
-19 4 16 178 197 83
-18 4 16 178 197 83
-17 4 16 178 197 83
-16 4 16 178 197 83
-15 4 16 178 197 83
-14 4 16 178 197 83
-13 4 16 178 197 83
-12 4 16 178 197 83
-11 4 16 178 197 83
-10 4 16 178 197 83
-9 4 16 178 197 83
-8 4 16 178 197 83
-7 4 16 178 197 83
-6 4 16 178 197 83
-5 4 16 178 197 83
-4 4 16 178 197 83
-3 4 16 178 197 83
-2 4 16 178 197 83
-1 4 16 178 197 83
0 4 16 178 197 83
1 4 16 178 197 83
2 4 16 178 197 83
3 4 16 178 197 83
4 4 16 178 197 83
5 4 16 178 197 83
6 4 16 178 197 83
7 4 16 178 197 83
8 4 16 178 197 83
9 4 16 178 197 83
10 4 16 178 197 83
11 4 16 178 197 83
12 4 16 178 197 83
13 4 16 178 197 83
14 4 16 178 197 83
15 4 16 178 197 83
16 4 16 178 197 83
17 4 16 178 197 83
18 4 16 178 197 83
19 4 16 178 197 83
20 4 16 178 197 83
21 4 16 178 197 83
22 4 16 178 197 83
23 4 16 178 197 83
24 4 16 178 197 83
25 4 16 178 197 83
26 4 16 178 197 83
27 4 16 178 197 83
28 4 16 178 197 83
-28 5 16 178 197 83
-27 5 16 178 197 83
-26 5 16 178 197 83
-25 5 16 178 197 83
-24 5 16 178 197 83
-23 5 16 178 197 83
-22 5 16 178 197 83
-21 5 16 178 197 83
-20 5 16 178 197 83
-19 5 16 178 197 83
-18 5 16 178 197 83
-17 5 16 178 197 83
-16 5 16 178 197 83
-15 5 16 178 197 83
-14 5 16 178 197 83
-13 5 16 178 197 83
-12 5 16 178 197 83
-11 5 16 178 197 83
-10 5 16 178 197 83
-9 5 16 178 197 83
-8 5 16 178 197 83
-7 5 16 178 197 83
-6 5 16 178 197 83
-5 5 16 178 197 83
-4 5 16 178 197 83
-3 5 16 178 197 83
-2 5 16 178 197 83
-1 5 16 178 197 83
0 5 16 178 197 83
1 5 16 178 197 83
2 5 16 178 197 83
3 5 16 178 197 83
4 5 16 178 197 83
5 5 16 178 197 83
6 5 16 178 197 83
7 5 16 178 197 83
8 5 16 178 197 83
9 5 16 178 197 83
10 5 16 178 197 83
11 5 16 178 197 83
12 5 16 178 197 83
13 5 16 178 197 83
14 5 16 178 197 83
15 5 16 178 197 83
16 5 16 178 197 83
17 5 16 178 197 83
18 5 16 178 197 83
19 5 16 178 197 83
20 5 16 178 197 83
21 5 16 178 197 83
22 5 16 178 197 83
23 5 16 178 197 83
24 5 16 178 197 83
25 5 16 178 197 83
26 5 16 178 197 83
27 5 16 178 197 83
28 5 16 178 197 83
-28 6 16 178 197 83
-27 6 16 178 197 83
-26 6 16 178 197 83
-25 6 16 178 197 83
-24 6 16 178 197 83
-23 6 16 178 197 83
-22 6 16 178 197 83
-21 6 16 178 197 83
-20 6 16 178 197 83
-19 6 16 178 197 83
-18 6 16 178 197 83
-17 6 16 178 197 83
-16 6 16 178 197 83
-15 6 16 178 197 83
-14 6 16 178 197 83
-13 6 16 178 197 83
-12 6 16 178 197 83
-11 6 16 178 197 83
-10 6 16 178 197 83
-9 6 16 178 197 83
-8 6 16 178 197 83
-7 6 16 178 197 83
-6 6 16 178 197 83
-5 6 16 178 197 83
-4 6 16 178 197 83
-3 6 16 178 197 83
-2 6 16 178 197 83
-1 6 16 178 197 83
0 6 16 178 197 83
1 6 16 178 197 83
2 6 16 178 197 83
3 6 16 178 197 83
4 6 16 178 197 83
5 6 16 178 197 83
6 6 16 178 197 83
7 6 16 178 197 83
8 6 16 178 197 83
9 6 16 178 197 83
10 6 16 178 197 83
11 6 16 178 197 83
12 6 16 178 197 83
13 6 16 178 197 83
14 6 16 178 197 83
15 6 16 178 197 83
16 6 16 178 197 83
17 6 16 178 197 83
18 6 16 178 197 83
19 6 16 178 197 83
20 6 16 178 197 83
21 6 16 178 197 83
22 6 16 178 197 83
23 6 16 178 197 83
24 6 16 178 197 83
25 6 16 178 197 83
26 6 16 178 197 83
27 6 16 178 197 83
28 6 16 178 197 83
-28 7 16 178 197 83
-27 7 16 178 197 83
-26 7 16 178 197 83
-25 7 16 178 197 83
-24 7 16 178 197 83
-23 7 16 178 197 83
-22 7 16 178 197 83
-21 7 16 178 197 83
-20 7 16 178 197 83
-19 7 16 178 197 83
-18 7 16 178 197 83
-17 7 16 178 197 83
-16 7 16 178 197 83
-15 7 16 178 197 83
-14 7 16 178 197 83
-13 7 16 178 197 83
-12 7 16 178 197 83
-11 7 16 178 197 83
-10 7 16 178 197 83
-9 7 16 178 197 83
-8 7 16 178 197 83
-7 7 16 178 197 83
-6 7 16 178 197 83
-5 7 16 178 197 83
-4 7 16 178 197 83
-3 7 16 178 197 83
-2 7 16 178 197 83
-1 7 16 178 197 83
0 7 16 178 197 83
1 7 16 178 197 83
2 7 16 178 197 83
3 7 16 178 197 83
4 7 16 178 197 83
5 7 16 178 197 83
6 7 16 178 197 83
7 7 16 178 197 83
8 7 16 178 197 83
9 7 16 178 197 83
10 7 16 178 197 83
11 7 16 178 197 83
12 7 16 178 197 83
13 7 16 178 197 83
14 7 16 178 197 83
15 7 16 178 197 83
16 7 16 178 197 83
17 7 16 178 197 83
18 7 16 178 197 83
19 7 16 178 197 83
20 7 16 178 197 83
21 7 16 178 197 83
22 7 16 178 197 83
23 7 16 178 197 83
24 7 16 178 197 83
25 7 16 178 197 83
26 7 16 178 197 83
27 7 16 178 197 83
28 7 16 178 197 83
-28 8 16 178 197 83
-27 8 16 178 197 83
-26 8 16 178 197 83
-25 8 16 178 197 83
-24 8 16 178 197 83
-23 8 16 178 197 83
-22 8 16 178 197 83
-21 8 16 178 197 83
-20 8 16 178 197 83
-19 8 16 178 197 83
-18 8 16 178 197 83
-17 8 16 178 197 83
-16 8 16 178 197 83
-15 8 16 178 197 83
-14 8 16 178 197 83
-13 8 16 178 197 83
-12 8 16 178 197 83
-11 8 16 178 197 83
-10 8 16 178 197 83
-9 8 16 178 197 83
-8 8 16 178 197 83
-7 8 16 178 197 83
-6 8 16 178 197 83
-5 8 16 178 197 83
-4 8 16 178 197 83
-3 8 16 178 197 83
-2 8 16 178 197 83
-1 8 16 178 197 83
0 8 16 178 197 83
1 8 16 178 197 83
2 8 16 178 197 83
3 8 16 178 197 83
4 8 16 178 197 83
5 8 16 178 197 83
6 8 16 178 197 83
7 8 16 178 197 83
8 8 16 178 197 83
9 8 16 178 197 83
10 8 16 178 197 83
11 8 16 178 197 83
12 8 16 178 197 83
13 8 16 178 197 83
14 8 16 178 197 83
15 8 16 178 197 83
16 8 16 178 197 83
17 8 16 178 197 83
18 8 16 178 197 83
19 8 16 178 197 83
20 8 16 178 197 83
21 8 16 178 197 83
22 8 16 178 197 83
23 8 16 178 197 83
24 8 16 178 197 83
25 8 16 178 197 83
26 8 16 178 197 83
27 8 16 178 197 83
28 8 16 178 197 83
-28 9 16 178 197 83
-27 9 16 178 197 83
-26 9 16 178 197 83
-25 9 16 178 197 83
-24 9 16 178 197 83
-23 9 16 178 197 83
-22 9 16 178 197 83
-21 9 16 178 197 83
-20 9 16 178 197 83
-19 9 16 178 197 83
-18 9 16 178 197 83
-17 9 16 178 197 83
-16 9 16 178 197 83
-15 9 16 178 197 83
-14 9 16 178 197 83
-13 9 16 178 197 83
-12 9 16 178 197 83
-11 9 16 178 197 83
-10 9 16 178 197 83
-9 9 16 178 197 83
-8 9 16 178 197 83
-7 9 16 178 197 83
-6 9 16 178 197 83
-5 9 16 178 197 83
-4 9 16 178 197 83
-3 9 16 178 197 83
-2 9 16 178 197 83
-1 9 16 178 197 83
0 9 16 178 197 83
1 9 16 178 197 83
2 9 16 178 197 83
3 9 16 178 197 83
4 9 16 178 197 83
5 9 16 178 197 83
6 9 16 178 197 83
7 9 16 178 197 83
8 9 16 178 197 83
9 9 16 178 197 83
10 9 16 178 197 83
11 9 16 178 197 83
12 9 16 178 197 83
13 9 16 178 197 83
14 9 16 178 197 83
15 9 16 178 197 83
16 9 16 178 197 83
17 9 16 178 197 83
18 9 16 178 197 83
19 9 16 178 197 83
20 9 16 178 197 83
21 9 16 178 197 83
22 9 16 178 197 83
23 9 16 178 197 83
24 9 16 178 197 83
25 9 16 178 197 83
26 9 16 178 197 83
27 9 16 178 197 83
28 9 16 178 197 83
-28 10 16 178 197 83
-27 10 16 178 197 83
-26 10 16 178 197 83
-25 10 16 178 197 83
-24 10 16 178 197 83
-23 10 16 178 197 83
-22 10 16 178 197 83
-21 10 16 178 197 83
-20 10 16 178 197 83
-19 10 16 178 197 83
-18 10 16 178 197 83
-17 10 16 178 197 83
-16 10 16 178 197 83
-15 10 16 178 197 83
-14 10 16 178 197 83
-13 10 16 178 197 83
-12 10 16 178 197 83
-11 10 16 178 197 83
-10 10 16 178 197 83
-9 10 16 178 197 83
-8 10 16 178 197 83
-7 10 16 178 197 83
-6 10 16 178 197 83
-5 10 16 178 197 83
-4 10 16 178 197 83
-3 10 16 178 197 83
-2 10 16 178 197 83
-1 10 16 178 197 83
0 10 16 178 197 83
1 10 16 178 197 83
2 10 16 178 197 83
3 10 16 178 197 83
4 10 16 178 197 83
5 10 16 178 197 83
6 10 16 178 197 83
7 10 16 178 197 83
8 10 16 178 197 83
9 10 16 178 197 83
10 10 16 178 197 83
11 10 16 178 197 83
12 10 16 178 197 83
13 10 16 178 197 83
14 10 16 178 197 83
15 10 16 178 197 83
16 10 16 178 197 83
17 10 16 178 197 83
18 10 16 178 197 83
19 10 16 178 197 83
20 10 16 178 197 83
21 10 16 178 197 83
22 10 16 178 197 83
23 10 16 178 197 83
24 10 16 178 197 83
25 10 16 178 197 83
26 10 16 178 197 83
27 10 16 178 197 83
28 10 16 178 197 83
-28 11 16 178 197 83
-27 11 16 178 197 83
-26 11 16 178 197 83
-25 11 16 178 197 83
-24 11 16 178 197 83
-23 11 16 178 197 83
-22 11 16 178 197 83
-21 11 16 178 197 83
-20 11 16 178 197 83
-19 11 16 178 197 83
-18 11 16 178 197 83
-17 11 16 178 197 83
-16 11 16 178 197 83
-15 11 16 178 197 83
-14 11 16 178 197 83
-13 11 16 178 197 83
-12 11 16 178 197 83
-11 11 16 178 197 83
-10 11 16 178 197 83
-9 11 16 178 197 83
-8 11 16 178 197 83
-7 11 16 178 197 83
-6 11 16 178 197 83
-5 11 16 178 197 83
-4 11 16 178 197 83
-3 11 16 178 197 83
-2 11 16 178 197 83
-1 11 16 178 197 83
0 11 16 178 197 83
1 11 16 178 197 83
2 11 16 178 197 83
3 11 16 178 197 83
4 11 16 178 197 83
5 11 16 178 197 83
6 11 16 178 197 83
7 11 16 178 197 83
8 11 16 178 197 83
9 11 16 178 197 83
10 11 16 178 197 83
11 11 16 178 197 83
12 11 16 178 197 83
13 11 16 178 197 83
14 11 16 178 197 83
15 11 16 178 197 83
16 11 16 178 197 83
17 11 16 178 197 83
18 11 16 178 197 83
19 11 16 178 197 83
20 11 16 178 197 83
21 11 16 178 197 83
22 11 16 178 197 83
23 11 16 178 197 83
24 11 16 178 197 83
25 11 16 178 197 83
26 11 16 178 197 83
27 11 16 178 197 83
28 11 16 178 197 83
-28 12 16 178 197 83
-27 12 16 178 197 83
-26 12 16 178 197 83
-25 12 16 178 197 83
-24 12 16 178 197 83
-23 12 16 178 197 83
-22 12 16 178 197 83
-21 12 16 178 197 83
-20 12 16 178 197 83
-19 12 16 178 197 83
-18 12 16 178 197 83
-17 12 16 178 197 83
-16 12 16 178 197 83
-15 12 16 178 197 83
-14 12 16 178 197 83
-13 12 16 178 197 83
-12 12 16 178 197 83
-11 12 16 178 197 83
-10 12 16 178 197 83
-9 12 16 178 197 83
-8 12 16 178 197 83
-7 12 16 178 197 83
-6 12 16 178 197 83
-5 12 16 178 197 83
-4 12 16 178 197 83
-3 12 16 178 197 83
-2 12 16 178 197 83
-1 12 16 178 197 83
0 12 16 178 197 83
1 12 16 178 197 83
2 12 16 178 197 83
3 12 16 178 197 83
4 12 16 178 197 83
5 12 16 178 197 83
6 12 16 178 197 83
7 12 16 178 197 83
8 12 16 178 197 83
9 12 16 178 197 83
10 12 16 178 197 83
11 12 16 178 197 83
12 12 16 178 197 83
13 12 16 178 197 83
14 12 16 178 197 83
15 12 16 178 197 83
16 12 16 178 197 83
17 12 16 178 197 83
18 12 16 178 197 83
19 12 16 178 197 83
20 12 16 178 197 83
21 12 16 178 197 83
22 12 16 178 197 83
23 12 16 178 197 83
24 12 16 178 197 83
25 12 16 178 197 83
26 12 16 178 197 83
27 12 16 178 197 83
28 12 16 178 197 83
-28 13 16 178 197 83
-27 13 16 178 197 83
-26 13 16 178 197 83
-25 13 16 178 197 83
-24 13 16 178 197 83
-23 13 16 178 197 83
-22 13 16 178 197 83
-21 13 16 178 197 83
-20 13 16 178 197 83
-19 13 16 178 197 83
-18 13 16 178 197 83
-17 13 16 178 197 83
-16 13 16 178 197 83
-15 13 16 178 197 83
-14 13 16 178 197 83
-13 13 16 178 197 83
-12 13 16 178 197 83
-11 13 16 178 197 83
-10 13 16 178 197 83
-9 13 16 178 197 83
-8 13 16 178 197 83
-7 13 16 178 197 83
-6 13 16 178 197 83
-5 13 16 178 197 83
-4 13 16 178 197 83
-3 13 16 178 197 83
-2 13 16 178 197 83
-1 13 16 178 197 83
0 13 16 178 197 83
1 13 16 178 197 83
2 13 16 178 197 83
3 13 16 178 197 83
4 13 16 178 197 83
5 13 16 178 197 83
6 13 16 178 197 83
7 13 16 178 197 83
8 13 16 178 197 83
9 13 16 178 197 83
10 13 16 178 197 83
11 13 16 178 197 83
12 13 16 178 197 83
13 13 16 178 197 83
14 13 16 178 197 83
15 13 16 178 197 83
16 13 16 178 197 83
17 13 16 178 197 83
18 13 16 178 197 83
19 13 16 178 197 83
20 13 16 178 197 83
21 13 16 178 197 83
22 13 16 178 197 83
23 13 16 178 197 83
24 13 16 178 197 83
25 13 16 178 197 83
26 13 16 178 197 83
27 13 16 178 197 83
28 13 16 178 197 83
-28 14 16 178 197 83
-27 14 16 178 197 83
-26 14 16 178 197 83
-25 14 16 178 197 83
-24 14 16 178 197 83
-23 14 16 178 197 83
-22 14 16 178 197 83
-21 14 16 178 197 83
-20 14 16 178 197 83
-19 14 16 178 197 83
-18 14 16 178 197 83
-17 14 16 178 197 83
-16 14 16 178 197 83
-15 14 16 178 197 83
-14 14 16 178 197 83
-13 14 16 178 197 83
-12 14 16 178 197 83
-11 14 16 178 197 83
-10 14 16 178 197 83
-9 14 16 178 197 83
-8 14 16 178 197 83
-7 14 16 178 197 83
-6 14 16 178 197 83
-5 14 16 178 197 83
-4 14 16 178 197 83
-3 14 16 178 197 83
-2 14 16 178 197 83
-1 14 16 178 197 83
0 14 16 178 197 83
1 14 16 178 197 83
2 14 16 178 197 83
3 14 16 178 197 83
4 14 16 178 197 83
5 14 16 178 197 83
6 14 16 178 197 83
7 14 16 178 197 83
8 14 16 178 197 83
9 14 16 178 197 83
10 14 16 178 197 83
11 14 16 178 197 83
12 14 16 178 197 83
13 14 16 178 197 83
14 14 16 178 197 83
15 14 16 178 197 83
16 14 16 178 197 83
17 14 16 178 197 83
18 14 16 178 197 83
19 14 16 178 197 83
20 14 16 178 197 83
21 14 16 178 197 83
22 14 16 178 197 83
23 14 16 178 197 83
24 14 16 178 197 83
25 14 16 178 197 83
26 14 16 178 197 83
27 14 16 178 197 83
28 14 16 178 197 83
-28 15 16 178 197 83
-27 15 16 178 197 83
-26 15 16 178 197 83
-25 15 16 178 197 83
-24 15 16 178 197 83
-23 15 16 178 197 83
-22 15 16 178 197 83
-21 15 16 178 197 83
-20 15 16 178 197 83
-19 15 16 178 197 83
-18 15 16 178 197 83
-17 15 16 178 197 83
-16 15 16 178 197 83
-15 15 16 178 197 83
-14 15 16 178 197 83
-13 15 16 178 197 83
-12 15 16 178 197 83
-11 15 16 178 197 83
-10 15 16 178 197 83
-9 15 16 178 197 83
-8 15 16 178 197 83
-7 15 16 178 197 83
-6 15 16 178 197 83
-5 15 16 178 197 83
-4 15 16 178 197 83
-3 15 16 178 197 83
-2 15 16 178 197 83
-1 15 16 178 197 83
0 15 16 178 197 83
1 15 16 178 197 83
2 15 16 178 197 83
3 15 16 178 197 83
4 15 16 178 197 83
5 15 16 178 197 83
6 15 16 178 197 83
7 15 16 178 197 83
8 15 16 178 197 83
9 15 16 178 197 83
10 15 16 178 197 83
11 15 16 178 197 83
12 15 16 178 197 83
13 15 16 178 197 83
14 15 16 178 197 83
15 15 16 178 197 83
16 15 16 178 197 83
17 15 16 178 197 83
18 15 16 178 197 83
19 15 16 178 197 83
20 15 16 178 197 83
21 15 16 178 197 83
22 15 16 178 197 83
23 15 16 178 197 83
24 15 16 178 197 83
25 15 16 178 197 83
26 15 16 178 197 83
27 15 16 178 197 83
28 15 16 178 197 83
-28 16 16 178 197 83
-27 16 16 178 197 83
-26 16 16 178 197 83
-25 16 16 178 197 83
-24 16 16 178 197 83
-23 16 16 178 197 83
-22 16 16 178 197 83
-21 16 16 178 197 83
-20 16 16 178 197 83
-19 16 16 178 197 83
-18 16 16 178 197 83
-17 16 16 178 197 83
-16 16 16 178 197 83
-15 16 16 178 197 83
-14 16 16 178 197 83
-13 16 16 178 197 83
-12 16 16 178 197 83
-11 16 16 178 197 83
-10 16 16 178 197 83
-9 16 16 178 197 83
-8 16 16 178 197 83
-7 16 16 178 197 83
-6 16 16 178 197 83
-5 16 16 178 197 83
-4 16 16 178 197 83
-3 16 16 178 197 83
-2 16 16 178 197 83
-1 16 16 178 197 83
0 16 16 178 197 83
1 16 16 178 197 83
2 16 16 178 197 83
3 16 16 178 197 83
4 16 16 178 197 83
5 16 16 178 197 83
6 16 16 178 197 83
7 16 16 178 197 83
8 16 16 178 197 83
9 16 16 178 197 83
10 16 16 178 197 83
11 16 16 178 197 83
12 16 16 178 197 83
13 16 16 178 197 83
14 16 16 178 197 83
15 16 16 178 197 83
16 16 16 178 197 83
17 16 16 178 197 83
18 16 16 178 197 83
19 16 16 178 197 83
20 16 16 178 197 83
21 16 16 178 197 83
22 16 16 178 197 83
23 16 16 178 197 83
24 16 16 178 197 83
25 16 16 178 197 83
26 16 16 178 197 83
27 16 16 178 197 83
28 16 16 178 197 83
-28 17 16 178 197 83
-27 17 16 178 197 83
-26 17 16 178 197 83
-25 17 16 178 197 83
-24 17 16 178 197 83
-23 17 16 178 197 83
-22 17 16 178 197 83
-21 17 16 178 197 83
-20 17 16 178 197 83
-19 17 16 178 197 83
-18 17 16 178 197 83
-17 17 16 178 197 83
-16 17 16 178 197 83
-15 17 16 178 197 83
-14 17 16 178 197 83
-13 17 16 178 197 83
-12 17 16 178 197 83
-11 17 16 178 197 83
-10 17 16 178 197 83
-9 17 16 178 197 83
-8 17 16 178 197 83
-7 17 16 178 197 83
-6 17 16 178 197 83
-5 17 16 178 197 83
-4 17 16 178 197 83
-3 17 16 178 197 83
-2 17 16 178 197 83
-1 17 16 178 197 83
0 17 16 178 197 83
1 17 16 178 197 83
2 17 16 178 197 83
3 17 16 178 197 83
4 17 16 178 197 83
5 17 16 178 197 83
6 17 16 178 197 83
7 17 16 178 197 83
8 17 16 178 197 83
9 17 16 178 197 83
10 17 16 178 197 83
11 17 16 178 197 83
12 17 16 178 197 83
13 17 16 178 197 83
14 17 16 178 197 83
15 17 16 178 197 83
16 17 16 178 197 83
17 17 16 178 197 83
18 17 16 178 197 83
19 17 16 178 197 83
20 17 16 178 197 83
21 17 16 178 197 83
22 17 16 178 197 83
23 17 16 178 197 83
24 17 16 178 197 83
25 17 16 178 197 83
26 17 16 178 197 83
27 17 16 178 197 83
28 17 16 178 197 83
-28 18 16 178 197 83
-27 18 16 178 197 83
-26 18 16 178 197 83
-25 18 16 178 197 83
-24 18 16 178 197 83
-23 18 16 178 197 83
-22 18 16 178 197 83
-21 18 16 178 197 83
-20 18 16 178 197 83
-19 18 16 178 197 83
-18 18 16 178 197 83
-17 18 16 178 197 83
-16 18 16 178 197 83
-15 18 16 178 197 83
-14 18 16 178 197 83
-13 18 16 178 197 83
-12 18 16 178 197 83
-11 18 16 178 197 83
-10 18 16 178 197 83
-9 18 16 178 197 83
-8 18 16 178 197 83
-7 18 16 178 197 83
-6 18 16 178 197 83
-5 18 16 178 197 83
-4 18 16 178 197 83
-3 18 16 178 197 83
-2 18 16 178 197 83
-1 18 16 178 197 83
0 18 16 178 197 83
1 18 16 178 197 83
2 18 16 178 197 83
3 18 16 178 197 83
4 18 16 178 197 83
5 18 16 178 197 83
6 18 16 178 197 83
7 18 16 178 197 83
8 18 16 178 197 83
9 18 16 178 197 83
10 18 16 178 197 83
11 18 16 178 197 83
12 18 16 178 197 83
13 18 16 178 197 83
14 18 16 178 197 83
15 18 16 178 197 83
16 18 16 178 197 83
17 18 16 178 197 83
18 18 16 178 197 83
19 18 16 178 197 83
20 18 16 178 197 83
21 18 16 178 197 83
22 18 16 178 197 83
23 18 16 178 197 83
24 18 16 178 197 83
25 18 16 178 197 83
26 18 16 178 197 83
27 18 16 178 197 83
28 18 16 178 197 83
-28 19 16 178 197 83
-27 19 16 178 197 83
-26 19 16 178 197 83
-25 19 16 178 197 83
-24 19 16 178 197 83
-23 19 16 178 197 83
-22 19 16 178 197 83
-21 19 16 178 197 83
-20 19 16 178 197 83
-19 19 16 178 197 83
-18 19 16 178 197 83
-17 19 16 178 197 83
-16 19 16 178 197 83
-15 19 16 178 197 83
-14 19 16 178 197 83
-13 19 16 178 197 83
-12 19 16 178 197 83
-11 19 16 178 197 83
-10 19 16 178 197 83
-9 19 16 178 197 83
-8 19 16 178 197 83
-7 19 16 178 197 83
-6 19 16 178 197 83
-5 19 16 178 197 83
-4 19 16 178 197 83
-3 19 16 178 197 83
-2 19 16 178 197 83
-1 19 16 178 197 83
0 19 16 178 197 83
1 19 16 178 197 83
2 19 16 178 197 83
3 19 16 178 197 83
4 19 16 178 197 83
5 19 16 178 197 83
6 19 16 178 197 83
7 19 16 178 197 83
8 19 16 178 197 83
9 19 16 178 197 83
10 19 16 178 197 83
11 19 16 178 197 83
12 19 16 178 197 83
13 19 16 178 197 83
14 19 16 178 197 83
15 19 16 178 197 83
16 19 16 178 197 83
17 19 16 178 197 83
18 19 16 178 197 83
19 19 16 178 197 83
20 19 16 178 197 83
21 19 16 178 197 83
22 19 16 178 197 83
23 19 16 178 197 83
24 19 16 178 197 83
25 19 16 178 197 83
26 19 16 178 197 83
27 19 16 178 197 83
28 19 16 178 197 83
-28 20 16 178 197 83
-27 20 16 178 197 83
-26 20 16 178 197 83
-25 20 16 178 197 83
-24 20 16 178 197 83
-23 20 16 178 197 83
-22 20 16 178 197 83
-21 20 16 178 197 83
-20 20 16 178 197 83
-19 20 16 178 197 83
-18 20 16 178 197 83
-17 20 16 178 197 83
-16 20 16 178 197 83
-15 20 16 178 197 83
-14 20 16 178 197 83
-13 20 16 178 197 83
-12 20 16 178 197 83
-11 20 16 178 197 83
-10 20 16 178 197 83
-9 20 16 178 197 83
-8 20 16 178 197 83
-7 20 16 178 197 83
-6 20 16 178 197 83
-5 20 16 178 197 83
-4 20 16 178 197 83
-3 20 16 178 197 83
-2 20 16 178 197 83
-1 20 16 178 197 83
0 20 16 178 197 83
1 20 16 178 197 83
2 20 16 178 197 83
3 20 16 178 197 83
4 20 16 178 197 83
5 20 16 178 197 83
6 20 16 178 197 83
7 20 16 178 197 83
8 20 16 178 197 83
9 20 16 178 197 83
10 20 16 178 197 83
11 20 16 178 197 83
12 20 16 178 197 83
13 20 16 178 197 83
14 20 16 178 197 83
15 20 16 178 197 83
16 20 16 178 197 83
17 20 16 178 197 83
18 20 16 178 197 83
19 20 16 178 197 83
20 20 16 178 197 83
21 20 16 178 197 83
22 20 16 178 197 83
23 20 16 178 197 83
24 20 16 178 197 83
25 20 16 178 197 83
26 20 16 178 197 83
27 20 16 178 197 83
28 20 16 178 197 83
-28 21 16 178 197 83
-27 21 16 178 197 83
-26 21 16 178 197 83
-25 21 16 178 197 83
-24 21 16 178 197 83
-23 21 16 178 197 83
-22 21 16 178 197 83
-21 21 16 178 197 83
-20 21 16 178 197 83
-19 21 16 178 197 83
-18 21 16 178 197 83
-17 21 16 178 197 83
-16 21 16 178 197 83
-15 21 16 178 197 83
-14 21 16 178 197 83
-13 21 16 178 197 83
-12 21 16 178 197 83
-11 21 16 178 197 83
-10 21 16 178 197 83
-9 21 16 178 197 83
-8 21 16 178 197 83
-7 21 16 178 197 83
-6 21 16 178 197 83
-5 21 16 178 197 83
-4 21 16 178 197 83
-3 21 16 178 197 83
-2 21 16 178 197 83
-1 21 16 178 197 83
0 21 16 178 197 83
1 21 16 178 197 83
2 21 16 178 197 83
3 21 16 178 197 83
4 21 16 178 197 83
5 21 16 178 197 83
6 21 16 178 197 83
7 21 16 178 197 83
8 21 16 178 197 83
9 21 16 178 197 83
10 21 16 178 197 83
11 21 16 178 197 83
12 21 16 178 197 83
13 21 16 178 197 83
14 21 16 178 197 83
15 21 16 178 197 83
16 21 16 178 197 83
17 21 16 178 197 83
18 21 16 178 197 83
19 21 16 178 197 83
20 21 16 178 197 83
21 21 16 178 197 83
22 21 16 178 197 83
23 21 16 178 197 83
24 21 16 178 197 83
25 21 16 178 197 83
26 21 16 178 197 83
27 21 16 178 197 83
28 21 16 178 197 83
-28 22 16 178 197 83
-27 22 16 178 197 83
-26 22 16 178 197 83
-25 22 16 178 197 83
-24 22 16 178 197 83
-23 22 16 178 197 83
-22 22 16 178 197 83
-21 22 16 178 197 83
-20 22 16 178 197 83
-19 22 16 178 197 83
-18 22 16 178 197 83
-17 22 16 178 197 83
-16 22 16 178 197 83
-15 22 16 178 197 83
-14 22 16 178 197 83
-13 22 16 178 197 83
-12 22 16 178 197 83
-11 22 16 178 197 83
-10 22 16 178 197 83
-9 22 16 178 197 83
-8 22 16 178 197 83
-7 22 16 178 197 83
-6 22 16 178 197 83
-5 22 16 178 197 83
-4 22 16 178 197 83
-3 22 16 178 197 83
-2 22 16 178 197 83
-1 22 16 178 197 83
0 22 16 178 197 83
1 22 16 178 197 83
2 22 16 178 197 83
3 22 16 178 197 83
4 22 16 178 197 83
5 22 16 178 197 83
6 22 16 178 197 83
7 22 16 178 197 83
8 22 16 178 197 83
9 22 16 178 197 83
10 22 16 178 197 83
11 22 16 178 197 83
12 22 16 178 197 83
13 22 16 178 197 83
14 22 16 178 197 83
15 22 16 178 197 83
16 22 16 178 197 83
17 22 16 178 197 83
18 22 16 178 197 83
19 22 16 178 197 83
20 22 16 178 197 83
21 22 16 178 197 83
22 22 16 178 197 83
23 22 16 178 197 83
24 22 16 178 197 83
25 22 16 178 197 83
26 22 16 178 197 83
27 22 16 178 197 83
28 22 16 178 197 83
-28 23 16 178 197 83
-27 23 16 178 197 83
-26 23 16 178 197 83
-25 23 16 178 197 83
-24 23 16 178 197 83
-23 23 16 178 197 83
-22 23 16 178 197 83
-21 23 16 178 197 83
-20 23 16 178 197 83
-19 23 16 178 197 83
-18 23 16 178 197 83
-17 23 16 178 197 83
-16 23 16 178 197 83
-15 23 16 178 197 83
-14 23 16 178 197 83
-13 23 16 178 197 83
-12 23 16 178 197 83
-11 23 16 178 197 83
-10 23 16 178 197 83
-9 23 16 178 197 83
-8 23 16 178 197 83
-7 23 16 178 197 83
-6 23 16 178 197 83
-5 23 16 178 197 83
-4 23 16 178 197 83
-3 23 16 178 197 83
-2 23 16 178 197 83
-1 23 16 178 197 83
0 23 16 178 197 83
1 23 16 178 197 83
2 23 16 178 197 83
3 23 16 178 197 83
4 23 16 178 197 83
5 23 16 178 197 83
6 23 16 178 197 83
7 23 16 178 197 83
8 23 16 178 197 83
9 23 16 178 197 83
10 23 16 178 197 83
11 23 16 178 197 83
12 23 16 178 197 83
13 23 16 178 197 83
14 23 16 178 197 83
15 23 16 178 197 83
16 23 16 178 197 83
17 23 16 178 197 83
18 23 16 178 197 83
19 23 16 178 197 83
20 23 16 178 197 83
21 23 16 178 197 83
22 23 16 178 197 83
23 23 16 178 197 83
24 23 16 178 197 83
25 23 16 178 197 83
26 23 16 178 197 83
27 23 16 178 197 83
28 23 16 178 197 83
-28 24 16 178 197 83
-27 24 16 178 197 83
-26 24 16 178 197 83
-25 24 16 178 197 83
-24 24 16 178 197 83
-23 24 16 178 197 83
-22 24 16 178 197 83
-21 24 16 178 197 83
-20 24 16 178 197 83
-19 24 16 178 197 83
-18 24 16 178 197 83
-17 24 16 178 197 83
-16 24 16 178 197 83
-15 24 16 178 197 83
-14 24 16 178 197 83
-13 24 16 178 197 83
-12 24 16 178 197 83
-11 24 16 178 197 83
-10 24 16 178 197 83
-9 24 16 178 197 83
-8 24 16 178 197 83
-7 24 16 178 197 83
-6 24 16 178 197 83
-5 24 16 178 197 83
-4 24 16 178 197 83
-3 24 16 178 197 83
-2 24 16 178 197 83
-1 24 16 178 197 83
0 24 16 178 197 83
1 24 16 178 197 83
2 24 16 178 197 83
3 24 16 178 197 83
4 24 16 178 197 83
5 24 16 178 197 83
6 24 16 178 197 83
7 24 16 178 197 83
8 24 16 178 197 83
9 24 16 178 197 83
10 24 16 178 197 83
11 24 16 178 197 83
12 24 16 178 197 83
13 24 16 178 197 83
14 24 16 178 197 83
15 24 16 178 197 83
16 24 16 178 197 83
17 24 16 178 197 83
18 24 16 178 197 83
19 24 16 178 197 83
20 24 16 178 197 83
21 24 16 178 197 83
22 24 16 178 197 83
23 24 16 178 197 83
24 24 16 178 197 83
25 24 16 178 197 83
26 24 16 178 197 83
27 24 16 178 197 83
28 24 16 178 197 83
-28 25 16 178 197 83
-27 25 16 178 197 83
-26 25 16 178 197 83
-25 25 16 178 197 83
-24 25 16 178 197 83
-23 25 16 178 197 83
-22 25 16 178 197 83
-21 25 16 178 197 83
-20 25 16 178 197 83
-19 25 16 178 197 83
-18 25 16 178 197 83
-17 25 16 178 197 83
-16 25 16 178 197 83
-15 25 16 178 197 83
-14 25 16 178 197 83
-13 25 16 178 197 83
-12 25 16 178 197 83
-11 25 16 178 197 83
-10 25 16 178 197 83
-9 25 16 178 197 83
-8 25 16 178 197 83
-7 25 16 178 197 83
-6 25 16 178 197 83
-5 25 16 178 197 83
-4 25 16 178 197 83
-3 25 16 178 197 83
-2 25 16 178 197 83
-1 25 16 178 197 83
0 25 16 178 197 83
1 25 16 178 197 83
2 25 16 178 197 83
3 25 16 178 197 83
4 25 16 178 197 83
5 25 16 178 197 83
6 25 16 178 197 83
7 25 16 178 197 83
8 25 16 178 197 83
9 25 16 178 197 83
10 25 16 178 197 83
11 25 16 178 197 83
12 25 16 178 197 83
13 25 16 178 197 83
14 25 16 178 197 83
15 25 16 178 197 83
16 25 16 178 197 83
17 25 16 178 197 83
18 25 16 178 197 83
19 25 16 178 197 83
20 25 16 178 197 83
21 25 16 178 197 83
22 25 16 178 197 83
23 25 16 178 197 83
24 25 16 178 197 83
25 25 16 178 197 83
26 25 16 178 197 83
27 25 16 178 197 83
28 25 16 178 197 83
-28 26 16 178 197 83
-27 26 16 178 197 83
-26 26 16 178 197 83
-25 26 16 178 197 83
-24 26 16 178 197 83
-23 26 16 178 197 83
-22 26 16 178 197 83
-21 26 16 178 197 83
-20 26 16 178 197 83
-19 26 16 178 197 83
-18 26 16 178 197 83
-17 26 16 178 197 83
-16 26 16 178 197 83
-15 26 16 178 197 83
-14 26 16 178 197 83
-13 26 16 178 197 83
-12 26 16 178 197 83
-11 26 16 178 197 83
-10 26 16 178 197 83
-9 26 16 178 197 83
-8 26 16 178 197 83
-7 26 16 178 197 83
-6 26 16 178 197 83
-5 26 16 178 197 83
-4 26 16 178 197 83
-3 26 16 178 197 83
-2 26 16 178 197 83
-1 26 16 178 197 83
0 26 16 178 197 83
1 26 16 178 197 83
2 26 16 178 197 83
3 26 16 178 197 83
4 26 16 178 197 83
5 26 16 178 197 83
6 26 16 178 197 83
7 26 16 178 197 83
8 26 16 178 197 83
9 26 16 178 197 83
10 26 16 178 197 83
11 26 16 178 197 83
12 26 16 178 197 83
13 26 16 178 197 83
14 26 16 178 197 83
15 26 16 178 197 83
16 26 16 178 197 83
17 26 16 178 197 83
18 26 16 178 197 83
19 26 16 178 197 83
20 26 16 178 197 83
21 26 16 178 197 83
22 26 16 178 197 83
23 26 16 178 197 83
24 26 16 178 197 83
25 26 16 178 197 83
26 26 16 178 197 83
27 26 16 178 197 83
28 26 16 178 197 83
-28 27 16 178 197 83
-27 27 16 178 197 83
-26 27 16 178 197 83
-25 27 16 178 197 83
-24 27 16 178 197 83
-23 27 16 178 197 83
-22 27 16 178 197 83
-21 27 16 178 197 83
-20 27 16 178 197 83
-19 27 16 178 197 83
-18 27 16 178 197 83
-17 27 16 178 197 83
-16 27 16 178 197 83
-15 27 16 178 197 83
-14 27 16 178 197 83
-13 27 16 178 197 83
-12 27 16 178 197 83
-11 27 16 178 197 83
-10 27 16 178 197 83
-9 27 16 178 197 83
-8 27 16 178 197 83
-7 27 16 178 197 83
-6 27 16 178 197 83
-5 27 16 178 197 83
-4 27 16 178 197 83
-3 27 16 178 197 83
-2 27 16 178 197 83
-1 27 16 178 197 83
0 27 16 178 197 83
1 27 16 178 197 83
2 27 16 178 197 83
3 27 16 178 197 83
4 27 16 178 197 83
5 27 16 178 197 83
6 27 16 178 197 83
7 27 16 178 197 83
8 27 16 178 197 83
9 27 16 178 197 83
10 27 16 178 197 83
11 27 16 178 197 83
12 27 16 178 197 83
13 27 16 178 197 83
14 27 16 178 197 83
15 27 16 178 197 83
16 27 16 178 197 83
17 27 16 178 197 83
18 27 16 178 197 83
19 27 16 178 197 83
20 27 16 178 197 83
21 27 16 178 197 83
22 27 16 178 197 83
23 27 16 178 197 83
24 27 16 178 197 83
25 27 16 178 197 83
26 27 16 178 197 83
27 27 16 178 197 83
28 27 16 178 197 83
-28 28 16 178 197 83
-27 28 16 178 197 83
-26 28 16 178 197 83
-25 28 16 178 197 83
-24 28 16 178 197 83
-23 28 16 178 197 83
-22 28 16 178 197 83
-21 28 16 178 197 83
-20 28 16 178 197 83
-19 28 16 178 197 83
-18 28 16 178 197 83
-17 28 16 178 197 83
-16 28 16 178 197 83
-15 28 16 178 197 83
-14 28 16 178 197 83
-13 28 16 178 197 83
-12 28 16 178 197 83
-11 28 16 178 197 83
-10 28 16 178 197 83
-9 28 16 178 197 83
-8 28 16 178 197 83
-7 28 16 178 197 83
-6 28 16 178 197 83
-5 28 16 178 197 83
-4 28 16 178 197 83
-3 28 16 178 197 83
-2 28 16 178 197 83
-1 28 16 178 197 83
0 28 16 178 197 83
1 28 16 178 197 83
2 28 16 178 197 83
3 28 16 178 197 83
4 28 16 178 197 83
5 28 16 178 197 83
6 28 16 178 197 83
7 28 16 178 197 83
8 28 16 178 197 83
9 28 16 178 197 83
10 28 16 178 197 83
11 28 16 178 197 83
12 28 16 178 197 83
13 28 16 178 197 83
14 28 16 178 197 83
15 28 16 178 197 83
16 28 16 178 197 83
17 28 16 178 197 83
18 28 16 178 197 83
19 28 16 178 197 83
20 28 16 178 197 83
21 28 16 178 197 83
22 28 16 178 197 83
23 28 16 178 197 83
24 28 16 178 197 83
25 28 16 178 197 83
26 28 16 178 197 83
27 28 16 178 197 83
28 28 16 178 197 83
-19 -24 17 103 113 88
-18 -24 17 103 113 88
-5 -24 17 103 113 88
-4 -24 17 103 113 88
-19 -23 17 103 113 88
-18 -23 17 103 113 88
-19 -22 17 103 113 88
-18 -22 17 103 113 88
-11 -22 17 103 113 88
-10 -22 17 103 113 88
14 -22 17 103 113 88
15 -22 17 103 113 88
21 -22 17 103 113 88
22 -22 17 103 113 88
23 -22 17 103 113 88
-11 -21 17 103 113 88
-10 -21 17 103 113 88
14 -21 17 103 113 88
15 -21 17 103 113 88
21 -21 17 103 113 88
22 -21 17 103 113 88
23 -21 17 103 113 88
-11 -20 17 103 113 88
-10 -20 17 103 113 88
14 -20 17 103 113 88
15 -20 17 103 113 88
21 -20 17 103 113 88
22 -20 17 103 113 88
23 -20 17 103 113 88
-1 -19 17 255 255 255
12 -19 17 103 113 88
-19 -18 17 255 255 255
13 -18 17 103 113 88
14 -18 17 103 113 88
13 -17 17 103 113 88
14 -17 17 103 113 88
-14 -16 17 255 255 255
8 -16 17 103 113 88
9 -16 17 103 113 88
24 -11 17 103 113 88
25 -11 17 103 113 88
-24 -10 17 199 194 154
-23 -10 17 199 194 154
-22 -10 17 199 194 154
-21 -10 17 199 194 154
12 -10 17 199 194 154
13 -10 17 199 194 154
14 -10 17 199 194 154
15 -10 17 199 194 154
24 -10 17 103 113 88
25 -10 17 103 113 88
-24 -9 17 199 194 154
-23 -9 17 199 194 154
-22 -9 17 199 194 154
-21 -9 17 199 194 154
12 -9 17 199 194 154
13 -9 17 199 194 154
14 -9 17 199 194 154
15 -9 17 199 194 154
-24 -8 17 199 194 154
-23 -8 17 199 194 154
-22 -8 17 199 194 154
-21 -8 17 199 194 154
12 -8 17 199 194 154
13 -8 17 199 194 154
14 -8 17 199 194 154
15 -8 17 199 194 154
-24 -7 17 199 194 154
-23 -7 17 199 194 154
-22 -7 17 199 194 154
-21 -7 17 199 194 154
12 -7 17 199 194 154
13 -7 17 199 194 154
14 -7 17 199 194 154
15 -7 17 199 194 154
-24 -6 17 199 194 154
-23 -6 17 199 194 154
-22 -6 17 199 194 154
-21 -6 17 199 194 154
12 -6 17 199 194 154
13 -6 17 199 194 154
14 -6 17 199 194 154
15 -6 17 199 194 154
-24 -5 17 199 194 154
-23 -5 17 199 194 154
-22 -5 17 199 194 154
-21 -5 17 199 194 154
12 -5 17 199 194 154
13 -5 17 199 194 154
14 -5 17 199 194 154
15 -5 17 199 194 154
-24 -4 17 199 194 154
-23 -4 17 199 194 154
-22 -4 17 199 194 154
-21 -4 17 199 194 154
-4 -4 17 199 194 154
-3 -4 17 199 194 154
-2 -4 17 199 194 154
-1 -4 17 199 194 154
0 -4 17 199 194 154
1 -4 17 199 194 154
2 -4 17 199 194 154
3 -4 17 199 194 154
12 -4 17 199 194 154
13 -4 17 199 194 154
14 -4 17 199 194 154
15 -4 17 199 194 154
-24 -3 17 199 194 154
-23 -3 17 199 194 154
-22 -3 17 199 194 154
-21 -3 17 199 194 154
-4 -3 17 199 194 154
12 -3 17 199 194 154
13 -3 17 199 194 154
14 -3 17 199 194 154
15 -3 17 199 194 154
-24 -2 17 199 194 154
-23 -2 17 199 194 154
-22 -2 17 199 194 154
-21 -2 17 199 194 154
-20 -2 17 199 194 154
-19 -2 17 199 194 154
-18 -2 17 199 194 154
-17 -2 17 199 194 154
-16 -2 17 199 194 154
-4 -2 17 199 194 154
-2 -2 17 167 162 121
-1 -2 17 167 162 121
0 -2 17 167 162 121
1 -2 17 167 162 121
2 -2 17 167 162 121
12 -2 17 199 194 154
13 -2 17 199 194 154
14 -2 17 199 194 154
15 -2 17 199 194 154
16 -2 17 199 194 154
17 -2 17 199 194 154
18 -2 17 199 194 154
19 -2 17 199 194 154
20 -2 17 199 194 154
21 -2 17 199 194 154
22 -2 17 199 194 154
23 -2 17 199 194 154
24 -2 17 199 194 154
-24 -1 17 199 194 154
-23 -1 17 199 194 154
-22 -1 17 199 194 154
-21 -1 17 199 194 154
-20 -1 17 199 194 154
-19 -1 17 199 194 154
-18 -1 17 199 194 154
-17 -1 17 199 194 154
-16 -1 17 199 194 154
-4 -1 17 199 194 154
-2 -1 17 167 162 121
-1 -1 17 167 162 121
0 -1 17 167 162 121
1 -1 17 167 162 121
2 -1 17 167 162 121
12 -1 17 199 194 154
13 -1 17 199 194 154
14 -1 17 199 194 154
15 -1 17 199 194 154
16 -1 17 199 194 154
17 -1 17 199 194 154
18 -1 17 199 194 154
19 -1 17 199 194 154
20 -1 17 199 194 154
21 -1 17 199 194 154
22 -1 17 199 194 154
23 -1 17 199 194 154
24 -1 17 199 194 154
-24 0 17 199 194 154
-23 0 17 199 194 154
-22 0 17 199 194 154
-21 0 17 199 194 154
-20 0 17 199 194 154
-19 0 17 199 194 154
-18 0 17 199 194 154
-17 0 17 199 194 154
-16 0 17 199 194 154
-4 0 17 199 194 154
-2 0 17 167 162 121
-1 0 17 167 162 121
0 0 17 167 162 121
1 0 17 167 162 121
2 0 17 167 162 121
12 0 17 199 194 154
13 0 17 199 194 154
14 0 17 199 194 154
15 0 17 199 194 154
16 0 17 199 194 154
17 0 17 199 194 154
18 0 17 199 194 154
19 0 17 199 194 154
20 0 17 199 194 154
21 0 17 199 194 154
22 0 17 199 194 154
23 0 17 199 194 154
24 0 17 199 194 154
-24 1 17 199 194 154
-23 1 17 199 194 154
-22 1 17 199 194 154
-21 1 17 199 194 154
-20 1 17 199 194 154
-19 1 17 199 194 154
-18 1 17 199 194 154
-17 1 17 199 194 154
-16 1 17 199 194 154
-4 1 17 199 194 154
-2 1 17 167 162 121
-1 1 17 167 162 121
0 1 17 167 162 121
1 1 17 167 162 121
2 1 17 167 162 121
12 1 17 199 194 154
13 1 17 199 194 154
14 1 17 199 194 154
15 1 17 199 194 154
16 1 17 199 194 154
17 1 17 199 194 154
18 1 17 199 194 154
19 1 17 199 194 154
20 1 17 199 194 154
21 1 17 199 194 154
22 1 17 199 194 154
23 1 17 199 194 154
24 1 17 199 194 154
-24 2 17 199 194 154
-23 2 17 199 194 154
-22 2 17 199 194 154
-21 2 17 199 194 154
-20 2 17 199 194 154
-19 2 17 199 194 154
-18 2 17 199 194 154
-17 2 17 199 194 154
-16 2 17 199 194 154
-4 2 17 199 194 154
-2 2 17 167 162 121
-1 2 17 167 162 121
0 2 17 167 162 121
1 2 17 167 162 121
2 2 17 167 162 121
12 2 17 199 194 154
13 2 17 199 194 154
14 2 17 199 194 154
15 2 17 199 194 154
16 2 17 199 194 154
17 2 17 199 194 154
18 2 17 199 194 154
19 2 17 199 194 154
20 2 17 199 194 154
21 2 17 199 194 154
22 2 17 199 194 154
23 2 17 199 194 154
24 2 17 199 194 154
-4 3 17 199 194 154
21 3 17 199 194 154
22 3 17 199 194 154
23 3 17 199 194 154
24 3 17 199 194 154
21 4 17 199 194 154
22 4 17 199 194 154
23 4 17 199 194 154
24 4 17 199 194 154
21 5 17 199 194 154
22 5 17 199 194 154
23 5 17 199 194 154
24 5 17 199 194 154
21 6 17 199 194 154
22 6 17 199 194 154
23 6 17 199 194 154
24 6 17 199 194 154
21 7 17 199 194 154
22 7 17 199 194 154
23 7 17 199 194 154
24 7 17 199 194 154
21 8 17 199 194 154
22 8 17 199 194 154
23 8 17 199 194 154
24 8 17 199 194 154
21 9 17 199 194 154
22 9 17 199 194 154
23 9 17 199 194 154
24 9 17 199 194 154
21 10 17 199 194 154
22 10 17 199 194 154
23 10 17 199 194 154
24 10 17 199 194 154
-13 16 17 255 255 255
-8 16 17 103 113 88
-6 16 17 103 113 88
-5 16 17 103 113 88
-4 16 17 103 113 88
-2 16 17 199 194 154
-1 16 17 199 194 154
0 16 17 199 194 154
1 16 17 199 194 154
2 16 17 199 194 154
-19 17 17 103 113 88
-18 17 17 103 113 88
-8 17 17 103 113 88
-6 17 17 103 113 88
-5 17 17 103 113 88
-4 17 17 103 113 88
-2 17 17 199 194 154
-1 17 17 199 194 154
0 17 17 199 194 154
1 17 17 199 194 154
2 17 17 199 194 154
-19 18 17 103 113 88
-18 18 17 103 113 88
-6 18 17 103 113 88
-5 18 17 103 113 88
-4 18 17 103 113 88
-2 18 17 199 194 154
-1 18 17 199 194 154
0 18 17 199 194 154
1 18 17 199 194 154
2 18 17 199 194 154
-19 19 17 103 113 88
-18 19 17 103 113 88
-12 19 17 103 113 88
-11 19 17 103 113 88
-10 19 17 103 113 88
-2 19 17 199 194 154
-1 19 17 199 194 154
0 19 17 199 194 154
1 19 17 199 194 154
2 19 17 199 194 154
-12 20 17 103 113 88
-11 20 17 103 113 88
-10 20 17 103 113 88
-2 20 17 199 194 154
-1 20 17 199 194 154
0 20 17 199 194 154
1 20 17 199 194 154
2 20 17 199 194 154
-2 21 17 199 194 154
-1 21 17 199 194 154
0 21 17 199 194 154
1 21 17 199 194 154
2 21 17 199 194 154
-17 22 17 103 113 88
-2 22 17 199 194 154
-1 22 17 199 194 154
0 22 17 199 194 154
1 22 17 199 194 154
2 22 17 199 194 154
-17 23 17 103 113 88
-2 23 17 199 194 154
-1 23 17 199 194 154
0 23 17 199 194 154
1 23 17 199 194 154
2 23 17 199 194 154
-5 24 17 255 255 255
-2 24 17 199 194 154
-1 24 17 199 194 154
0 24 17 199 194 154
1 24 17 199 194 154
2 24 17 199 194 154
8 24 17 255 255 255
-7 -25 18 255 255 255
-19 -24 18 103 113 88
-18 -24 18 103 113 88
-5 -24 18 103 113 88
-4 -24 18 103 113 88
-19 -23 18 103 113 88
-18 -23 18 103 113 88
-19 -22 18 103 113 88
-18 -22 18 103 113 88
-11 -22 18 103 113 88
-10 -22 18 103 113 88
14 -22 18 103 113 88
15 -22 18 103 113 88
21 -22 18 103 113 88
22 -22 18 103 113 88
23 -22 18 103 113 88
-11 -21 18 103 113 88
-10 -21 18 103 113 88
14 -21 18 103 113 88
15 -21 18 103 113 88
21 -21 18 103 113 88
22 -21 18 103 113 88
23 -21 18 103 113 88
-11 -20 18 103 113 88
-10 -20 18 103 113 88
6 -20 18 255 255 255
14 -20 18 103 113 88
15 -20 18 103 113 88
21 -20 18 103 113 88
22 -20 18 103 113 88
23 -20 18 103 113 88
-2 -19 18 255 255 255
-1 -19 18 255 255 255
6 -19 18 255 255 255
12 -19 18 103 113 88
-19 -18 18 255 255 255
13 -18 18 103 113 88
14 -18 18 103 113 88
13 -17 18 103 113 88
14 -17 18 103 113 88
-14 -16 18 255 255 255
-13 -16 18 255 255 255
8 -16 18 103 113 88
9 -16 18 103 113 88
23 -15 18 255 255 255
24 -15 18 255 255 255
21 -11 18 255 255 255
24 -11 18 103 113 88
25 -11 18 103 113 88
-24 -10 18 199 194 154
-23 -10 18 199 194 154
-22 -10 18 199 194 154
-21 -10 18 199 194 154
12 -10 18 199 194 154
13 -10 18 199 194 154
14 -10 18 199 194 154
15 -10 18 199 194 154
21 -10 18 255 255 255
24 -10 18 103 113 88
25 -10 18 103 113 88
-24 -9 18 199 194 154
-23 -9 18 199 194 154
-22 -9 18 199 194 154
-21 -9 18 199 194 154
12 -9 18 199 194 154
13 -9 18 199 194 154
14 -9 18 199 194 154
15 -9 18 199 194 154
-24 -8 18 199 194 154
-23 -8 18 199 194 154
-22 -8 18 199 194 154
-21 -8 18 199 194 154
12 -8 18 199 194 154
13 -8 18 199 194 154
14 -8 18 199 194 154
15 -8 18 199 194 154
-24 -7 18 199 194 154
-23 -7 18 199 194 154
-22 -7 18 199 194 154
-21 -7 18 199 194 154
12 -7 18 199 194 154
13 -7 18 199 194 154
14 -7 18 199 194 154
15 -7 18 199 194 154
-24 -6 18 199 194 154
-23 -6 18 199 194 154
-22 -6 18 199 194 154
-21 -6 18 199 194 154
12 -6 18 199 194 154
13 -6 18 199 194 154
14 -6 18 199 194 154
15 -6 18 199 194 154
-24 -5 18 199 194 154
-23 -5 18 199 194 154
-22 -5 18 199 194 154
-21 -5 18 199 194 154
12 -5 18 199 194 154
13 -5 18 199 194 154
14 -5 18 199 194 154
15 -5 18 199 194 154
-24 -4 18 199 194 154
-23 -4 18 199 194 154
-22 -4 18 199 194 154
-21 -4 18 199 194 154
-4 -4 18 199 194 154
-3 -4 18 199 194 154
-2 -4 18 199 194 154
-1 -4 18 199 194 154
0 -4 18 199 194 154
1 -4 18 199 194 154
2 -4 18 199 194 154
3 -4 18 199 194 154
12 -4 18 199 194 154
13 -4 18 199 194 154
14 -4 18 199 194 154
15 -4 18 199 194 154
-24 -3 18 199 194 154
-23 -3 18 199 194 154
-22 -3 18 199 194 154
-21 -3 18 199 194 154
-4 -3 18 199 194 154
12 -3 18 199 194 154
13 -3 18 199 194 154
14 -3 18 199 194 154
15 -3 18 199 194 154
-24 -2 18 199 194 154
-23 -2 18 199 194 154
-22 -2 18 199 194 154
-21 -2 18 199 194 154
-20 -2 18 199 194 154
-19 -2 18 199 194 154
-18 -2 18 199 194 154
-17 -2 18 199 194 154
-16 -2 18 199 194 154
-4 -2 18 199 194 154
-2 -2 18 167 162 121
-1 -2 18 167 162 121
0 -2 18 167 162 121
1 -2 18 167 162 121
2 -2 18 167 162 121
12 -2 18 199 194 154
13 -2 18 199 194 154
14 -2 18 199 194 154
15 -2 18 199 194 154
16 -2 18 199 194 154
17 -2 18 199 194 154
18 -2 18 199 194 154
19 -2 18 199 194 154
20 -2 18 199 194 154
21 -2 18 199 194 154
22 -2 18 199 194 154
23 -2 18 199 194 154
24 -2 18 199 194 154
-24 -1 18 199 194 154
-23 -1 18 199 194 154
-22 -1 18 199 194 154
-21 -1 18 199 194 154
-20 -1 18 199 194 154
-19 -1 18 199 194 154
-18 -1 18 199 194 154
-17 -1 18 199 194 154
-16 -1 18 199 194 154
-4 -1 18 199 194 154
-2 -1 18 167 162 121
-1 -1 18 167 162 121
0 -1 18 167 162 121
1 -1 18 167 162 121
2 -1 18 167 162 121
12 -1 18 199 194 154
13 -1 18 199 194 154
14 -1 18 199 194 154
15 -1 18 199 194 154
16 -1 18 199 194 154
17 -1 18 199 194 154
18 -1 18 199 194 154
19 -1 18 199 194 154
20 -1 18 199 194 154
21 -1 18 199 194 154
22 -1 18 199 194 154
23 -1 18 199 194 154
24 -1 18 199 194 154
-24 0 18 199 194 154
-23 0 18 199 194 154
-22 0 18 199 194 154
-21 0 18 199 194 154
-20 0 18 199 194 154
-19 0 18 199 194 154
-18 0 18 199 194 154
-17 0 18 199 194 154
-16 0 18 199 194 154
-4 0 18 199 194 154
-2 0 18 167 162 121
-1 0 18 167 162 121
0 0 18 167 162 121
1 0 18 167 162 121
2 0 18 167 162 121
12 0 18 199 194 154
13 0 18 199 194 154
14 0 18 199 194 154
15 0 18 199 194 154
16 0 18 199 194 154
17 0 18 199 194 154
18 0 18 199 194 154
19 0 18 199 194 154
20 0 18 199 194 154
21 0 18 199 194 154
22 0 18 199 194 154
23 0 18 199 194 154
24 0 18 199 194 154
-24 1 18 199 194 154
-23 1 18 199 194 154
-22 1 18 199 194 154
-21 1 18 199 194 154
-20 1 18 199 194 154
-19 1 18 199 194 154
-18 1 18 199 194 154
-17 1 18 199 194 154
-16 1 18 199 194 154
-4 1 18 199 194 154
-2 1 18 167 162 121
-1 1 18 167 162 121
0 1 18 167 162 121
1 1 18 167 162 121
2 1 18 167 162 121
12 1 18 199 194 154
13 1 18 199 194 154
14 1 18 199 194 154
15 1 18 199 194 154
16 1 18 199 194 154
17 1 18 199 194 154
18 1 18 199 194 154
19 1 18 199 194 154
20 1 18 199 194 154
21 1 18 199 194 154
22 1 18 199 194 154
23 1 18 199 194 154
24 1 18 199 194 154
-24 2 18 199 194 154
-23 2 18 199 194 154
-22 2 18 199 194 154
-21 2 18 199 194 154
-20 2 18 199 194 154
-19 2 18 199 194 154
-18 2 18 199 194 154
-17 2 18 199 194 154
-16 2 18 199 194 154
-4 2 18 199 194 154
-2 2 18 167 162 121
-1 2 18 167 162 121
0 2 18 167 162 121
1 2 18 167 162 121
2 2 18 167 162 121
12 2 18 199 194 154
13 2 18 199 194 154
14 2 18 199 194 154
15 2 18 199 194 154
16 2 18 199 194 154
17 2 18 199 194 154
18 2 18 199 194 154
19 2 18 199 194 154
20 2 18 199 194 154
21 2 18 199 194 154
22 2 18 199 194 154
23 2 18 199 194 154
24 2 18 199 194 154
-4 3 18 199 194 154
21 3 18 199 194 154
22 3 18 199 194 154
23 3 18 199 194 154
24 3 18 199 194 154
21 4 18 199 194 154
22 4 18 199 194 154
23 4 18 199 194 154
24 4 18 199 194 154
21 5 18 199 194 154
22 5 18 199 194 154
23 5 18 199 194 154
24 5 18 199 194 154
21 6 18 199 194 154
22 6 18 199 194 154
23 6 18 199 194 154
24 6 18 199 194 154
21 7 18 199 194 154
22 7 18 199 194 154
23 7 18 199 194 154
24 7 18 199 194 154
21 8 18 199 194 154
22 8 18 199 194 154
23 8 18 199 194 154
24 8 18 199 194 154
21 9 18 199 194 154
22 9 18 199 194 154
23 9 18 199 194 154
24 9 18 199 194 154
21 10 18 199 194 154
22 10 18 199 194 154
23 10 18 199 194 154
24 10 18 199 194 154
-19 15 18 255 255 255
-18 15 18 255 255 255
-14 16 18 255 255 255
-13 16 18 255 255 255
-8 16 18 103 113 88
-6 16 18 103 113 88
-5 16 18 103 113 88
-4 16 18 103 113 88
-2 16 18 199 194 154
-1 16 18 199 194 154
0 16 18 199 194 154
1 16 18 199 194 154
2 16 18 199 194 154
-19 17 18 103 113 88
-18 17 18 103 113 88
-13 17 18 255 255 255
-8 17 18 103 113 88
-6 17 18 103 113 88
-5 17 18 103 113 88
-4 17 18 103 113 88
-2 17 18 199 194 154
-1 17 18 199 194 154
0 17 18 199 194 154
1 17 18 199 194 154
2 17 18 199 194 154
-19 18 18 103 113 88
-18 18 18 103 113 88
-6 18 18 103 113 88
-5 18 18 103 113 88
-4 18 18 103 113 88
-2 18 18 199 194 154
-1 18 18 199 194 154
0 18 18 199 194 154
1 18 18 199 194 154
2 18 18 199 194 154
-19 19 18 103 113 88
-18 19 18 103 113 88
-12 19 18 103 113 88
-11 19 18 103 113 88
-10 19 18 103 113 88
-2 19 18 199 194 154
-1 19 18 199 194 154
0 19 18 199 194 154
1 19 18 199 194 154
2 19 18 199 194 154
-12 20 18 103 113 88
-11 20 18 103 113 88
-10 20 18 103 113 88
-2 20 18 199 194 154
-1 20 18 199 194 154
0 20 18 199 194 154
1 20 18 199 194 154
2 20 18 199 194 154
-2 21 18 199 194 154
-1 21 18 199 194 154
0 21 18 199 194 154
1 21 18 199 194 154
2 21 18 199 194 154
-17 22 18 103 113 88
-2 22 18 199 194 154
-1 22 18 199 194 154
0 22 18 199 194 154
1 22 18 199 194 154
2 22 18 199 194 154
-17 23 18 103 113 88
-2 23 18 199 194 154
-1 23 18 199 194 154
0 23 18 199 194 154
1 23 18 199 194 154
2 23 18 199 194 154
-6 24 18 255 255 255
-5 24 18 255 255 255
-4 24 18 255 255 255
-2 24 18 199 194 154
-1 24 18 199 194 154
0 24 18 199 194 154
1 24 18 199 194 154
2 24 18 199 194 154
8 24 18 255 255 255
9 24 18 255 255 255
-5 25 18 255 255 255
8 25 18 255 255 255
-19 -24 19 103 113 88
-18 -24 19 103 113 88
-5 -24 19 103 113 88
-4 -24 19 103 113 88
-19 -23 19 103 113 88
-18 -23 19 103 113 88
-19 -22 19 103 113 88
-18 -22 19 103 113 88
-11 -22 19 103 113 88
-10 -22 19 103 113 88
14 -22 19 103 113 88
15 -22 19 103 113 88
21 -22 19 103 113 88
22 -22 19 103 113 88
23 -22 19 103 113 88
-11 -21 19 103 113 88
-10 -21 19 103 113 88
14 -21 19 103 113 88
15 -21 19 103 113 88
21 -21 19 103 113 88
22 -21 19 103 113 88
23 -21 19 103 113 88
-11 -20 19 103 113 88
-10 -20 19 103 113 88
14 -20 19 103 113 88
15 -20 19 103 113 88
21 -20 19 103 113 88
22 -20 19 103 113 88
23 -20 19 103 113 88
13 -18 19 103 113 88
14 -18 19 103 113 88
13 -17 19 103 113 88
14 -17 19 103 113 88
8 -16 19 103 113 88
9 -16 19 103 113 88
24 -11 19 103 113 88
25 -11 19 103 113 88
-24 -10 19 199 194 154
-23 -10 19 199 194 154
-22 -10 19 199 194 154
-21 -10 19 199 194 154
12 -10 19 199 194 154
13 -10 19 199 194 154
14 -10 19 199 194 154
15 -10 19 199 194 154
24 -10 19 103 113 88
25 -10 19 103 113 88
-24 -9 19 199 194 154
-23 -9 19 199 194 154
-22 -9 19 199 194 154
-21 -9 19 199 194 154
12 -9 19 199 194 154
13 -9 19 199 194 154
14 -9 19 199 194 154
15 -9 19 199 194 154
-24 -8 19 199 194 154
-23 -8 19 199 194 154
-22 -8 19 199 194 154
-21 -8 19 199 194 154
12 -8 19 199 194 154
13 -8 19 199 194 154
14 -8 19 199 194 154
15 -8 19 199 194 154
-24 -7 19 199 194 154
-23 -7 19 199 194 154
-22 -7 19 199 194 154
-21 -7 19 199 194 154
12 -7 19 199 194 154
13 -7 19 199 194 154
14 -7 19 199 194 154
15 -7 19 199 194 154
-24 -6 19 199 194 154
-23 -6 19 199 194 154
-22 -6 19 199 194 154
-21 -6 19 199 194 154
12 -6 19 199 194 154
13 -6 19 199 194 154
14 -6 19 199 194 154
15 -6 19 199 194 154
-24 -5 19 199 194 154
-23 -5 19 199 194 154
-22 -5 19 199 194 154
-21 -5 19 199 194 154
12 -5 19 199 194 154
13 -5 19 199 194 154
14 -5 19 199 194 154
15 -5 19 199 194 154
-24 -4 19 199 194 154
-23 -4 19 199 194 154
-22 -4 19 199 194 154
-21 -4 19 199 194 154
-4 -4 19 199 194 154
-3 -4 19 199 194 154
-2 -4 19 199 194 154
-1 -4 19 199 194 154
0 -4 19 199 194 154
1 -4 19 199 194 154
2 -4 19 199 194 154
3 -4 19 199 194 154
12 -4 19 199 194 154
13 -4 19 199 194 154
14 -4 19 199 194 154
15 -4 19 199 194 154
-24 -3 19 199 194 154
-23 -3 19 199 194 154
-22 -3 19 199 194 154
-21 -3 19 199 194 154
-4 -3 19 199 194 154
12 -3 19 199 194 154
13 -3 19 199 194 154
14 -3 19 199 194 154
15 -3 19 199 194 154
-24 -2 19 199 194 154
-23 -2 19 199 194 154
-22 -2 19 199 194 154
-21 -2 19 199 194 154
-20 -2 19 199 194 154
-19 -2 19 199 194 154
-18 -2 19 199 194 154
-17 -2 19 199 194 154
-16 -2 19 199 194 154
-4 -2 19 199 194 154
-2 -2 19 167 162 121
-1 -2 19 167 162 121
0 -2 19 167 162 121
1 -2 19 167 162 121
2 -2 19 167 162 121
12 -2 19 199 194 154
13 -2 19 199 194 154
14 -2 19 199 194 154
15 -2 19 199 194 154
16 -2 19 199 194 154
17 -2 19 199 194 154
18 -2 19 199 194 154
19 -2 19 199 194 154
20 -2 19 199 194 154
21 -2 19 199 194 154
22 -2 19 199 194 154
23 -2 19 199 194 154
24 -2 19 199 194 154
-24 -1 19 199 194 154
-23 -1 19 199 194 154
-22 -1 19 199 194 154
-21 -1 19 199 194 154
-20 -1 19 199 194 154
-19 -1 19 199 194 154
-18 -1 19 199 194 154
-17 -1 19 199 194 154
-16 -1 19 199 194 154
-4 -1 19 199 194 154
-2 -1 19 167 162 121
-1 -1 19 167 162 121
0 -1 19 167 162 121
1 -1 19 167 162 121
2 -1 19 167 162 121
12 -1 19 199 194 154
13 -1 19 199 194 154
14 -1 19 199 194 154
15 -1 19 199 194 154
16 -1 19 199 194 154
17 -1 19 199 194 154
18 -1 19 199 194 154
19 -1 19 199 194 154
20 -1 19 199 194 154
21 -1 19 199 194 154
22 -1 19 199 194 154
23 -1 19 199 194 154
24 -1 19 199 194 154
-24 0 19 199 194 154
-23 0 19 199 194 154
-22 0 19 199 194 154
-21 0 19 199 194 154
-20 0 19 199 194 154
-19 0 19 199 194 154
-18 0 19 199 194 154
-17 0 19 199 194 154
-16 0 19 199 194 154
-4 0 19 199 194 154
-2 0 19 167 162 121
-1 0 19 167 162 121
0 0 19 167 162 121
1 0 19 167 162 121
2 0 19 167 162 121
12 0 19 199 194 154
13 0 19 199 194 154
14 0 19 199 194 154
15 0 19 199 194 154
16 0 19 199 194 154
17 0 19 199 194 154
18 0 19 199 194 154
19 0 19 199 194 154
20 0 19 199 194 154
21 0 19 199 194 154
22 0 19 199 194 154
23 0 19 199 194 154
24 0 19 199 194 154
-24 1 19 199 194 154
-23 1 19 199 194 154
-22 1 19 199 194 154
-21 1 19 199 194 154
-20 1 19 199 194 154
-19 1 19 199 194 154
-18 1 19 199 194 154
-17 1 19 199 194 154
-16 1 19 199 194 154
-4 1 19 199 194 154
-2 1 19 167 162 121
-1 1 19 167 162 121
0 1 19 167 162 121
1 1 19 167 162 121
2 1 19 167 162 121
12 1 19 199 194 154
13 1 19 199 194 154
14 1 19 199 194 154
15 1 19 199 194 154
16 1 19 199 194 154
17 1 19 199 194 154
18 1 19 199 194 154
19 1 19 199 194 154
20 1 19 199 194 154
21 1 19 199 194 154
22 1 19 199 194 154
23 1 19 199 194 154
24 1 19 199 194 154
-24 2 19 199 194 154
-23 2 19 199 194 154
-22 2 19 199 194 154
-21 2 19 199 194 154
-20 2 19 199 194 154
-19 2 19 199 194 154
-18 2 19 199 194 154
-17 2 19 199 194 154
-16 2 19 199 194 154
-4 2 19 199 194 154
-2 2 19 167 162 121
-1 2 19 167 162 121
0 2 19 167 162 121
1 2 19 167 162 121
2 2 19 167 162 121
12 2 19 199 194 154
13 2 19 199 194 154
14 2 19 199 194 154
15 2 19 199 194 154
16 2 19 199 194 154
17 2 19 199 194 154
18 2 19 199 194 154
19 2 19 199 194 154
20 2 19 199 194 154
21 2 19 199 194 154
22 2 19 199 194 154
23 2 19 199 194 154
24 2 19 199 194 154
-4 3 19 199 194 154
21 3 19 199 194 154
22 3 19 199 194 154
23 3 19 199 194 154
24 3 19 199 194 154
21 4 19 199 194 154
22 4 19 199 194 154
23 4 19 199 194 154
24 4 19 199 194 154
21 5 19 199 194 154
22 5 19 199 194 154
23 5 19 199 194 154
24 5 19 199 194 154
21 6 19 199 194 154
22 6 19 199 194 154
23 6 19 199 194 154
24 6 19 199 194 154
21 7 19 199 194 154
22 7 19 199 194 154
23 7 19 199 194 154
24 7 19 199 194 154
21 8 19 199 194 154
22 8 19 199 194 154
23 8 19 199 194 154
24 8 19 199 194 154
21 9 19 199 194 154
22 9 19 199 194 154
23 9 19 199 194 154
24 9 19 199 194 154
21 10 19 199 194 154
22 10 19 199 194 154
23 10 19 199 194 154
24 10 19 199 194 154
-8 16 19 103 113 88
-6 16 19 103 113 88
-5 16 19 103 113 88
-4 16 19 103 113 88
-2 16 19 199 194 154
-1 16 19 199 194 154
0 16 19 199 194 154
1 16 19 199 194 154
2 16 19 199 194 154
-19 17 19 103 113 88
-18 17 19 103 113 88
-8 17 19 103 113 88
-6 17 19 103 113 88
-5 17 19 103 113 88
-4 17 19 103 113 88
-2 17 19 199 194 154
-1 17 19 199 194 154
0 17 19 199 194 154
1 17 19 199 194 154
2 17 19 199 194 154
-19 18 19 103 113 88
-18 18 19 103 113 88
-6 18 19 103 113 88
-5 18 19 103 113 88
-4 18 19 103 113 88
-2 18 19 199 194 154
-1 18 19 199 194 154
0 18 19 199 194 154
1 18 19 199 194 154
2 18 19 199 194 154
-19 19 19 103 113 88
-18 19 19 103 113 88
-12 19 19 103 113 88
-11 19 19 103 113 88
-10 19 19 103 113 88
-2 19 19 199 194 154
-1 19 19 199 194 154
0 19 19 199 194 154
1 19 19 199 194 154
2 19 19 199 194 154
-12 20 19 103 113 88
-11 20 19 103 113 88
-10 20 19 103 113 88
-2 20 19 199 194 154
-1 20 19 199 194 154
0 20 19 199 194 154
1 20 19 199 194 154
2 20 19 199 194 154
-2 21 19 199 194 154
-1 21 19 199 194 154
0 21 19 199 194 154
1 21 19 199 194 154
2 21 19 199 194 154
-17 22 19 103 113 88
-2 22 19 199 194 154
-1 22 19 199 194 154
0 22 19 199 194 154
1 22 19 199 194 154
2 22 19 199 194 154
-17 23 19 103 113 88
-2 23 19 199 194 154
-1 23 19 199 194 154
0 23 19 199 194 154
1 23 19 199 194 154
2 23 19 199 194 154
-2 24 19 199 194 154
-1 24 19 199 194 154
0 24 19 199 194 154
1 24 19 199 194 154
2 24 19 199 194 154
12 -10 20 199 194 154
13 -10 20 199 194 154
14 -10 20 199 194 154
15 -10 20 199 194 154
12 -9 20 199 194 154
13 -9 20 199 194 154
14 -9 20 199 194 154
15 -9 20 199 194 154
12 -8 20 199 194 154
13 -8 20 199 194 154
14 -8 20 199 194 154
15 -8 20 199 194 154
12 -7 20 199 194 154
13 -7 20 199 194 154
14 -7 20 199 194 154
15 -7 20 199 194 154
12 -6 20 199 194 154
13 -6 20 199 194 154
14 -6 20 199 194 154
15 -6 20 199 194 154
12 -5 20 199 194 154
13 -5 20 199 194 154
14 -5 20 199 194 154
15 -5 20 199 194 154
-4 -4 20 199 194 154
-3 -4 20 199 194 154
-2 -4 20 199 194 154
-1 -4 20 199 194 154
0 -4 20 199 194 154
1 -4 20 199 194 154
2 -4 20 199 194 154
3 -4 20 199 194 154
12 -4 20 199 194 154
13 -4 20 199 194 154
14 -4 20 199 194 154
15 -4 20 199 194 154
-4 -3 20 199 194 154
12 -3 20 199 194 154
13 -3 20 199 194 154
14 -3 20 199 194 154
15 -3 20 199 194 154
-24 -2 20 199 194 154
-23 -2 20 199 194 154
-22 -2 20 199 194 154
-21 -2 20 199 194 154
-20 -2 20 199 194 154
-19 -2 20 199 194 154
-18 -2 20 199 194 154
-17 -2 20 199 194 154
-16 -2 20 199 194 154
-4 -2 20 199 194 154
-2 -2 20 167 162 121
-1 -2 20 167 162 121
0 -2 20 167 162 121
1 -2 20 167 162 121
2 -2 20 167 162 121
12 -2 20 199 194 154
13 -2 20 199 194 154
14 -2 20 199 194 154
15 -2 20 199 194 154
16 -2 20 199 194 154
17 -2 20 199 194 154
18 -2 20 199 194 154
19 -2 20 199 194 154
20 -2 20 199 194 154
21 -2 20 199 194 154
22 -2 20 199 194 154
23 -2 20 199 194 154
24 -2 20 199 194 154
-24 -1 20 199 194 154
-23 -1 20 199 194 154
-22 -1 20 199 194 154
-21 -1 20 199 194 154
-20 -1 20 199 194 154
-19 -1 20 199 194 154
-18 -1 20 199 194 154
-17 -1 20 199 194 154
-16 -1 20 199 194 154
-4 -1 20 199 194 154
-2 -1 20 167 162 121
-1 -1 20 167 162 121
0 -1 20 167 162 121
1 -1 20 167 162 121
2 -1 20 167 162 121
12 -1 20 199 194 154
13 -1 20 199 194 154
14 -1 20 199 194 154
15 -1 20 199 194 154
16 -1 20 199 194 154
17 -1 20 199 194 154
18 -1 20 199 194 154
19 -1 20 199 194 154
20 -1 20 199 194 154
21 -1 20 199 194 154
22 -1 20 199 194 154
23 -1 20 199 194 154
24 -1 20 199 194 154
-24 0 20 199 194 154
-23 0 20 199 194 154
-22 0 20 199 194 154
-21 0 20 199 194 154
-20 0 20 199 194 154
-19 0 20 199 194 154
-18 0 20 199 194 154
-17 0 20 199 194 154
-16 0 20 199 194 154
-4 0 20 199 194 154
-2 0 20 167 162 121
-1 0 20 167 162 121
0 0 20 167 162 121
1 0 20 167 162 121
2 0 20 167 162 121
12 0 20 199 194 154
13 0 20 199 194 154
14 0 20 199 194 154
15 0 20 199 194 154
16 0 20 199 194 154
17 0 20 199 194 154
18 0 20 199 194 154
19 0 20 199 194 154
20 0 20 199 194 154
21 0 20 199 194 154
22 0 20 199 194 154
23 0 20 199 194 154
24 0 20 199 194 154
-24 1 20 199 194 154
-23 1 20 199 194 154
-22 1 20 199 194 154
-21 1 20 199 194 154
-20 1 20 199 194 154
-19 1 20 199 194 154
-18 1 20 199 194 154
-17 1 20 199 194 154
-16 1 20 199 194 154
-4 1 20 199 194 154
-2 1 20 167 162 121
-1 1 20 167 162 121
0 1 20 167 162 121
1 1 20 167 162 121
2 1 20 167 162 121
12 1 20 199 194 154
13 1 20 199 194 154
14 1 20 199 194 154
15 1 20 199 194 154
16 1 20 199 194 154
17 1 20 199 194 154
18 1 20 199 194 154
19 1 20 199 194 154
20 1 20 199 194 154
21 1 20 199 194 154
22 1 20 199 194 154
23 1 20 199 194 154
24 1 20 199 194 154
-24 2 20 199 194 154
-23 2 20 199 194 154
-22 2 20 199 194 154
-21 2 20 199 194 154
-20 2 20 199 194 154
-19 2 20 199 194 154
-18 2 20 199 194 154
-17 2 20 199 194 154
-16 2 20 199 194 154
-4 2 20 199 194 154
-2 2 20 167 162 121
-1 2 20 167 162 121
0 2 20 167 162 121
1 2 20 167 162 121
2 2 20 167 162 121
12 2 20 199 194 154
13 2 20 199 194 154
14 2 20 199 194 154
15 2 20 199 194 154
16 2 20 199 194 154
17 2 20 199 194 154
18 2 20 199 194 154
19 2 20 199 194 154
20 2 20 199 194 154
21 2 20 199 194 154
22 2 20 199 194 154
23 2 20 199 194 154
24 2 20 199 194 154
-4 3 20 199 194 154
21 3 20 199 194 154
22 3 20 199 194 154
23 3 20 199 194 154
24 3 20 199 194 154
21 4 20 199 194 154
22 4 20 199 194 154
23 4 20 199 194 154
24 4 20 199 194 154
21 5 20 199 194 154
22 5 20 199 194 154
23 5 20 199 194 154
24 5 20 199 194 154
21 6 20 199 194 154
22 6 20 199 194 154
23 6 20 199 194 154
24 6 20 199 194 154
21 7 20 199 194 154
22 7 20 199 194 154
23 7 20 199 194 154
24 7 20 199 194 154
21 8 20 199 194 154
22 8 20 199 194 154
23 8 20 199 194 154
24 8 20 199 194 154
21 9 20 199 194 154
22 9 20 199 194 154
23 9 20 199 194 154
24 9 20 199 194 154
21 10 20 199 194 154
22 10 20 199 194 154
23 10 20 199 194 154
24 10 20 199 194 154
-2 16 20 199 194 154
-1 16 20 199 194 154
0 16 20 199 194 154
1 16 20 199 194 154
2 16 20 199 194 154
-2 17 20 199 194 154
-1 17 20 199 194 154
0 17 20 199 194 154
1 17 20 199 194 154
2 17 20 199 194 154
-2 18 20 199 194 154
-1 18 20 199 194 154
0 18 20 199 194 154
1 18 20 199 194 154
2 18 20 199 194 154
-2 19 20 199 194 154
-1 19 20 199 194 154
0 19 20 199 194 154
1 19 20 199 194 154
2 19 20 199 194 154
-2 20 20 199 194 154
-1 20 20 199 194 154
0 20 20 199 194 154
1 20 20 199 194 154
2 20 20 199 194 154
-2 21 20 199 194 154
-1 21 20 199 194 154
0 21 20 199 194 154
1 21 20 199 194 154
2 21 20 199 194 154
-2 22 20 199 194 154
-1 22 20 199 194 154
0 22 20 199 194 154
1 22 20 199 194 154
2 22 20 199 194 154
-2 23 20 199 194 154
-1 23 20 199 194 154
0 23 20 199 194 154
1 23 20 199 194 154
2 23 20 199 194 154
-2 24 20 199 194 154
-1 24 20 199 194 154
0 24 20 199 194 154
1 24 20 199 194 154
2 24 20 199 194 154
12 -10 21 199 194 154
13 -10 21 199 194 154
14 -10 21 199 194 154
15 -10 21 199 194 154
12 -9 21 199 194 154
13 -9 21 199 194 154
14 -9 21 199 194 154
15 -9 21 199 194 154
12 -8 21 199 194 154
13 -8 21 199 194 154
14 -8 21 199 194 154
15 -8 21 199 194 154
12 -7 21 199 194 154
13 -7 21 199 194 154
14 -7 21 199 194 154
15 -7 21 199 194 154
12 -6 21 199 194 154
13 -6 21 199 194 154
14 -6 21 199 194 154
15 -6 21 199 194 154
12 -5 21 199 194 154
13 -5 21 199 194 154
14 -5 21 199 194 154
15 -5 21 199 194 154
-4 -4 21 199 194 154
-3 -4 21 199 194 154
-2 -4 21 199 194 154
-1 -4 21 199 194 154
0 -4 21 199 194 154
1 -4 21 199 194 154
2 -4 21 199 194 154
3 -4 21 199 194 154
12 -4 21 199 194 154
13 -4 21 199 194 154
14 -4 21 199 194 154
15 -4 21 199 194 154
-4 -3 21 199 194 154
12 -3 21 199 194 154
13 -3 21 199 194 154
14 -3 21 199 194 154
15 -3 21 199 194 154
-22 -2 21 199 194 154
-21 -2 21 199 194 154
-20 -2 21 199 194 154
-19 -2 21 199 194 154
-18 -2 21 199 194 154
-17 -2 21 199 194 154
-16 -2 21 199 194 154
-4 -2 21 199 194 154
-2 -2 21 167 162 121
-1 -2 21 167 162 121
0 -2 21 167 162 121
1 -2 21 167 162 121
2 -2 21 167 162 121
12 -2 21 199 194 154
13 -2 21 199 194 154
14 -2 21 199 194 154
15 -2 21 199 194 154
16 -2 21 199 194 154
17 -2 21 199 194 154
18 -2 21 199 194 154
19 -2 21 199 194 154
20 -2 21 199 194 154
21 -2 21 199 194 154
22 -2 21 199 194 154
23 -2 21 199 194 154
24 -2 21 199 194 154
-24 -1 21 199 194 154
-23 -1 21 199 194 154
-22 -1 21 199 194 154
-21 -1 21 199 194 154
-20 -1 21 199 194 154
-19 -1 21 199 194 154
-18 -1 21 199 194 154
-17 -1 21 199 194 154
-16 -1 21 199 194 154
-4 -1 21 199 194 154
-2 -1 21 167 162 121
-1 -1 21 167 162 121
0 -1 21 167 162 121
1 -1 21 167 162 121
2 -1 21 167 162 121
12 -1 21 199 194 154
13 -1 21 199 194 154
14 -1 21 199 194 154
15 -1 21 199 194 154
16 -1 21 199 194 154
17 -1 21 199 194 154
18 -1 21 199 194 154
19 -1 21 199 194 154
20 -1 21 199 194 154
21 -1 21 199 194 154
22 -1 21 199 194 154
23 -1 21 199 194 154
24 -1 21 199 194 154
-24 0 21 199 194 154
-23 0 21 199 194 154
-22 0 21 199 194 154
-21 0 21 199 194 154
-20 0 21 199 194 154
-19 0 21 199 194 154
-18 0 21 199 194 154
-17 0 21 199 194 154
-16 0 21 199 194 154
-4 0 21 199 194 154
-2 0 21 167 162 121
-1 0 21 167 162 121
0 0 21 167 162 121
1 0 21 167 162 121
2 0 21 167 162 121
12 0 21 199 194 154
13 0 21 199 194 154
14 0 21 199 194 154
15 0 21 199 194 154
16 0 21 199 194 154
17 0 21 199 194 154
18 0 21 199 194 154
19 0 21 199 194 154
20 0 21 199 194 154
21 0 21 199 194 154
22 0 21 199 194 154
23 0 21 199 194 154
24 0 21 199 194 154
-24 1 21 199 194 154
-23 1 21 199 194 154
-22 1 21 199 194 154
-21 1 21 199 194 154
-20 1 21 199 194 154
-19 1 21 199 194 154
-18 1 21 199 194 154
-17 1 21 199 194 154
-16 1 21 199 194 154
-4 1 21 199 194 154
-2 1 21 167 162 121
-1 1 21 167 162 121
0 1 21 167 162 121
1 1 21 167 162 121
2 1 21 167 162 121
12 1 21 199 194 154
13 1 21 199 194 154
14 1 21 199 194 154
15 1 21 199 194 154
16 1 21 199 194 154
17 1 21 199 194 154
18 1 21 199 194 154
19 1 21 199 194 154
20 1 21 199 194 154
21 1 21 199 194 154
22 1 21 199 194 154
23 1 21 199 194 154
24 1 21 199 194 154
-24 2 21 199 194 154
-23 2 21 199 194 154
-22 2 21 199 194 154
-21 2 21 199 194 154
-20 2 21 199 194 154
-19 2 21 199 194 154
-18 2 21 199 194 154
-17 2 21 199 194 154
-16 2 21 199 194 154
-4 2 21 199 194 154
-2 2 21 167 162 121
-1 2 21 167 162 121
0 2 21 167 162 121
1 2 21 167 162 121
2 2 21 167 162 121
12 2 21 199 194 154
13 2 21 199 194 154
14 2 21 199 194 154
15 2 21 199 194 154
16 2 21 199 194 154
17 2 21 199 194 154
18 2 21 199 194 154
19 2 21 199 194 154
20 2 21 199 194 154
21 2 21 199 194 154
22 2 21 199 194 154
23 2 21 199 194 154
24 2 21 199 194 154
-4 3 21 199 194 154
21 3 21 199 194 154
22 3 21 199 194 154
23 3 21 199 194 154
24 3 21 199 194 154
21 4 21 199 194 154
22 4 21 199 194 154
23 4 21 199 194 154
24 4 21 199 194 154
21 5 21 199 194 154
22 5 21 199 194 154
23 5 21 199 194 154
24 5 21 199 194 154
21 6 21 199 194 154
22 6 21 199 194 154
23 6 21 199 194 154
24 6 21 199 194 154
21 7 21 199 194 154
22 7 21 199 194 154
23 7 21 199 194 154
24 7 21 199 194 154
21 8 21 199 194 154
22 8 21 199 194 154
23 8 21 199 194 154
24 8 21 199 194 154
21 9 21 199 194 154
22 9 21 199 194 154
23 9 21 199 194 154
24 9 21 199 194 154
21 10 21 199 194 154
22 10 21 199 194 154
23 10 21 199 194 154
24 10 21 199 194 154
-2 16 21 199 194 154
-1 16 21 199 194 154
0 16 21 199 194 154
1 16 21 199 194 154
2 16 21 199 194 154
-2 17 21 199 194 154
-1 17 21 199 194 154
0 17 21 199 194 154
1 17 21 199 194 154
2 17 21 199 194 154
-2 18 21 199 194 154
-1 18 21 199 194 154
0 18 21 199 194 154
1 18 21 199 194 154
2 18 21 199 194 154
-2 19 21 199 194 154
-1 19 21 199 194 154
0 19 21 199 194 154
1 19 21 199 194 154
2 19 21 199 194 154
-2 20 21 199 194 154
-1 20 21 199 194 154
0 20 21 199 194 154
1 20 21 199 194 154
2 20 21 199 194 154
-2 21 21 199 194 154
-1 21 21 199 194 154
0 21 21 199 194 154
1 21 21 199 194 154
2 21 21 199 194 154
-2 22 21 199 194 154
-1 22 21 199 194 154
0 22 21 199 194 154
1 22 21 199 194 154
2 22 21 199 194 154
-2 23 21 199 194 154
-1 23 21 199 194 154
0 23 21 199 194 154
1 23 21 199 194 154
2 23 21 199 194 154
-2 24 21 199 194 154
-1 24 21 199 194 154
0 24 21 199 194 154
1 24 21 199 194 154
2 24 21 199 194 154
12 -10 22 199 194 154
13 -10 22 199 194 154
14 -10 22 199 194 154
15 -10 22 199 194 154
12 -9 22 199 194 154
13 -9 22 199 194 154
14 -9 22 199 194 154
15 -9 22 199 194 154
12 -8 22 199 194 154
13 -8 22 199 194 154
14 -8 22 199 194 154
15 -8 22 199 194 154
12 -7 22 199 194 154
13 -7 22 199 194 154
14 -7 22 199 194 154
15 -7 22 199 194 154
