ply
format ascii 1.0
comment : MagicaVoxel @ Ephtracy
element vertex 3362
property float x
property float y
property float z
property uchar red
property uchar green
property uchar blue
end_header
-4 -15 15 102 153 255
-3 -15 15 102 153 255
-2 -15 15 102 153 255
-1 -15 15 102 153 255
0 -15 15 102 153 255
1 -15 15 102 153 255
2 -15 15 102 153 255
3 -15 15 102 153 255
4 -15 15 102 153 255
5 -15 15 102 153 255
6 -15 15 102 153 255
-6 -14 15 102 153 255
-5 -14 15 102 153 255
-4 -14 15 102 153 255
-3 -14 15 102 153 255
-2 -14 15 102 153 255
-1 -14 15 102 153 255
0 -14 15 102 153 255
1 -14 15 102 153 255
2 -14 15 102 153 255
3 -14 15 102 153 255
4 -14 15 102 153 255
5 -14 15 102 153 255
6 -14 15 102 153 255
7 -14 15 102 153 255
8 -14 15 102 153 255
-8 -13 15 102 153 255
-7 -13 15 102 153 255
-6 -13 15 102 153 255
-5 -13 15 102 153 255
-4 -13 15 102 153 255
5 -13 15 102 153 255
6 -13 15 102 153 255
7 -13 15 102 153 255
8 -13 15 102 153 255
9 -13 15 102 153 255
-9 -12 15 102 153 255
-8 -12 15 102 153 255
-7 -12 15 102 153 255
-6 -12 15 102 153 255
8 -12 15 102 153 255
9 -12 15 102 153 255
10 -12 15 102 153 255
11 -12 15 102 153 255
-10 -11 15 102 153 255
-9 -11 15 102 153 255
-8 -11 15 102 153 255
-7 -11 15 102 153 255
9 -11 15 102 153 255
10 -11 15 102 153 255
11 -11 15 102 153 255
-11 -10 15 102 153 255
-10 -10 15 102 153 255
-9 -10 15 102 153 255
-8 -10 15 102 153 255
10 -10 15 102 153 255
11 -10 15 102 153 255
12 -10 15 102 153 255
-11 -9 15 102 153 255
-10 -9 15 102 153 255
-9 -9 15 102 153 255
11 -9 15 102 153 255
12 -9 15 102 153 255
13 -9 15 102 153 255
-12 -8 15 102 153 255
-11 -8 15 102 153 255
-10 -8 15 102 153 255
12 -8 15 102 153 255
13 -8 15 102 153 255
14 -8 15 102 153 255
-12 -7 15 102 153 255
-11 -7 15 102 153 255
12 -7 15 102 153 255
13 -7 15 102 153 255
14 -7 15 102 153 255
-13 -6 15 102 153 255
-12 -6 15 102 153 255
-11 -6 15 102 153 255
13 -6 15 102 153 255
14 -6 15 102 153 255
-13 -5 15 102 153 255
-12 -5 15 102 153 255
13 -5 15 102 153 255
14 -5 15 102 153 255
15 -5 15 102 153 255
-13 -4 15 102 153 255
-12 -4 15 102 153 255
14 -4 15 102 153 255
15 -4 15 102 153 255
-13 -3 15 102 153 255
-12 -3 15 102 153 255
14 -3 15 102 153 255
15 -3 15 102 153 255
-13 -2 15 102 153 255
-12 -2 15 102 153 255
14 -2 15 102 153 255
15 -2 15 102 153 255
-13 -1 15 102 153 255
-12 -1 15 102 153 255
14 -1 15 102 153 255
15 -1 15 102 153 255
-13 0 15 102 153 255
-12 0 15 102 153 255
14 0 15 102 153 255
15 0 15 102 153 255
-13 1 15 102 153 255
-12 1 15 102 153 255
14 1 15 102 153 255
15 1 15 102 153 255
-13 2 15 102 153 255
-12 2 15 102 153 255
13 2 15 102 153 255
14 2 15 102 153 255
15 2 15 102 153 255
-13 3 15 102 153 255
-12 3 15 102 153 255
-11 3 15 102 153 255
13 3 15 102 153 255
14 3 15 102 153 255
15 3 15 102 153 255
-12 4 15 102 153 255
-11 4 15 102 153 255
13 4 15 102 153 255
14 4 15 102 153 255
-12 5 15 102 153 255
-11 5 15 102 153 255
12 5 15 102 153 255
13 5 15 102 153 255
14 5 15 102 153 255
-12 6 15 102 153 255
-11 6 15 102 153 255
-10 6 15 102 153 255
12 6 15 102 153 255
13 6 15 102 153 255
-11 7 15 102 153 255
-10 7 15 102 153 255
-9 7 15 102 153 255
11 7 15 102 153 255
12 7 15 102 153 255
13 7 15 102 153 255
-10 8 15 102 153 255
-9 8 15 102 153 255
-8 8 15 102 153 255
10 8 15 102 153 255
11 8 15 102 153 255
12 8 15 102 153 255
-9 9 15 102 153 255
-8 9 15 102 153 255
-7 9 15 102 153 255
9 9 15 102 153 255
10 9 15 102 153 255
11 9 15 102 153 255
-8 10 15 102 153 255
-7 10 15 102 153 255
-6 10 15 102 153 255
-5 10 15 102 153 255
7 10 15 102 153 255
8 10 15 102 153 255
9 10 15 102 153 255
10 10 15 102 153 255
-7 11 15 102 153 255
-6 11 15 102 153 255
-5 11 15 102 153 255
-4 11 15 102 153 255
-3 11 15 102 153 255
4 11 15 102 153 255
5 11 15 102 153 255
6 11 15 102 153 255
7 11 15 102 153 255
8 11 15 102 153 255
9 11 15 102 153 255
-5 12 15 102 153 255
-4 12 15 102 153 255
-3 12 15 102 153 255
-2 12 15 102 153 255
-1 12 15 102 153 255
0 12 15 102 153 255
1 12 15 102 153 255
2 12 15 102 153 255
3 12 15 102 153 255
4 12 15 102 153 255
5 12 15 102 153 255
6 12 15 102 153 255
7 12 15 102 153 255
-3 13 15 102 153 255
-2 13 15 102 153 255
-1 13 15 102 153 255
0 13 15 102 153 255
1 13 15 102 153 255
2 13 15 102 153 255
3 13 15 102 153 255
4 13 15 102 153 255
5 13 15 102 153 255
-3 -16 16 102 153 255
-2 -16 16 102 153 255
-1 -16 16 102 153 255
0 -16 16 102 153 255
1 -16 16 102 153 255
2 -16 16 102 153 255
3 -16 16 102 153 255
4 -16 16 102 153 255
5 -16 16 102 153 255
-6 -15 16 102 153 255
-5 -15 16 102 153 255
-4 -15 16 102 153 255
5 -15 16 102 153 255
6 -15 16 102 153 255
7 -15 16 102 153 255
-7 -14 16 102 153 255
-6 -14 16 102 153 255
8 -14 16 102 153 255
9 -14 16 102 153 255
-9 -13 16 102 153 255
-8 -13 16 102 153 255
10 -13 16 102 153 255
-10 -12 16 102 153 255
-9 -12 16 102 153 255
11 -12 16 102 153 255
-11 -11 16 102 153 255
-10 -11 16 102 153 255
12 -11 16 102 153 255
-11 -10 16 102 153 255
13 -10 16 102 153 255
-12 -9 16 102 153 255
13 -9 16 102 153 255
14 -9 16 102 153 255
-12 -8 16 102 153 255
14 -8 16 102 153 255
-13 -7 16 102 153 255
15 -7 16 102 153 255
-13 -6 16 102 153 255
15 -6 16 102 153 255
-14 -5 16 102 153 255
15 -5 16 102 153 255
-14 -4 16 102 153 255
-14 -3 16 102 153 255
16 -3 16 102 153 255
-14 -2 16 102 153 255
16 -2 16 102 153 255
-14 -1 16 102 153 255
16 -1 16 102 153 255
-14 0 16 102 153 255
16 0 16 102 153 255
-14 1 16 102 153 255
16 1 16 102 153 255
-14 2 16 102 153 255
15 2 16 102 153 255
-13 3 16 102 153 255
15 3 16 102 153 255
-13 4 16 102 153 255
15 4 16 102 153 255
-13 5 16 102 153 255
14 5 16 102 153 255
15 5 16 102 153 255
-12 6 16 102 153 255
14 6 16 102 153 255
-12 7 16 102 153 255
-11 7 16 102 153 255
13 7 16 102 153 255
14 7 16 102 153 255
-11 8 16 102 153 255
12 8 16 102 153 255
13 8 16 102 153 255
-10 9 16 102 153 255
12 9 16 102 153 255
-9 10 16 102 153 255
10 10 16 102 153 255
11 10 16 102 153 255
-8 11 16 102 153 255
-7 11 16 102 153 255
9 11 16 102 153 255
10 11 16 102 153 255
-7 12 16 102 153 255
-6 12 16 102 153 255
-5 12 16 102 153 255
7 12 16 102 153 255
8 12 16 102 153 255
9 12 16 102 153 255
-5 13 16 102 153 255
-4 13 16 102 153 255
-3 13 16 102 153 255
-2 13 16 102 153 255
4 13 16 102 153 255
5 13 16 102 153 255
6 13 16 102 153 255
7 13 16 102 153 255
-1 14 16 102 153 255
0 14 16 102 153 255
1 14 16 102 153 255
2 14 16 102 153 255
3 14 16 102 153 255
-4 -17 17 102 153 255
-3 -17 17 102 153 255
-2 -17 17 102 153 255
-1 -17 17 102 153 255
0 -17 17 102 153 255
1 -17 17 102 153 255
2 -17 17 102 153 255
3 -17 17 102 153 255
4 -17 17 102 153 255
5 -17 17 102 153 255
-6 -16 17 102 153 255
-5 -16 17 102 153 255
-4 -16 17 102 153 255
5 -16 17 102 153 255
6 -16 17 102 153 255
7 -16 17 102 153 255
8 -16 17 102 153 255
-8 -15 17 102 153 255
-7 -15 17 102 153 255
-6 -15 17 102 153 255
8 -15 17 102 153 255
9 -15 17 102 153 255
10 -15 17 102 153 255
-9 -14 17 102 153 255
-8 -14 17 102 153 255
10 -14 17 102 153 255
11 -14 17 102 153 255
-10 -13 17 102 153 255
-9 -13 17 102 153 255
11 -13 17 102 153 255
12 -13 17 102 153 255
-11 -12 17 102 153 255
12 -12 17 102 153 255
13 -12 17 102 153 255
-12 -11 17 102 153 255
-11 -11 17 102 153 255
13 -11 17 102 153 255
14 -11 17 102 153 255
-13 -10 17 102 153 255
-12 -10 17 102 153 255
14 -10 17 102 153 255
15 -10 17 102 153 255
-13 -9 17 102 153 255
15 -9 17 102 153 255
-14 -8 17 102 153 255
-13 -8 17 102 153 255
15 -8 17 102 153 255
16 -8 17 102 153 255
-14 -7 17 102 153 255
16 -7 17 102 153 255
-15 -6 17 102 153 255
-14 -6 17 102 153 255
16 -6 17 102 153 255
-15 -5 17 102 153 255
16 -5 17 102 153 255
17 -5 17 102 153 255
-15 -4 17 102 153 255
17 -4 17 102 153 255
-15 -3 17 102 153 255
17 -3 17 102 153 255
-15 -2 17 102 153 255
17 -2 17 102 153 255
-15 -1 17 102 153 255
17 -1 17 102 153 255
-15 0 17 102 153 255
17 0 17 102 153 255
-15 1 17 102 153 255
17 1 17 102 153 255
-15 2 17 102 153 255
16 2 17 102 153 255
17 2 17 102 153 255
-15 3 17 102 153 255
-14 3 17 102 153 255
16 3 17 102 153 255
-14 4 17 102 153 255
16 4 17 102 153 255
-14 5 17 102 153 255
15 5 17 102 153 255
16 5 17 102 153 255
-14 6 17 102 153 255
-13 6 17 102 153 255
15 6 17 102 153 255
-13 7 17 102 153 255
14 7 17 102 153 255
15 7 17 102 153 255
-13 8 17 102 153 255
-12 8 17 102 153 255
14 8 17 102 153 255
-12 9 17 102 153 255
-11 9 17 102 153 255
13 9 17 102 153 255
14 9 17 102 153 255
-11 10 17 102 153 255
-10 10 17 102 153 255
12 10 17 102 153 255
13 10 17 102 153 255
-10 11 17 102 153 255
-9 11 17 102 153 255
11 11 17 102 153 255
12 11 17 102 153 255
-9 12 17 102 153 255
-8 12 17 102 153 255
9 12 17 102 153 255
10 12 17 102 153 255
11 12 17 102 153 255
-7 13 17 102 153 255
-6 13 17 102 153 255
7 13 17 102 153 255
8 13 17 102 153 255
9 13 17 102 153 255
-6 14 17 102 153 255
-5 14 17 102 153 255
-4 14 17 102 153 255
-3 14 17 102 153 255
-2 14 17 102 153 255
4 14 17 102 153 255
5 14 17 102 153 255
6 14 17 102 153 255
7 14 17 102 153 255
-2 15 17 102 153 255
-1 15 17 102 153 255
0 15 17 102 153 255
1 15 17 102 153 255
2 15 17 102 153 255
3 15 17 102 153 255
4 15 17 102 153 255
-4 -18 18 102 153 255
-3 -18 18 102 153 255
-2 -18 18 102 153 255
-1 -18 18 102 153 255
0 -18 18 102 153 255
1 -18 18 102 153 255
2 -18 18 102 153 255
3 -18 18 102 153 255
4 -18 18 102 153 255
5 -18 18 102 153 255
6 -18 18 102 153 255
-7 -17 18 102 153 255
-6 -17 18 102 153 255
-5 -17 18 102 153 255
6 -17 18 102 153 255
7 -17 18 102 153 255
8 -17 18 102 153 255
-8 -16 18 102 153 255
-7 -16 18 102 153 255
9 -16 18 102 153 255
10 -16 18 102 153 255
-10 -15 18 102 153 255
-9 -15 18 102 153 255
10 -15 18 102 153 255
11 -15 18 102 153 255
12 -15 18 102 153 255
-11 -14 18 102 153 255
-10 -14 18 102 153 255
12 -14 18 102 153 255
13 -14 18 102 153 255
-12 -13 18 102 153 255
-11 -13 18 102 153 255
13 -13 18 102 153 255
14 -13 18 102 153 255
-13 -12 18 102 153 255
-12 -12 18 102 153 255
14 -12 18 102 153 255
-13 -11 18 102 153 255
15 -11 18 102 153 255
-14 -10 18 102 153 255
15 -10 18 102 153 255
16 -10 18 102 153 255
-15 -9 18 102 153 255
-14 -9 18 102 153 255
16 -9 18 102 153 255
-15 -8 18 102 153 255
16 -8 18 102 153 255
17 -8 18 102 153 255
-15 -7 18 102 153 255
17 -7 18 102 153 255
-16 -6 18 102 153 255
-15 -6 18 102 153 255
17 -6 18 102 153 255
-16 -5 18 102 153 255
17 -5 18 102 153 255
18 -5 18 102 153 255
-16 -4 18 102 153 255
18 -4 18 102 153 255
-16 -3 18 102 153 255
18 -3 18 102 153 255
-16 -2 18 102 153 255
18 -2 18 102 153 255
-16 -1 18 102 153 255
18 -1 18 102 153 255
-16 0 18 102 153 255
18 0 18 102 153 255
-16 1 18 102 153 255
18 1 18 102 153 255
-16 2 18 102 153 255
18 2 18 102 153 255
-16 3 18 102 153 255
17 3 18 102 153 255
18 3 18 102 153 255
-16 4 18 102 153 255
-15 4 18 102 153 255
17 4 18 102 153 255
-15 5 18 102 153 255
17 5 18 102 153 255
-15 6 18 102 153 255
16 6 18 102 153 255
17 6 18 102 153 255
-14 7 18 102 153 255
16 7 18 102 153 255
-14 8 18 102 153 255
-13 8 18 102 153 255
15 8 18 102 153 255
16 8 18 102 153 255
-13 9 18 102 153 255
14 9 18 102 153 255
15 9 18 102 153 255
-12 10 18 102 153 255
14 10 18 102 153 255
-12 11 18 102 153 255
-11 11 18 102 153 255
13 11 18 102 153 255
-11 12 18 102 153 255
-10 12 18 102 153 255
11 12 18 102 153 255
12 12 18 102 153 255
-9 13 18 102 153 255
-8 13 18 102 153 255
10 13 18 102 153 255
11 13 18 102 153 255
-8 14 18 102 153 255
-7 14 18 102 153 255
-6 14 18 102 153 255
8 14 18 102 153 255
9 14 18 102 153 255
10 14 18 102 153 255
-6 15 18 102 153 255
-5 15 18 102 153 255
-4 15 18 102 153 255
-3 15 18 102 153 255
5 15 18 102 153 255
6 15 18 102 153 255
7 15 18 102 153 255
8 15 18 102 153 255
-3 16 18 102 153 255
-2 16 18 102 153 255
-1 16 18 102 153 255
0 16 18 102 153 255
1 16 18 102 153 255
2 16 18 102 153 255
3 16 18 102 153 255
4 16 18 102 153 255
5 16 18 102 153 255
-4 -19 19 102 153 255
-3 -19 19 102 153 255
-2 -19 19 102 153 255
-1 -19 19 102 153 255
0 -19 19 102 153 255
1 -19 19 102 153 255
2 -19 19 102 153 255
3 -19 19 102 153 255
4 -19 19 102 153 255
5 -19 19 102 153 255
-7 -18 19 102 153 255
-6 -18 19 102 153 255
-5 -18 19 102 153 255
6 -18 19 102 153 255
7 -18 19 102 153 255
8 -18 19 102 153 255
-8 -17 19 102 153 255
-7 -17 19 102 153 255
9 -17 19 102 153 255
10 -17 19 102 153 255
-10 -16 19 102 153 255
-9 -16 19 102 153 255
11 -16 19 102 153 255
12 -16 19 102 153 255
-11 -15 19 102 153 255
-10 -15 19 102 153 255
12 -15 19 102 153 255
13 -15 19 102 153 255
-12 -14 19 102 153 255
13 -14 19 102 153 255
14 -14 19 102 153 255
-13 -13 19 102 153 255
14 -13 19 102 153 255
15 -13 19 102 153 255
-14 -12 19 102 153 255
-13 -12 19 102 153 255
15 -12 19 102 153 255
16 -12 19 102 153 255
-14 -11 19 102 153 255
16 -11 19 102 153 255
-15 -10 19 102 153 255
17 -10 19 102 153 255
-15 -9 19 102 153 255
17 -9 19 102 153 255
-16 -8 19 102 153 255
18 -8 19 102 153 255
-16 -7 19 102 153 255
18 -7 19 102 153 255
-17 -6 19 102 153 255
-16 -6 19 102 153 255
18 -6 19 102 153 255
-17 -5 19 102 153 255
18 -5 19 102 153 255
19 -5 19 102 153 255
-17 -4 19 102 153 255
19 -4 19 102 153 255
-17 -3 19 102 153 255
19 -3 19 102 153 255
-17 -2 19 102 153 255
19 -2 19 102 153 255
-17 -1 19 102 153 255
19 -1 19 102 153 255
-17 0 19 102 153 255
19 0 19 102 153 255
-17 1 19 102 153 255
19 1 19 102 153 255
-17 2 19 102 153 255
19 2 19 102 153 255
-17 3 19 102 153 255
18 3 19 102 153 255
-16 4 19 102 153 255
18 4 19 102 153 255
-16 5 19 102 153 255
18 5 19 102 153 255
-16 6 19 102 153 255
17 6 19 102 153 255
18 6 19 102 153 255
-15 7 19 102 153 255
17 7 19 102 153 255
-15 8 19 102 153 255
16 8 19 102 153 255
17 8 19 102 153 255
-14 9 19 102 153 255
16 9 19 102 153 255
-14 10 19 102 153 255
-13 10 19 102 153 255
15 10 19 102 153 255
-13 11 19 102 153 255
-12 11 19 102 153 255
14 11 19 102 153 255
-12 12 19 102 153 255
-11 12 19 102 153 255
13 12 19 102 153 255
14 12 19 102 153 255
-11 13 19 102 153 255
-10 13 19 102 153 255
12 13 19 102 153 255
-9 14 19 102 153 255
-8 14 19 102 153 255
10 14 19 102 153 255
11 14 19 102 153 255
-8 15 19 102 153 255
-7 15 19 102 153 255
-6 15 19 102 153 255
8 15 19 102 153 255
9 15 19 102 153 255
10 15 19 102 153 255
-6 16 19 102 153 255
-5 16 19 102 153 255
-4 16 19 102 153 255
-3 16 19 102 153 255
5 16 19 102 153 255
6 16 19 102 153 255
7 16 19 102 153 255
-2 17 19 102 153 255
-1 17 19 102 153 255
0 17 19 102 153 255
1 17 19 102 153 255
2 17 19 102 153 255
3 17 19 102 153 255
4 17 19 102 153 255
-2 -20 20 102 153 255
-1 -20 20 102 153 255
0 -20 20 102 153 255
1 -20 20 102 153 255
2 -20 20 102 153 255
3 -20 20 102 153 255
4 -20 20 102 153 255
-6 -19 20 102 153 255
-5 -19 20 102 153 255
-4 -19 20 102 153 255
5 -19 20 102 153 255
6 -19 20 102 153 255
7 -19 20 102 153 255
8 -19 20 102 153 255
-8 -18 20 102 153 255
-7 -18 20 102 153 255
9 -18 20 102 153 255
10 -18 20 102 153 255
-10 -17 20 102 153 255
-9 -17 20 102 153 255
10 -17 20 102 153 255
11 -17 20 102 153 255
-11 -16 20 102 153 255
-10 -16 20 102 153 255
12 -16 20 102 153 255
13 -16 20 102 153 255
-12 -15 20 102 153 255
13 -15 20 102 153 255
14 -15 20 102 153 255
-13 -14 20 102 153 255
14 -14 20 102 153 255
15 -14 20 102 153 255
-14 -13 20 102 153 255
15 -13 20 102 153 255
16 -13 20 102 153 255
-15 -12 20 102 153 255
-14 -12 20 102 153 255
16 -12 20 102 153 255
-15 -11 20 102 153 255
17 -11 20 102 153 255
-16 -10 20 102 153 255
17 -10 20 102 153 255
-16 -9 20 102 153 255
18 -9 20 102 153 255
-17 -8 20 102 153 255
18 -8 20 102 153 255
-17 -7 20 102 153 255
19 -7 20 102 153 255
-17 -6 20 102 153 255
19 -6 20 102 153 255
-17 -5 20 102 153 255
19 -5 20 102 153 255
-18 -4 20 102 153 255
19 -4 20 102 153 255
-18 -3 20 102 153 255
-18 -2 20 102 153 255
-16 -2 20 102 153 255
-18 -1 20 102 153 255
-16 -1 20 102 153 255
-18 0 20 102 153 255
-16 0 20 102 153 255
-18 1 20 102 153 255
-18 2 20 102 153 255
19 2 20 102 153 255
-17 3 20 102 153 255
19 3 20 102 153 255
-17 4 20 102 153 255
19 4 20 102 153 255
-17 5 20 102 153 255
19 5 20 102 153 255
-16 6 20 102 153 255
18 6 20 102 153 255
-16 7 20 102 153 255
18 7 20 102 153 255
-16 8 20 102 153 255
-15 8 20 102 153 255
17 8 20 102 153 255
-15 9 20 102 153 255
17 9 20 102 153 255
-14 10 20 102 153 255
16 10 20 102 153 255
-14 11 20 102 153 255
-13 11 20 102 153 255
15 11 20 102 153 255
-13 12 20 102 153 255
-12 12 20 102 153 255
14 12 20 102 153 255
-12 13 20 102 153 255
-11 13 20 102 153 255
13 13 20 102 153 255
-11 14 20 102 153 255
-10 14 20 102 153 255
12 14 20 102 153 255
-9 15 20 102 153 255
-8 15 20 102 153 255
10 15 20 102 153 255
11 15 20 102 153 255
-7 16 20 102 153 255
-6 16 20 102 153 255
8 16 20 102 153 255
9 16 20 102 153 255
-5 17 20 102 153 255
-4 17 20 102 153 255
-3 17 20 102 153 255
-2 17 20 102 153 255
3 17 20 102 153 255
4 17 20 102 153 255
5 17 20 102 153 255
6 17 20 102 153 255
7 17 20 102 153 255
-4 -20 21 102 153 255
-3 -20 21 102 153 255
-2 -20 21 102 153 255
-1 -20 21 102 153 255
0 -20 21 102 153 255
1 -20 21 102 153 255
2 -20 21 102 153 255
3 -20 21 102 153 255
4 -20 21 102 153 255
5 -20 21 102 153 255
6 -20 21 102 153 255
-7 -19 21 102 153 255
-6 -19 21 102 153 255
7 -19 21 102 153 255
8 -19 21 102 153 255
9 -19 21 102 153 255
-9 -18 21 102 153 255
-8 -18 21 102 153 255
10 -18 21 102 153 255
11 -18 21 102 153 255
-10 -17 21 102 153 255
12 -17 21 102 153 255
-12 -16 21 102 153 255
-11 -16 21 102 153 255
13 -16 21 102 153 255
-13 -15 21 102 153 255
-12 -15 21 102 153 255
14 -15 21 102 153 255
-14 -14 21 102 153 255
-13 -14 21 102 153 255
15 -14 21 102 153 255
-14 -13 21 102 153 255
16 -13 21 102 153 255
-15 -12 21 102 153 255
17 -12 21 102 153 255
-16 -11 21 102 153 255
17 -11 21 102 153 255
-16 -10 21 102 153 255
18 -10 21 102 153 255
-17 -9 21 102 153 255
18 -9 21 102 153 255
-17 -8 21 102 153 255
19 -8 21 102 153 255
19 -7 21 102 153 255
-18 -6 21 102 153 255
-18 -5 21 102 153 255
20 -5 21 102 153 255
-18 -4 21 102 153 255
-17 -4 21 102 153 255
-16 -4 21 102 153 255
20 -4 21 102 153 255
-19 -3 21 102 153 255
-18 -3 21 102 153 255
-17 -3 21 102 153 255
20 -3 21 102 153 255
21 -3 21 102 153 255
-19 -2 21 102 153 255
-18 -2 21 102 153 255
20 -2 21 102 153 255
21 -2 21 102 153 255
-19 -1 21 102 153 255
-18 -1 21 102 153 255
20 -1 21 102 153 255
21 -1 21 102 153 255
22 -1 21 102 153 255
-19 0 21 102 153 255
-18 0 21 102 153 255
20 0 21 102 153 255
21 0 21 102 153 255
-19 1 21 102 153 255
-18 1 21 102 153 255
-17 1 21 102 153 255
20 1 21 102 153 255
-18 2 21 102 153 255
-17 2 21 102 153 255
-16 2 21 102 153 255
20 2 21 102 153 255
-18 3 21 102 153 255
20 3 21 102 153 255
-18 4 21 102 153 255
19 4 21 102 153 255
-17 5 21 102 153 255
19 5 21 102 153 255
-17 6 21 102 153 255
19 6 21 102 153 255
-17 7 21 102 153 255
18 7 21 102 153 255
-16 8 21 102 153 255
18 8 21 102 153 255
-15 9 21 102 153 255
17 9 21 102 153 255
-15 10 21 102 153 255
17 10 21 102 153 255
-14 11 21 102 153 255
16 11 21 102 153 255
-13 12 21 102 153 255
15 12 21 102 153 255
-12 13 21 102 153 255
14 13 21 102 153 255
-11 14 21 102 153 255
12 14 21 102 153 255
13 14 21 102 153 255
-10 15 21 102 153 255
-9 15 21 102 153 255
11 15 21 102 153 255
12 15 21 102 153 255
-8 16 21 102 153 255
-7 16 21 102 153 255
9 16 21 102 153 255
10 16 21 102 153 255
-6 17 21 102 153 255
-5 17 21 102 153 255
-4 17 21 102 153 255
6 17 21 102 153 255
7 17 21 102 153 255
8 17 21 102 153 255
-3 18 21 102 153 255
-2 18 21 102 153 255
-1 18 21 102 153 255
0 18 21 102 153 255
1 18 21 102 153 255
2 18 21 102 153 255
3 18 21 102 153 255
4 18 21 102 153 255
-5 -20 22 102 153 255
-4 -20 22 102 153 255
-3 -20 22 102 153 255
5 -20 22 102 153 255
6 -20 22 102 153 255
7 -20 22 102 153 255
-7 -19 22 102 153 255
8 -19 22 102 153 255
9 -19 22 102 153 255
-9 -18 22 102 153 255
10 -18 22 102 153 255
11 -18 22 102 153 255
-11 -17 22 102 153 255
-10 -17 22 102 153 255
12 -17 22 102 153 255
-12 -16 22 102 153 255
13 -16 22 102 153 255
14 -16 22 102 153 255
-13 -15 22 102 153 255
15 -15 22 102 153 255
-14 -14 22 102 153 255
16 -14 22 102 153 255
-15 -13 22 102 153 255
16 -13 22 102 153 255
-15 -12 22 102 153 255
17 -12 22 102 153 255
-16 -11 22 102 153 255
18 -11 22 102 153 255
18 -10 22 102 153 255
-17 -9 22 102 153 255
19 -9 22 102 153 255
-17 -8 22 102 153 255
19 -8 22 102 153 255
-18 -7 22 102 153 255
-18 -6 22 102 153 255
20 -6 22 102 153 255
-19 -5 22 102 153 255
-18 -5 22 102 153 255
-17 -5 22 102 153 255
-16 -5 22 102 153 255
20 -5 22 102 153 255
-20 -4 22 102 153 255
-19 -4 22 102 153 255
20 -4 22 102 153 255
-21 -3 22 102 153 255
-20 -3 22 102 153 255
20 -3 22 102 153 255
21 -3 22 102 153 255
22 -3 22 102 153 255
23 -3 22 102 153 255
-21 -2 22 102 153 255
20 -2 22 102 153 255
23 -2 22 102 153 255
-21 -1 22 102 153 255
23 -1 22 102 153 255
-21 0 22 102 153 255
20 0 22 102 153 255
22 0 22 102 153 255
23 0 22 102 153 255
-21 1 22 102 153 255
-20 1 22 102 153 255
20 1 22 102 153 255
21 1 22 102 153 255
22 1 22 102 153 255
-20 2 22 102 153 255
-19 2 22 102 153 255
-18 2 22 102 153 255
20 2 22 102 153 255
-18 3 22 102 153 255
-17 3 22 102 153 255
-16 3 22 102 153 255
20 3 22 102 153 255
-18 4 22 102 153 255
20 4 22 102 153 255
-18 5 22 102 153 255
19 5 22 102 153 255
-17 6 22 102 153 255
19 6 22 102 153 255
-17 7 22 102 153 255
19 7 22 102 153 255
-16 8 22 102 153 255
18 8 22 102 153 255
-16 9 22 102 153 255
-15 10 22 102 153 255
17 10 22 102 153 255
-14 11 22 102 153 255
16 11 22 102 153 255
-14 12 22 102 153 255
15 12 22 102 153 255
-13 13 22 102 153 255
-12 13 22 102 153 255
14 13 22 102 153 255
-12 14 22 102 153 255
-11 14 22 102 153 255
13 14 22 102 153 255
-10 15 22 102 153 255
12 15 22 102 153 255
-9 16 22 102 153 255
-8 16 22 102 153 255
10 16 22 102 153 255
-7 17 22 102 153 255
-6 17 22 102 153 255
7 17 22 102 153 255
8 17 22 102 153 255
-4 18 22 102 153 255
-3 18 22 102 153 255
-2 18 22 102 153 255
-1 18 22 102 153 255
0 18 22 102 153 255
1 18 22 102 153 255
2 18 22 102 153 255
3 18 22 102 153 255
4 18 22 102 153 255
5 18 22 102 153 255
-5 -20 23 102 153 255
-4 -20 23 102 153 255
5 -20 23 102 153 255
6 -20 23 102 153 255
7 -20 23 102 153 255
-8 -19 23 102 153 255
-7 -19 23 102 153 255
9 -19 23 102 153 255
-9 -18 23 102 153 255
11 -18 23 102 153 255
-11 -17 23 102 153 255
12 -17 23 102 153 255
13 -17 23 102 153 255
-12 -16 23 102 153 255
14 -16 23 102 153 255
-13 -15 23 102 153 255
15 -15 23 102 153 255
-14 -14 23 102 153 255
16 -14 23 102 153 255
-15 -13 23 102 153 255
17 -12 23 102 153 255
-16 -11 23 102 153 255
18 -11 23 102 153 255
-17 -10 23 102 153 255
-17 -9 23 102 153 255
19 -9 23 102 153 255
19 -8 23 102 153 255
-18 -7 23 102 153 255
-18 -6 23 102 153 255
-17 -6 23 102 153 255
-16 -6 23 102 153 255
20 -6 23 102 153 255
-21 -5 23 102 153 255
-20 -5 23 102 153 255
-19 -5 23 102 153 255
20 -5 23 102 153 255
-22 -4 23 102 153 255
-21 -4 23 102 153 255
20 -4 23 102 153 255
-22 -3 23 102 153 255
21 -3 23 102 153 255
22 -3 23 102 153 255
23 -3 23 102 153 255
24 -3 23 102 153 255
-22 -2 23 102 153 255
21 -2 23 102 153 255
24 -2 23 102 153 255
25 -2 23 102 153 255
-22 -1 23 102 153 255
21 -1 23 102 153 255
24 -1 23 102 153 255
25 -1 23 102 153 255
-22 0 23 102 153 255
21 0 23 102 153 255
24 0 23 102 153 255
25 0 23 102 153 255
-22 1 23 102 153 255
21 1 23 102 153 255
22 1 23 102 153 255
23 1 23 102 153 255
24 1 23 102 153 255
-21 2 23 102 153 255
20 2 23 102 153 255
-20 3 23 102 153 255
-19 3 23 102 153 255
-18 3 23 102 153 255
-17 3 23 102 153 255
20 3 23 102 153 255
-18 4 23 102 153 255
20 4 23 102 153 255
-18 5 23 102 153 255
19 6 23 102 153 255
-17 7 23 102 153 255
19 7 23 102 153 255
18 8 23 102 153 255
-16 9 23 102 153 255
18 9 23 102 153 255
-15 10 23 102 153 255
17 10 23 102 153 255
16 11 23 102 153 255
-14 12 23 102 153 255
15 12 23 102 153 255
-13 13 23 102 153 255
14 13 23 102 153 255
15 13 23 102 153 255
-12 14 23 102 153 255
13 14 23 102 153 255
-10 15 23 102 153 255
12 15 23 102 153 255
-9 16 23 102 153 255
-8 16 23 102 153 255
10 16 23 102 153 255
11 16 23 102 153 255
-7 17 23 102 153 255
-6 17 23 102 153 255
8 17 23 102 153 255
9 17 23 102 153 255
-4 18 23 102 153 255
-3 18 23 102 153 255
-2 18 23 102 153 255
3 18 23 102 153 255
4 18 23 102 153 255
5 18 23 102 153 255
6 18 23 102 153 255
-5 -20 24 102 153 255
-4 -20 24 102 153 255
5 -20 24 102 153 255
6 -20 24 102 153 255
7 -20 24 102 153 255
-8 -19 24 102 153 255
-7 -19 24 102 153 255
9 -19 24 102 153 255
-9 -18 24 102 153 255
11 -18 24 102 153 255
-11 -17 24 102 153 255
12 -17 24 102 153 255
13 -17 24 102 153 255
-12 -16 24 102 153 255
14 -16 24 102 153 255
-13 -15 24 102 153 255
15 -15 24 102 153 255
-14 -14 24 102 153 255
16 -14 24 102 153 255
-15 -13 24 102 153 255
17 -12 24 102 153 255
-16 -11 24 102 153 255
18 -11 24 102 153 255
18 -10 24 102 153 255
-17 -9 24 102 153 255
19 -9 24 102 153 255
19 -8 24 102 153 255
-18 -7 24 102 153 255
-19 -6 24 102 153 255
-18 -6 24 102 153 255
-17 -6 24 102 153 255
-16 -6 24 102 153 255
20 -6 24 102 153 255
-22 -5 24 102 153 255
-21 -5 24 102 153 255
-18 -5 24 102 153 255
20 -5 24 102 153 255
-23 -4 24 102 153 255
-22 -4 24 102 153 255
20 -4 24 102 153 255
-23 -3 24 102 153 255
23 -3 24 102 153 255
24 -3 24 102 153 255
25 -3 24 102 153 255
-23 -2 24 102 153 255
22 -2 24 102 153 255
23 -2 24 102 153 255
26 -2 24 102 153 255
-23 -1 24 102 153 255
22 -1 24 102 153 255
26 -1 24 102 153 255
-23 0 24 102 153 255
22 0 24 102 153 255
23 0 24 102 153 255
25 0 24 102 153 255
26 0 24 102 153 255
-23 1 24 102 153 255
20 1 24 102 153 255
23 1 24 102 153 255
24 1 24 102 153 255
25 1 24 102 153 255
-22 2 24 102 153 255
20 2 24 102 153 255
-21 3 24 102 153 255
-20 3 24 102 153 255
-18 3 24 102 153 255
20 3 24 102 153 255
-18 4 24 102 153 255
20 4 24 102 153 255
-18 5 24 102 153 255
-17 6 24 102 153 255
19 6 24 102 153 255
-17 7 24 102 153 255
19 7 24 102 153 255
18 8 24 102 153 255
-16 9 24 102 153 255
18 9 24 102 153 255
-15 10 24 102 153 255
17 10 24 102 153 255
16 11 24 102 153 255
-14 12 24 102 153 255
15 12 24 102 153 255
-13 13 24 102 153 255
14 13 24 102 153 255
-12 14 24 102 153 255
-11 14 24 102 153 255
13 14 24 102 153 255
-10 15 24 102 153 255
12 15 24 102 153 255
-9 16 24 102 153 255
-8 16 24 102 153 255
10 16 24 102 153 255
11 16 24 102 153 255
-7 17 24 102 153 255
-6 17 24 102 153 255
8 17 24 102 153 255
9 17 24 102 153 255
-4 18 24 102 153 255
-3 18 24 102 153 255
-2 18 24 102 153 255
-1 18 24 102 153 255
3 18 24 102 153 255
4 18 24 102 153 255
5 18 24 102 153 255
6 18 24 102 153 255
-5 -20 25 102 153 255
-4 -20 25 102 153 255
-3 -20 25 102 153 255
5 -20 25 102 153 255
6 -20 25 102 153 255
7 -20 25 102 153 255
-7 -19 25 102 153 255
-6 -19 25 102 153 255
8 -19 25 102 153 255
9 -19 25 102 153 255
-9 -18 25 102 153 255
10 -18 25 102 153 255
11 -18 25 102 153 255
-11 -17 25 102 153 255
-10 -17 25 102 153 255
12 -17 25 102 153 255
-12 -16 25 102 153 255
13 -16 25 102 153 255
14 -16 25 102 153 255
-13 -15 25 102 153 255
15 -15 25 102 153 255
-14 -14 25 102 153 255
16 -14 25 102 153 255
-15 -13 25 102 153 255
16 -13 25 102 153 255
-15 -12 25 102 153 255
17 -12 25 102 153 255
-16 -11 25 102 153 255
18 -11 25 102 153 255
18 -10 25 102 153 255
-17 -9 25 102 153 255
19 -9 25 102 153 255
-17 -8 25 102 153 255
19 -8 25 102 153 255
-18 -7 25 102 153 255
-20 -6 25 102 153 255
-19 -6 25 102 153 255
-18 -6 25 102 153 255
-17 -6 25 102 153 255
-16 -6 25 102 153 255
20 -6 25 102 153 255
-23 -5 25 102 153 255
-22 -5 25 102 153 255
-18 -5 25 102 153 255
20 -5 25 102 153 255
-23 -4 25 102 153 255
20 -4 25 102 153 255
-24 -3 25 102 153 255
20 -3 25 102 153 255
24 -3 25 102 153 255
25 -3 25 102 153 255
26 -3 25 102 153 255
27 -3 25 102 153 255
-24 -2 25 102 153 255
20 -2 25 102 153 255
24 -2 25 102 153 255
27 -2 25 102 153 255
-24 -1 25 102 153 255
23 -1 25 102 153 255
24 -1 25 102 153 255
27 -1 25 102 153 255
-24 0 25 102 153 255
20 0 25 102 153 255
24 0 25 102 153 255
27 0 25 102 153 255
-24 1 25 102 153 255
20 1 25 102 153 255
24 1 25 102 153 255
25 1 25 102 153 255
26 1 25 102 153 255
-23 2 25 102 153 255
-18 2 25 102 153 255
20 2 25 102 153 255
-22 3 25 102 153 255
-21 3 25 102 153 255
-18 3 25 102 153 255
20 3 25 102 153 255
-18 4 25 102 153 255
19 5 25 102 153 255
-17 6 25 102 153 255
19 6 25 102 153 255
-17 7 25 102 153 255
-16 8 25 102 153 255
18 8 25 102 153 255
-16 9 25 102 153 255
-15 10 25 102 153 255
17 10 25 102 153 255
-14 11 25 102 153 255
16 11 25 102 153 255
-14 12 25 102 153 255
-13 12 25 102 153 255
15 12 25 102 153 255
-13 13 25 102 153 255
-12 13 25 102 153 255
14 13 25 102 153 255
-12 14 25 102 153 255
-11 14 25 102 153 255
13 14 25 102 153 255
-10 15 25 102 153 255
12 15 25 102 153 255
-9 16 25 102 153 255
-8 16 25 102 153 255
10 16 25 102 153 255
-7 17 25 102 153 255
-6 17 25 102 153 255
7 17 25 102 153 255
8 17 25 102 153 255
-4 18 25 102 153 255
-3 18 25 102 153 255
-2 18 25 102 153 255
-1 18 25 102 153 255
0 18 25 102 153 255
1 18 25 102 153 255
2 18 25 102 153 255
3 18 25 102 153 255
4 18 25 102 153 255
5 18 25 102 153 255
-4 -20 26 102 153 255
-3 -20 26 102 153 255
-2 -20 26 102 153 255
3 -20 26 102 153 255
4 -20 26 102 153 255
5 -20 26 102 153 255
6 -20 26 102 153 255
-7 -19 26 102 153 255
-6 -19 26 102 153 255
8 -19 26 102 153 255
9 -19 26 102 153 255
-9 -18 26 102 153 255
-8 -18 26 102 153 255
10 -18 26 102 153 255
11 -18 26 102 153 255
-10 -17 26 102 153 255
12 -17 26 102 153 255
-12 -16 26 102 153 255
-11 -16 26 102 153 255
13 -16 26 102 153 255
-13 -15 26 102 153 255
14 -15 26 102 153 255
-14 -14 26 102 153 255
15 -14 26 102 153 255
-14 -13 26 102 153 255
16 -13 26 102 153 255
-15 -12 26 102 153 255
17 -12 26 102 153 255
-16 -11 26 102 153 255
-16 -10 26 102 153 255
18 -10 26 102 153 255
-17 -9 26 102 153 255
-17 -8 26 102 153 255
19 -8 26 102 153 255
19 -7 26 102 153 255
-20 -6 26 102 153 255
-19 -6 26 102 153 255
-18 -6 26 102 153 255
-23 -5 26 102 153 255
-18 -5 26 102 153 255
20 -5 26 102 153 255
-24 -4 26 102 153 255
-18 -4 26 102 153 255
20 -4 26 102 153 255
-24 -3 26 102 153 255
-18 -3 26 102 153 255
20 -3 26 102 153 255
25 -3 26 102 153 255
26 -3 26 102 153 255
27 -3 26 102 153 255
20 -2 26 102 153 255
25 -2 26 102 153 255
28 -2 26 102 153 255
20 -1 26 102 153 255
25 -1 26 102 153 255
28 -1 26 102 153 255
20 0 26 102 153 255
25 0 26 102 153 255
28 0 26 102 153 255
-24 1 26 102 153 255
-18 1 26 102 153 255
20 1 26 102 153 255
25 1 26 102 153 255
26 1 26 102 153 255
27 1 26 102 153 255
-24 2 26 102 153 255
-18 2 26 102 153 255
20 2 26 102 153 255
-23 3 26 102 153 255
-22 3 26 102 153 255
-21 3 26 102 153 255
-19 3 26 102 153 255
-18 3 26 102 153 255
-17 3 26 102 153 255
-16 3 26 102 153 255
20 3 26 102 153 255
-18 4 26 102 153 255
19 5 26 102 153 255
-17 6 26 102 153 255
19 6 26 102 153 255
-17 7 26 102 153 255
18 7 26 102 153 255
-16 8 26 102 153 255
18 8 26 102 153 255
-16 9 26 102 153 255
17 9 26 102 153 255
-15 10 26 102 153 255
17 10 26 102 153 255
-14 11 26 102 153 255
16 11 26 102 153 255
-13 12 26 102 153 255
15 12 26 102 153 255
-12 13 26 102 153 255
14 13 26 102 153 255
-11 14 26 102 153 255
13 14 26 102 153 255
-10 15 26 102 153 255
-9 15 26 102 153 255
11 15 26 102 153 255
12 15 26 102 153 255
-8 16 26 102 153 255
9 16 26 102 153 255
10 16 26 102 153 255
-6 17 26 102 153 255
-5 17 26 102 153 255
7 17 26 102 153 255
8 17 26 102 153 255
-3 18 26 102 153 255
-2 18 26 102 153 255
-1 18 26 102 153 255
0 18 26 102 153 255
1 18 26 102 153 255
2 18 26 102 153 255
3 18 26 102 153 255
4 18 26 102 153 255
5 18 26 102 153 255
-3 -20 27 102 153 255
-2 -20 27 102 153 255
-1 -20 27 102 153 255
0 -20 27 102 153 255
1 -20 27 102 153 255
2 -20 27 102 153 255
3 -20 27 102 153 255
4 -20 27 102 153 255
5 -20 27 102 153 255
-6 -19 27 102 153 255
-5 -19 27 102 153 255
7 -19 27 102 153 255
8 -19 27 102 153 255
-8 -18 27 102 153 255
9 -18 27 102 153 255
10 -18 27 102 153 255
-10 -17 27 102 153 255
11 -17 27 102 153 255
12 -17 27 102 153 255
-11 -16 27 102 153 255
13 -16 27 102 153 255
-12 -15 27 102 153 255
14 -15 27 102 153 255
-13 -14 27 102 153 255
15 -14 27 102 153 255
-14 -13 27 102 153 255
16 -13 27 102 153 255
-15 -12 27 102 153 255
17 -12 27 102 153 255
17 -11 27 102 153 255
-16 -10 27 102 153 255
18 -10 27 102 153 255
18 -9 27 102 153 255
-17 -8 27 102 153 255
19 -8 27 102 153 255
-17 -7 27 102 153 255
19 -7 27 102 153 255
19 -6 27 102 153 255
-23 -5 27 102 153 255
-20 -5 27 102 153 255
-19 -5 27 102 153 255
-18 -5 27 102 153 255
-17 -5 27 102 153 255
-16 -5 27 102 153 255
-24 -4 27 102 153 255
-18 -4 27 102 153 255
20 -4 27 102 153 255
-25 -3 27 102 153 255
-18 -3 27 102 153 255
20 -3 27 102 153 255
26 -3 27 102 153 255
28 -3 27 102 153 255
-25 -2 27 102 153 255
-18 -2 27 102 153 255
20 -2 27 102 153 255
25 -2 27 102 153 255
26 -2 27 102 153 255
29 -2 27 102 153 255
-25 -1 27 102 153 255
-18 -1 27 102 153 255
20 -1 27 102 153 255
25 -1 27 102 153 255
29 -1 27 102 153 255
-25 0 27 102 153 255
-18 0 27 102 153 255
20 0 27 102 153 255
26 0 27 102 153 255
28 0 27 102 153 255
-25 1 27 102 153 255
-18 1 27 102 153 255
20 1 27 102 153 255
26 1 27 102 153 255
27 1 27 102 153 255
28 1 27 102 153 255
-24 2 27 102 153 255
-18 2 27 102 153 255
-17 2 27 102 153 255
-16 2 27 102 153 255
-23 3 27 102 153 255
-22 3 27 102 153 255
-21 3 27 102 153 255
-20 3 27 102 153 255
-19 3 27 102 153 255
-18 3 27 102 153 255
19 4 27 102 153 255
-17 5 27 102 153 255
19 5 27 102 153 255
-17 6 27 102 153 255
-16 7 27 102 153 255
18 7 27 102 153 255
-16 8 27 102 153 255
18 8 27 102 153 255
-15 9 27 102 153 255
17 9 27 102 153 255
-15 10 27 102 153 255
16 10 27 102 153 255
-14 11 27 102 153 255
16 11 27 102 153 255
-13 12 27 102 153 255
15 12 27 102 153 255
-12 13 27 102 153 255
14 13 27 102 153 255
-11 14 27 102 153 255
12 14 27 102 153 255
13 14 27 102 153 255
-10 15 27 102 153 255
-9 15 27 102 153 255
11 15 27 102 153 255
-8 16 27 102 153 255
-7 16 27 102 153 255
9 16 27 102 153 255
10 16 27 102 153 255
-6 17 27 102 153 255
-5 17 27 102 153 255
-4 17 27 102 153 255
6 17 27 102 153 255
7 17 27 102 153 255
-1 18 27 102 153 255
0 18 27 102 153 255
1 18 27 102 153 255
2 18 27 102 153 255
3 18 27 102 153 255
-2 -20 28 102 153 255
-1 -20 28 102 153 255
0 -20 28 102 153 255
1 -20 28 102 153 255
2 -20 28 102 153 255
3 -20 28 102 153 255
4 -20 28 102 153 255
-6 -19 28 102 153 255
-5 -19 28 102 153 255
-4 -19 28 102 153 255
6 -19 28 102 153 255
7 -19 28 102 153 255
-8 -18 28 102 153 255
-7 -18 28 102 153 255
9 -18 28 102 153 255
10 -18 28 102 153 255
-10 -17 28 102 153 255
-9 -17 28 102 153 255
11 -17 28 102 153 255
-11 -16 28 102 153 255
12 -16 28 102 153 255
13 -16 28 102 153 255
-12 -15 28 102 153 255
13 -15 28 102 153 255
14 -15 28 102 153 255
-13 -14 28 102 153 255
15 -14 28 102 153 255
-14 -13 28 102 153 255
15 -13 28 102 153 255
16 -13 28 102 153 255
-15 -12 28 102 153 255
-14 -12 28 102 153 255
16 -12 28 102 153 255
-15 -11 28 102 153 255
17 -11 28 102 153 255
-16 -10 28 102 153 255
-16 -9 28 102 153 255
18 -9 28 102 153 255
-17 -8 28 102 153 255
18 -8 28 102 153 255
-17 -7 28 102 153 255
19 -7 28 102 153 255
-17 -6 28 102 153 255
19 -6 28 102 153 255
-24 -5 28 102 153 255
-23 -5 28 102 153 255
-22 -5 28 102 153 255
-21 -5 28 102 153 255
-20 -5 28 102 153 255
19 -5 28 102 153 255
-25 -4 28 102 153 255
-20 -4 28 102 153 255
-19 -4 28 102 153 255
-18 -4 28 102 153 255
-25 -3 28 102 153 255
-19 -3 28 102 153 255
-18 -3 28 102 153 255
-17 -3 28 102 153 255
-16 -3 28 102 153 255
27 -3 28 102 153 255
28 -3 28 102 153 255
29 -3 28 102 153 255
-25 -2 28 102 153 255
-18 -2 28 102 153 255
-17 -2 28 102 153 255
-16 -2 28 102 153 255
26 -2 28 102 153 255
29 -2 28 102 153 255
-25 -1 28 102 153 255
-18 -1 28 102 153 255
-17 -1 28 102 153 255
-16 -1 28 102 153 255
26 -1 28 102 153 255
29 -1 28 102 153 255
-25 0 28 102 153 255
-18 0 28 102 153 255
-17 0 28 102 153 255
-16 0 28 102 153 255
26 0 28 102 153 255
29 0 28 102 153 255
-25 1 28 102 153 255
-19 1 28 102 153 255
-18 1 28 102 153 255
-17 1 28 102 153 255
-16 1 28 102 153 255
27 1 28 102 153 255
28 1 28 102 153 255
-24 2 28 102 153 255
-21 2 28 102 153 255
-20 2 28 102 153 255
-19 2 28 102 153 255
-23 3 28 102 153 255
-22 3 28 102 153 255
19 3 28 102 153 255
-17 4 28 102 153 255
19 4 28 102 153 255
-17 5 28 102 153 255
19 5 28 102 153 255
18 6 28 102 153 255
-16 7 28 102 153 255
18 7 28 102 153 255
-16 8 28 102 153 255
17 8 28 102 153 255
-15 9 28 102 153 255
17 9 28 102 153 255
-14 10 28 102 153 255
16 10 28 102 153 255
-14 11 28 102 153 255
-13 11 28 102 153 255
15 11 28 102 153 255
-13 12 28 102 153 255
-12 12 28 102 153 255
14 12 28 102 153 255
-12 13 28 102 153 255
-11 13 28 102 153 255
13 13 28 102 153 255
-10 14 28 102 153 255
12 14 28 102 153 255
-9 15 28 102 153 255
-8 15 28 102 153 255
10 15 28 102 153 255
11 15 28 102 153 255
-7 16 28 102 153 255
-6 16 28 102 153 255
8 16 28 102 153 255
9 16 28 102 153 255
-5 17 28 102 153 255
-4 17 28 102 153 255
-3 17 28 102 153 255
4 17 28 102 153 255
5 17 28 102 153 255
6 17 28 102 153 255
7 17 28 102 153 255
-5 -19 29 102 153 255
-4 -19 29 102 153 255
-3 -19 29 102 153 255
4 -19 29 102 153 255
5 -19 29 102 153 255
6 -19 29 102 153 255
7 -19 29 102 153 255
-7 -18 29 102 153 255
-6 -18 29 102 153 255
8 -18 29 102 153 255
9 -18 29 102 153 255
-9 -17 29 102 153 255
-8 -17 29 102 153 255
10 -17 29 102 153 255
11 -17 29 102 153 255
-10 -16 29 102 153 255
12 -16 29 102 153 255
-12 -15 29 102 153 255
-11 -15 29 102 153 255
13 -15 29 102 153 255
-13 -14 29 102 153 255
-12 -14 29 102 153 255
14 -14 29 102 153 255
-13 -13 29 102 153 255
15 -13 29 102 153 255
-14 -12 29 102 153 255
16 -12 29 102 153 255
-15 -11 29 102 153 255
17 -11 29 102 153 255
-15 -10 29 102 153 255
17 -10 29 102 153 255
-16 -9 29 102 153 255
18 -9 29 102 153 255
-16 -8 29 102 153 255
18 -8 29 102 153 255
-17 -7 29 102 153 255
18 -7 29 102 153 255
-17 -6 29 102 153 255
19 -6 29 102 153 255
-24 -5 29 102 153 255
-23 -5 29 102 153 255
-22 -5 29 102 153 255
-17 -5 29 102 153 255
19 -5 29 102 153 255
-25 -4 29 102 153 255
-22 -4 29 102 153 255
-21 -4 29 102 153 255
-17 -4 29 102 153 255
19 -4 29 102 153 255
-25 -3 29 102 153 255
-21 -3 29 102 153 255
-20 -3 29 102 153 255
19 -3 29 102 153 255
27 -3 29 102 153 255
29 -3 29 102 153 255
-20 -2 29 102 153 255
19 -2 29 102 153 255
27 -2 29 102 153 255
30 -2 29 102 153 255
-20 -1 29 102 153 255
19 -1 29 102 153 255
30 -1 29 102 153 255
-20 0 29 102 153 255
19 0 29 102 153 255
27 0 29 102 153 255
-25 1 29 102 153 255
-21 1 29 102 153 255
-20 1 29 102 153 255
19 1 29 102 153 255
27 1 29 102 153 255
28 1 29 102 153 255
29 1 29 102 153 255
-24 2 29 102 153 255
-22 2 29 102 153 255
-21 2 29 102 153 255
-17 2 29 102 153 255
19 2 29 102 153 255
-17 3 29 102 153 255
19 3 29 102 153 255
-17 4 29 102 153 255
18 5 29 102 153 255
-16 6 29 102 153 255
18 6 29 102 153 255
-16 7 29 102 153 255
17 7 29 102 153 255
-15 8 29 102 153 255
17 8 29 102 153 255
-15 9 29 102 153 255
16 9 29 102 153 255
-14 10 29 102 153 255
16 10 29 102 153 255
-13 11 29 102 153 255
15 11 29 102 153 255
-12 12 29 102 153 255
14 12 29 102 153 255
-11 13 29 102 153 255
13 13 29 102 153 255
-10 14 29 102 153 255
-9 14 29 102 153 255
11 14 29 102 153 255
12 14 29 102 153 255
-8 15 29 102 153 255
9 15 29 102 153 255
10 15 29 102 153 255
-7 16 29 102 153 255
-6 16 29 102 153 255
-5 16 29 102 153 255
7 16 29 102 153 255
8 16 29 102 153 255
-4 17 29 102 153 255
-3 17 29 102 153 255
-2 17 29 102 153 255
-1 17 29 102 153 255
0 17 29 102 153 255
1 17 29 102 153 255
2 17 29 102 153 255
3 17 29 102 153 255
4 17 29 102 153 255
5 17 29 102 153 255
-4 -19 30 102 153 255
-3 -19 30 102 153 255
-2 -19 30 102 153 255
-1 -19 30 102 153 255
0 -19 30 102 153 255
1 -19 30 102 153 255
2 -19 30 102 153 255
3 -19 30 102 153 255
4 -19 30 102 153 255
5 -19 30 102 153 255
-6 -18 30 102 153 255
-5 -18 30 102 153 255
7 -18 30 102 153 255
8 -18 30 102 153 255
-8 -17 30 102 153 255
9 -17 30 102 153 255
10 -17 30 102 153 255
-10 -16 30 102 153 255
-9 -16 30 102 153 255
11 -16 30 102 153 255
12 -16 30 102 153 255
-11 -15 30 102 153 255
12 -15 30 102 153 255
13 -15 30 102 153 255
-12 -14 30 102 153 255
14 -14 30 102 153 255
-13 -13 30 102 153 255
15 -13 30 102 153 255
-14 -12 30 102 153 255
15 -12 30 102 153 255
-14 -11 30 102 153 255
16 -11 30 102 153 255
-15 -10 30 102 153 255
17 -10 30 102 153 255
17 -9 30 102 153 255
-16 -8 30 102 153 255
18 -8 30 102 153 255
-16 -7 30 102 153 255
18 -7 30 102 153 255
18 -6 30 102 153 255
-17 -5 30 102 153 255
-25 -4 30 102 153 255
-23 -4 30 102 153 255
-22 -4 30 102 153 255
-17 -4 30 102 153 255
19 -4 30 102 153 255
-22 -3 30 102 153 255
-17 -3 30 102 153 255
19 -3 30 102 153 255
28 -3 30 102 153 255
29 -3 30 102 153 255
-26 -2 30 102 153 255
-21 -2 30 102 153 255
-17 -2 30 102 153 255
19 -2 30 102 153 255
27 -2 30 102 153 255
30 -2 30 102 153 255
-26 -1 30 102 153 255
-21 -1 30 102 153 255
-17 -1 30 102 153 255
19 -1 30 102 153 255
27 -1 30 102 153 255
30 -1 30 102 153 255
-26 0 30 102 153 255
-22 0 30 102 153 255
-21 0 30 102 153 255
-17 0 30 102 153 255
19 0 30 102 153 255
27 0 30 102 153 255
30 0 30 102 153 255
-25 1 30 102 153 255
-22 1 30 102 153 255
-17 1 30 102 153 255
19 1 30 102 153 255
28 1 30 102 153 255
29 1 30 102 153 255
-25 2 30 102 153 255
-24 2 30 102 153 255
-23 2 30 102 153 255
-22 2 30 102 153 255
-17 2 30 102 153 255
19 2 30 102 153 255
-17 3 30 102 153 255
18 4 30 102 153 255
-16 5 30 102 153 255
18 5 30 102 153 255
-16 6 30 102 153 255
-15 7 30 102 153 255
17 7 30 102 153 255
-15 8 30 102 153 255
17 8 30 102 153 255
-14 9 30 102 153 255
16 9 30 102 153 255
-13 10 30 102 153 255
15 10 30 102 153 255
-13 11 30 102 153 255
14 11 30 102 153 255
-12 12 30 102 153 255
-11 12 30 102 153 255
13 12 30 102 153 255
14 12 30 102 153 255
-11 13 30 102 153 255
-10 13 30 102 153 255
12 13 30 102 153 255
-9 14 30 102 153 255
11 14 30 102 153 255
-8 15 30 102 153 255
-7 15 30 102 153 255
9 15 30 102 153 255
10 15 30 102 153 255
-6 16 30 102 153 255
-5 16 30 102 153 255
-4 16 30 102 153 255
6 16 30 102 153 255
7 16 30 102 153 255
-2 17 30 102 153 255
-1 17 30 102 153 255
0 17 30 102 153 255
1 17 30 102 153 255
2 17 30 102 153 255
3 17 30 102 153 255
4 17 30 102 153 255
-2 -19 31 102 153 255
-1 -19 31 102 153 255
0 -19 31 102 153 255
1 -19 31 102 153 255
2 -19 31 102 153 255
3 -19 31 102 153 255
-5 -18 31 102 153 255
-4 -18 31 102 153 255
5 -18 31 102 153 255
6 -18 31 102 153 255
7 -18 31 102 153 255
-8 -17 31 102 153 255
-7 -17 31 102 153 255
8 -17 31 102 153 255
9 -17 31 102 153 255
-9 -16 31 102 153 255
10 -16 31 102 153 255
11 -16 31 102 153 255
-10 -15 31 102 153 255
12 -15 31 102 153 255
-12 -14 31 102 153 255
-11 -14 31 102 153 255
13 -14 31 102 153 255
-12 -13 31 102 153 255
14 -13 31 102 153 255
-13 -12 31 102 153 255
15 -12 31 102 153 255
-14 -11 31 102 153 255
16 -11 31 102 153 255
-15 -10 31 102 153 255
16 -10 31 102 153 255
-15 -9 31 102 153 255
17 -9 31 102 153 255
17 -8 31 102 153 255
-16 -7 31 102 153 255
18 -7 31 102 153 255
-16 -6 31 102 153 255
18 -6 31 102 153 255
18 -5 31 102 153 255
-25 -4 31 102 153 255
-24 -4 31 102 153 255
-23 -4 31 102 153 255
18 -4 31 102 153 255
-26 -3 31 102 153 255
-22 -3 31 102 153 255
-17 -3 31 102 153 255
28 -3 31 102 153 255
29 -3 31 102 153 255
30 -3 31 102 153 255
-26 -2 31 102 153 255
-22 -2 31 102 153 255
-17 -2 31 102 153 255
27 -2 31 102 153 255
30 -2 31 102 153 255
-26 -1 31 102 153 255
-22 -1 31 102 153 255
-17 -1 31 102 153 255
27 -1 31 102 153 255
30 -1 31 102 153 255
-26 0 31 102 153 255
-22 0 31 102 153 255
-17 0 31 102 153 255
30 0 31 102 153 255
-26 1 31 102 153 255
-23 1 31 102 153 255
-17 1 31 102 153 255
28 1 31 102 153 255
29 1 31 102 153 255
-25 2 31 102 153 255
-24 2 31 102 153 255
-23 2 31 102 153 255
18 2 31 102 153 255
-16 3 31 102 153 255
18 3 31 102 153 255
-16 4 31 102 153 255
18 4 31 102 153 255
-16 5 31 102 153 255
-15 6 31 102 153 255
17 6 31 102 153 255
-15 7 31 102 153 255
17 7 31 102 153 255
-14 8 31 102 153 255
16 8 31 102 153 255
-14 9 31 102 153 255
15 9 31 102 153 255
-13 10 31 102 153 255
15 10 31 102 153 255
-12 11 31 102 153 255
14 11 31 102 153 255
-11 12 31 102 153 255
13 12 31 102 153 255
-10 13 31 102 153 255
11 13 31 102 153 255
12 13 31 102 153 255
-9 14 31 102 153 255
-8 14 31 102 153 255
10 14 31 102 153 255
-7 15 31 102 153 255
-6 15 31 102 153 255
8 15 31 102 153 255
9 15 31 102 153 255
-5 16 31 102 153 255
-4 16 31 102 153 255
-3 16 31 102 153 255
-2 16 31 102 153 255
4 16 31 102 153 255
5 16 31 102 153 255
6 16 31 102 153 255
-4 -18 32 102 153 255
-3 -18 32 102 153 255
-2 -18 32 102 153 255
-1 -18 32 102 153 255
3 -18 32 102 153 255
4 -18 32 102 153 255
5 -18 32 102 153 255
6 -18 32 102 153 255
-7 -17 32 102 153 255
-6 -17 32 102 153 255
7 -17 32 102 153 255
8 -17 32 102 153 255
-8 -16 32 102 153 255
10 -16 32 102 153 255
-10 -15 32 102 153 255
-9 -15 32 102 153 255
11 -15 32 102 153 255
12 -15 32 102 153 255
-11 -14 32 102 153 255
12 -14 32 102 153 255
13 -14 32 102 153 255
-12 -13 32 102 153 255
13 -13 32 102 153 255
14 -13 32 102 153 255
-13 -12 32 102 153 255
14 -12 32 102 153 255
15 -12 32 102 153 255
-13 -11 32 102 153 255
15 -11 32 102 153 255
-14 -10 32 102 153 255
16 -10 32 102 153 255
-15 -9 32 102 153 255
16 -9 32 102 153 255
-15 -8 32 102 153 255
17 -8 32 102 153 255
-15 -7 32 102 153 255
17 -7 32 102 153 255
-16 -6 32 102 153 255
-16 -5 32 102 153 255
18 -5 32 102 153 255
-25 -4 32 102 153 255
-24 -4 32 102 153 255
-16 -4 32 102 153 255
18 -4 32 102 153 255
-26 -3 32 102 153 255
-23 -3 32 102 153 255
-16 -3 32 102 153 255
18 -3 32 102 153 255
28 -3 32 102 153 255
29 -3 32 102 153 255
30 -3 32 102 153 255
-23 -2 32 102 153 255
18 -2 32 102 153 255
30 -2 32 102 153 255
18 -1 32 102 153 255
30 -1 32 102 153 255
-26 0 32 102 153 255
-23 0 32 102 153 255
18 0 32 102 153 255
30 0 32 102 153 255
-26 1 32 102 153 255
-23 1 32 102 153 255
-16 1 32 102 153 255
18 1 32 102 153 255
28 1 32 102 153 255
29 1 32 102 153 255
-24 2 32 102 153 255
-16 2 32 102 153 255
18 2 32 102 153 255
-16 3 32 102 153 255
18 3 32 102 153 255
-16 4 32 102 153 255
17 4 32 102 153 255
-15 5 32 102 153 255
17 5 32 102 153 255
-15 6 32 102 153 255
17 6 32 102 153 255
-14 7 32 102 153 255
16 7 32 102 153 255
-14 8 32 102 153 255
16 8 32 102 153 255
-13 9 32 102 153 255
15 9 32 102 153 255
-13 10 32 102 153 255
-12 10 32 102 153 255
14 10 32 102 153 255
-12 11 32 102 153 255
-11 11 32 102 153 255
13 11 32 102 153 255
-11 12 32 102 153 255
-10 12 32 102 153 255
12 12 32 102 153 255
-9 13 32 102 153 255
11 13 32 102 153 255
-8 14 32 102 153 255
-7 14 32 102 153 255
9 14 32 102 153 255
10 14 32 102 153 255
-6 15 32 102 153 255
-5 15 32 102 153 255
6 15 32 102 153 255
7 15 32 102 153 255
8 15 32 102 153 255
-3 16 32 102 153 255
-2 16 32 102 153 255
-1 16 32 102 153 255
0 16 32 102 153 255
1 16 32 102 153 255
2 16 32 102 153 255
3 16 32 102 153 255
4 16 32 102 153 255
5 16 32 102 153 255
-3 -18 33 102 153 255
-2 -18 33 102 153 255
-1 -18 33 102 153 255
0 -18 33 102 153 255
1 -18 33 102 153 255
2 -18 33 102 153 255
3 -18 33 102 153 255
4 -18 33 102 153 255
-6 -17 33 102 153 255
-5 -17 33 102 153 255
-4 -17 33 102 153 255
6 -17 33 102 153 255
7 -17 33 102 153 255
-8 -16 33 102 153 255
-7 -16 33 102 153 255
9 -16 33 102 153 255
-9 -15 33 102 153 255
10 -15 33 102 153 255
11 -15 33 102 153 255
-10 -14 33 102 153 255
12 -14 33 102 153 255
-11 -13 33 102 153 255
13 -13 33 102 153 255
-12 -12 33 102 153 255
14 -12 33 102 153 255
-13 -11 33 102 153 255
15 -11 33 102 153 255
-14 -10 33 102 153 255
15 -10 33 102 153 255
-14 -9 33 102 153 255
16 -9 33 102 153 255
-15 -8 33 102 153 255
16 -8 33 102 153 255
-15 -7 33 102 153 255
17 -7 33 102 153 255
-15 -6 33 102 153 255
17 -6 33 102 153 255
-16 -5 33 102 153 255
17 -5 33 102 153 255
-25 -4 33 102 153 255
-24 -4 33 102 153 255
-16 -4 33 102 153 255
-26 -3 33 102 153 255
-23 -3 33 102 153 255
-16 -3 33 102 153 255
18 -3 33 102 153 255
27 -3 33 102 153 255
28 -3 33 102 153 255
29 -3 33 102 153 255
-27 -2 33 102 153 255
-23 -2 33 102 153 255
-16 -2 33 102 153 255
18 -2 33 102 153 255
27 -2 33 102 153 255
30 -2 33 102 153 255
-27 -1 33 102 153 255
-23 -1 33 102 153 255
-16 -1 33 102 153 255
18 -1 33 102 153 255
27 -1 33 102 153 255
30 -1 33 102 153 255
-27 0 33 102 153 255
-23 0 33 102 153 255
-16 0 33 102 153 255
18 0 33 102 153 255
27 0 33 102 153 255
30 0 33 102 153 255
-26 1 33 102 153 255
-24 1 33 102 153 255
-16 1 33 102 153 255
18 1 33 102 153 255
28 1 33 102 153 255
29 1 33 102 153 255
-16 2 33 102 153 255
17 3 33 102 153 255
-15 4 33 102 153 255
17 4 33 102 153 255
-15 5 33 102 153 255
17 5 33 102 153 255
-14 6 33 102 153 255
16 6 33 102 153 255
-14 7 33 102 153 255
16 7 33 102 153 255
-13 8 33 102 153 255
15 8 33 102 153 255
-13 9 33 102 153 255
14 9 33 102 153 255
-12 10 33 102 153 255
13 10 33 102 153 255
14 10 33 102 153 255
-11 11 33 102 153 255
12 11 33 102 153 255
13 11 33 102 153 255
-10 12 33 102 153 255
11 12 33 102 153 255
12 12 33 102 153 255
-9 13 33 102 153 255
-8 13 33 102 153 255
10 13 33 102 153 255
-7 14 33 102 153 255
-6 14 33 102 153 255
8 14 33 102 153 255
9 14 33 102 153 255
-5 15 33 102 153 255
-4 15 33 102 153 255
-3 15 33 102 153 255
5 15 33 102 153 255
6 15 33 102 153 255
7 15 33 102 153 255
-1 16 33 102 153 255
0 16 33 102 153 255
1 16 33 102 153 255
2 16 33 102 153 255
-5 -17 34 102 153 255
-4 -17 34 102 153 255
-3 -17 34 102 153 255
-2 -17 34 102 153 255
4 -17 34 102 153 255
5 -17 34 102 153 255
6 -17 34 102 153 255
-7 -16 34 102 153 255
-6 -16 34 102 153 255
7 -16 34 102 153 255
8 -16 34 102 153 255
9 -16 34 102 153 255
-8 -15 34 102 153 255
9 -15 34 102 153 255
10 -15 34 102 153 255
-10 -14 34 102 153 255
-9 -14 34 102 153 255
11 -14 34 102 153 255
-11 -13 34 102 153 255
-10 -13 34 102 153 255
12 -13 34 102 153 255
13 -13 34 102 153 255
-12 -12 34 102 153 255
-11 -12 34 102 153 255
13 -12 34 102 153 255
-12 -11 34 102 153 255
14 -11 34 102 153 255
-13 -10 34 102 153 255
15 -10 34 102 153 255
-14 -9 34 102 153 255
15 -9 34 102 153 255
-14 -8 34 102 153 255
16 -8 34 102 153 255
16 -7 34 102 153 255
-15 -6 34 102 153 255
17 -6 34 102 153 255
-15 -5 34 102 153 255
17 -5 34 102 153 255
-15 -4 34 102 153 255
17 -4 34 102 153 255
-27 -3 34 102 153 255
-26 -3 34 102 153 255
-24 -3 34 102 153 255
17 -3 34 102 153 255
24 -3 34 102 153 255
25 -3 34 102 153 255
26 -3 34 102 153 255
27 -3 34 102 153 255
28 -3 34 102 153 255
29 -3 34 102 153 255
-27 -2 34 102 153 255
-23 -2 34 102 153 255
17 -2 34 102 153 255
18 -2 34 102 153 255
19 -2 34 102 153 255
20 -2 34 102 153 255
21 -2 34 102 153 255
22 -2 34 102 153 255
23 -2 34 102 153 255
24 -2 34 102 153 255
25 -2 34 102 153 255
30 -2 34 102 153 255
-27 -1 34 102 153 255
-23 -1 34 102 153 255
17 -1 34 102 153 255
18 -1 34 102 153 255
19 -1 34 102 153 255
20 -1 34 102 153 255
21 -1 34 102 153 255
22 -1 34 102 153 255
23 -1 34 102 153 255
24 -1 34 102 153 255
25 -1 34 102 153 255
30 -1 34 102 153 255
-27 0 34 102 153 255
17 0 34 102 153 255
18 0 34 102 153 255
19 0 34 102 153 255
20 0 34 102 153 255
21 0 34 102 153 255
22 0 34 102 153 255
23 0 34 102 153 255
24 0 34 102 153 255
25 0 34 102 153 255
26 0 34 102 153 255
29 0 34 102 153 255
-26 1 34 102 153 255
-25 1 34 102 153 255
-24 1 34 102 153 255
17 1 34 102 153 255
25 1 34 102 153 255
26 1 34 102 153 255
27 1 34 102 153 255
28 1 34 102 153 255
29 1 34 102 153 255
-15 2 34 102 153 255
17 2 34 102 153 255
-15 3 34 102 153 255
17 3 34 102 153 255
-15 4 34 102 153 255
-14 5 34 102 153 255
16 5 34 102 153 255
-14 6 34 102 153 255
16 6 34 102 153 255
-13 7 34 102 153 255
15 7 34 102 153 255
-13 8 34 102 153 255
15 8 34 102 153 255
-12 9 34 102 153 255
14 9 34 102 153 255
-11 10 34 102 153 255
13 10 34 102 153 255
-10 11 34 102 153 255
12 11 34 102 153 255
-9 12 34 102 153 255
11 12 34 102 153 255
-8 13 34 102 153 255
-7 13 34 102 153 255
9 13 34 102 153 255
10 13 34 102 153 255
-6 14 34 102 153 255
-5 14 34 102 153 255
7 14 34 102 153 255
8 14 34 102 153 255
-3 15 34 102 153 255
-2 15 34 102 153 255
-1 15 34 102 153 255
0 15 34 102 153 255
1 15 34 102 153 255
2 15 34 102 153 255
3 15 34 102 153 255
4 15 34 102 153 255
5 15 34 102 153 255
-3 -17 35 102 153 255
-2 -17 35 102 153 255
-1 -17 35 102 153 255
0 -17 35 102 153 255
1 -17 35 102 153 255
2 -17 35 102 153 255
3 -17 35 102 153 255
4 -17 35 102 153 255
5 -17 35 102 153 255
-6 -16 35 102 153 255
-5 -16 35 102 153 255
-4 -16 35 102 153 255
6 -16 35 102 153 255
7 -16 35 102 153 255
8 -16 35 102 153 255
-8 -15 35 102 153 255
-7 -15 35 102 153 255
9 -15 35 102 153 255
-9 -14 35 102 153 255
-8 -14 35 102 153 255
10 -14 35 102 153 255
11 -14 35 102 153 255
-10 -13 35 102 153 255
11 -13 35 102 153 255
12 -13 35 102 153 255
-11 -12 35 102 153 255
13 -12 35 102 153 255
-12 -11 35 102 153 255
13 -11 35 102 153 255
14 -11 35 102 153 255
-13 -10 35 102 153 255
-12 -10 35 102 153 255
14 -10 35 102 153 255
-13 -9 35 102 153 255
15 -9 35 102 153 255
-14 -8 35 102 153 255
15 -8 35 102 153 255
-14 -7 35 102 153 255
16 -7 35 102 153 255
-14 -6 35 102 153 255
16 -6 35 102 153 255
-15 -5 35 102 153 255
16 -5 35 102 153 255
-15 -4 35 102 153 255
17 -4 35 102 153 255
-27 -3 35 102 153 255
-25 -3 35 102 153 255
-24 -3 35 102 153 255
-15 -3 35 102 153 255
16 -3 35 102 153 255
17 -3 35 102 153 255
18 -3 35 102 153 255
19 -3 35 102 153 255
20 -3 35 102 153 255
21 -3 35 102 153 255
22 -3 35 102 153 255
25 -3 35 102 153 255
26 -3 35 102 153 255
27 -3 35 102 153 255
28 -3 35 102 153 255
-28 -2 35 102 153 255
-24 -2 35 102 153 255
-15 -2 35 102 153 255
17 -2 35 102 153 255
28 -2 35 102 153 255
29 -2 35 102 153 255
-28 -1 35 102 153 255
-24 -1 35 102 153 255
-15 -1 35 102 153 255
17 -1 35 102 153 255
28 -1 35 102 153 255
29 -1 35 102 153 255
-28 0 35 102 153 255
-24 0 35 102 153 255
-15 0 35 102 153 255
17 0 35 102 153 255
28 0 35 102 153 255
29 0 35 102 153 255
-27 1 35 102 153 255
-26 1 35 102 153 255
-25 1 35 102 153 255
-15 1 35 102 153 255
16 1 35 102 153 255
17 1 35 102 153 255
18 1 35 102 153 255
19 1 35 102 153 255
20 1 35 102 153 255
21 1 35 102 153 255
22 1 35 102 153 255
23 1 35 102 153 255
24 1 35 102 153 255
25 1 35 102 153 255
26 1 35 102 153 255
27 1 35 102 153 255
-15 2 35 102 153 255
16 3 35 102 153 255
-14 4 35 102 153 255
16 4 35 102 153 255
-14 5 35 102 153 255
16 5 35 102 153 255
-13 6 35 102 153 255
15 6 35 102 153 255
-13 7 35 102 153 255
15 7 35 102 153 255
-12 8 35 102 153 255
14 8 35 102 153 255
-12 9 35 102 153 255
-11 9 35 102 153 255
13 9 35 102 153 255
-11 10 35 102 153 255
-10 10 35 102 153 255
12 10 35 102 153 255
13 10 35 102 153 255
-10 11 35 102 153 255
-9 11 35 102 153 255
11 11 35 102 153 255
12 11 35 102 153 255
-9 12 35 102 153 255
-8 12 35 102 153 255
10 12 35 102 153 255
-7 13 35 102 153 255
-6 13 35 102 153 255
8 13 35 102 153 255
9 13 35 102 153 255
-5 14 35 102 153 255
-4 14 35 102 153 255
-3 14 35 102 153 255
5 14 35 102 153 255
6 14 35 102 153 255
7 14 35 102 153 255
-1 15 35 102 153 255
0 15 35 102 153 255
1 15 35 102 153 255
2 15 35 102 153 255
3 15 35 102 153 255
0 -17 36 102 153 255
1 -17 36 102 153 255
2 -17 36 102 153 255
-5 -16 36 102 153 255
-4 -16 36 102 153 255
-3 -16 36 102 153 255
4 -16 36 102 153 255
5 -16 36 102 153 255
6 -16 36 102 153 255
-7 -15 36 102 153 255
-6 -15 36 102 153 255
7 -15 36 102 153 255
8 -15 36 102 153 255
-8 -14 36 102 153 255
9 -14 36 102 153 255
10 -14 36 102 153 255
-9 -13 36 102 153 255
11 -13 36 102 153 255
-10 -12 36 102 153 255
12 -12 36 102 153 255
-11 -11 36 102 153 255
13 -11 36 102 153 255
-12 -10 36 102 153 255
14 -10 36 102 153 255
-13 -9 36 102 153 255
14 -9 36 102 153 255
-13 -8 36 102 153 255
15 -8 36 102 153 255
-14 -7 36 102 153 255
15 -7 36 102 153 255
-14 -6 36 102 153 255
16 -6 36 102 153 255
-14 -5 36 102 153 255
16 -5 36 102 153 255
-14 -4 36 102 153 255
16 -4 36 102 153 255
-28 -3 36 102 153 255
-27 -3 36 102 153 255
-26 -3 36 102 153 255
-25 -3 36 102 153 255
16 -3 36 102 153 255
17 -3 36 102 153 255
18 -3 36 102 153 255
19 -3 36 102 153 255
20 -3 36 102 153 255
21 -3 36 102 153 255
22 -3 36 102 153 255
23 -3 36 102 153 255
24 -3 36 102 153 255
-29 -2 36 102 153 255
-28 -2 36 102 153 255
-24 -2 36 102 153 255
16 -2 36 102 153 255
17 -2 36 102 153 255
18 -2 36 102 153 255
19 -2 36 102 153 255
20 -2 36 102 153 255
21 -2 36 102 153 255
22 -2 36 102 153 255
23 -2 36 102 153 255
24 -2 36 102 153 255
25 -2 36 102 153 255
26 -2 36 102 153 255
-29 -1 36 102 153 255
-24 -1 36 102 153 255
-15 -1 36 102 153 255
20 -1 36 102 153 255
21 -1 36 102 153 255
22 -1 36 102 153 255
23 -1 36 102 153 255
24 -1 36 102 153 255
25 -1 36 102 153 255
26 -1 36 102 153 255
-29 0 36 102 153 255
-28 0 36 102 153 255
-25 0 36 102 153 255
-24 0 36 102 153 255
16 0 36 102 153 255
17 0 36 102 153 255
18 0 36 102 153 255
19 0 36 102 153 255
20 0 36 102 153 255
21 0 36 102 153 255
22 0 36 102 153 255
23 0 36 102 153 255
24 0 36 102 153 255
25 0 36 102 153 255
26 0 36 102 153 255
-27 1 36 102 153 255
-26 1 36 102 153 255
16 1 36 102 153 255
-14 2 36 102 153 255
16 2 36 102 153 255
-14 3 36 102 153 255
16 3 36 102 153 255
-14 4 36 102 153 255
-13 5 36 102 153 255
15 5 36 102 153 255
-13 6 36 102 153 255
15 6 36 102 153 255
-12 7 36 102 153 255
14 7 36 102 153 255
-12 8 36 102 153 255
13 8 36 102 153 255
14 8 36 102 153 255
-11 9 36 102 153 255
13 9 36 102 153 255
-10 10 36 102 153 255
12 10 36 102 153 255
-9 11 36 102 153 255
10 11 36 102 153 255
11 11 36 102 153 255
-8 12 36 102 153 255
-7 12 36 102 153 255
9 12 36 102 153 255
10 12 36 102 153 255
-6 13 36 102 153 255
-5 13 36 102 153 255
7 13 36 102 153 255
8 13 36 102 153 255
-4 14 36 102 153 255
-3 14 36 102 153 255
-2 14 36 102 153 255
-1 14 36 102 153 255
0 14 36 102 153 255
1 14 36 102 153 255
2 14 36 102 153 255
3 14 36 102 153 255
4 14 36 102 153 255
5 14 36 102 153 255
-3 -16 37 102 153 255
-2 -16 37 102 153 255
-1 -16 37 102 153 255
0 -16 37 102 153 255
1 -16 37 102 153 255
2 -16 37 102 153 255
3 -16 37 102 153 255
4 -16 37 102 153 255
5 -16 37 102 153 255
-6 -15 37 102 153 255
-5 -15 37 102 153 255
-4 -15 37 102 153 255
6 -15 37 102 153 255
7 -15 37 102 153 255
-7 -14 37 102 153 255
8 -14 37 102 153 255
9 -14 37 102 153 255
-9 -13 37 102 153 255
-8 -13 37 102 153 255
10 -13 37 102 153 255
-10 -12 37 102 153 255
-9 -12 37 102 153 255
11 -12 37 102 153 255
12 -12 37 102 153 255
-11 -11 37 102 153 255
-10 -11 37 102 153 255
12 -11 37 102 153 255
-11 -10 37 102 153 255
13 -10 37 102 153 255
-12 -9 37 102 153 255
14 -9 37 102 153 255
-13 -8 37 102 153 255
14 -8 37 102 153 255
-13 -7 37 102 153 255
15 -7 37 102 153 255
-13 -6 37 102 153 255
15 -6 37 102 153 255
-14 -5 37 102 153 255
15 -5 37 102 153 255
-14 -4 37 102 153 255
16 -4 37 102 153 255
-29 -3 37 102 153 255
-28 -3 37 102 153 255
-27 -3 37 102 153 255
-26 -3 37 102 153 255
-14 -3 37 102 153 255
16 -3 37 102 153 255
-30 -2 37 102 153 255
-25 -2 37 102 153 255
-14 -2 37 102 153 255
16 -2 37 102 153 255
-30 -1 37 102 153 255
-25 -1 37 102 153 255
-14 -1 37 102 153 255
16 -1 37 102 153 255
-30 0 37 102 153 255
-29 0 37 102 153 255
-26 0 37 102 153 255
-25 0 37 102 153 255
-14 0 37 102 153 255
16 0 37 102 153 255
-14 1 37 102 153 255
16 1 37 102 153 255
-14 2 37 102 153 255
16 2 37 102 153 255
-14 3 37 102 153 255
15 3 37 102 153 255
-13 4 37 102 153 255
15 4 37 102 153 255
-13 5 37 102 153 255
15 5 37 102 153 255
-12 6 37 102 153 255
14 6 37 102 153 255
-12 7 37 102 153 255
14 7 37 102 153 255
-11 8 37 102 153 255
13 8 37 102 153 255
-10 9 37 102 153 255
12 9 37 102 153 255
-9 10 37 102 153 255
11 10 37 102 153 255
-8 11 37 102 153 255
10 11 37 102 153 255
-7 12 37 102 153 255
-6 12 37 102 153 255
8 12 37 102 153 255
9 12 37 102 153 255
-5 13 37 102 153 255
-4 13 37 102 153 255
-3 13 37 102 153 255
5 13 37 102 153 255
6 13 37 102 153 255
7 13 37 102 153 255
-2 14 37 102 153 255
-1 14 37 102 153 255
0 14 37 102 153 255
1 14 37 102 153 255
2 14 37 102 153 255
3 14 37 102 153 255
-1 -16 38 102 153 255
0 -16 38 102 153 255
1 -16 38 102 153 255
2 -16 38 102 153 255
-5 -15 38 102 153 255
-4 -15 38 102 153 255
-3 -15 38 102 153 255
-2 -15 38 102 153 255
-1 -15 38 102 153 255
0 -15 38 102 153 255
1 -15 38 102 153 255
2 -15 38 102 153 255
4 -15 38 102 153 255
5 -15 38 102 153 255
6 -15 38 102 153 255
-7 -14 38 102 153 255
-6 -14 38 102 153 255
-5 -14 38 102 153 255
-4 -14 38 102 153 255
-3 -14 38 102 153 255
-1 -14 38 102 153 255
0 -14 38 102 153 255
1 -14 38 102 153 255
2 -14 38 102 153 255
5 -14 38 102 153 255
6 -14 38 102 153 255
7 -14 38 102 153 255
8 -14 38 102 153 255
-8 -13 38 102 153 255
-7 -13 38 102 153 255
-6 -13 38 102 153 255
-4 -13 38 102 153 255
-3 -13 38 102 153 255
-2 -13 38 102 153 255
4 -13 38 102 153 255
5 -13 38 102 153 255
6 -13 38 102 153 255
7 -13 38 102 153 255
8 -13 38 102 153 255
9 -13 38 102 153 255
10 -13 38 102 153 255
-9 -12 38 102 153 255
-8 -12 38 102 153 255
-7 -12 38 102 153 255
-6 -12 38 102 153 255
-5 -12 38 102 153 255
7 -12 38 102 153 255
8 -12 38 102 153 255
9 -12 38 102 153 255
10 -12 38 102 153 255
11 -12 38 102 153 255
-10 -11 38 102 153 255
-9 -11 38 102 153 255
-8 -11 38 102 153 255
-7 -11 38 102 153 255
8 -11 38 102 153 255
9 -11 38 102 153 255
10 -11 38 102 153 255
11 -11 38 102 153 255
12 -11 38 102 153 255
-11 -10 38 102 153 255
-10 -10 38 102 153 255
-9 -10 38 102 153 255
-8 -10 38 102 153 255
10 -10 38 102 153 255
11 -10 38 102 153 255
12 -10 38 102 153 255
13 -10 38 102 153 255
-11 -9 38 102 153 255
-10 -9 38 102 153 255
-9 -9 38 102 153 255
10 -9 38 102 153 255
11 -9 38 102 153 255
12 -9 38 102 153 255
13 -9 38 102 153 255
-12 -8 38 102 153 255
-11 -8 38 102 153 255
-10 -8 38 102 153 255
11 -8 38 102 153 255
12 -8 38 102 153 255
13 -8 38 102 153 255
14 -8 38 102 153 255
-12 -7 38 102 153 255
-11 -7 38 102 153 255
-10 -7 38 102 153 255
12 -7 38 102 153 255
13 -7 38 102 153 255
14 -7 38 102 153 255
-13 -6 38 102 153 255
-12 -6 38 102 153 255
-11 -6 38 102 153 255
12 -6 38 102 153 255
13 -6 38 102 153 255
14 -6 38 102 153 255
15 -6 38 102 153 255
-13 -5 38 102 153 255
-12 -5 38 102 153 255
-11 -5 38 102 153 255
13 -5 38 102 153 255
14 -5 38 102 153 255
15 -5 38 102 153 255
-13 -4 38 102 153 255
-11 -4 38 102 153 255
13 -4 38 102 153 255
14 -4 38 102 153 255
15 -4 38 102 153 255
-30 -3 38 102 153 255
-29 -3 38 102 153 255
-28 -3 38 102 153 255
-27 -3 38 102 153 255
-12 -3 38 102 153 255
13 -3 38 102 153 255
14 -3 38 102 153 255
15 -3 38 102 153 255
-32 -2 38 102 153 255
-31 -2 38 102 153 255
-30 -2 38 102 153 255
-29 -2 38 102 153 255
-28 -2 38 102 153 255
-27 -2 38 102 153 255
-26 -2 38 102 153 255
-14 -2 38 102 153 255
-13 -2 38 102 153 255
-12 -2 38 102 153 255
13 -2 38 102 153 255
15 -2 38 102 153 255
-32 -1 38 102 153 255
-31 -1 38 102 153 255
-27 -1 38 102 153 255
-26 -1 38 102 153 255
-14 -1 38 102 153 255
-13 -1 38 102 153 255
-12 -1 38 102 153 255
13 -1 38 102 153 255
15 -1 38 102 153 255
-32 0 38 102 153 255
-31 0 38 102 153 255
-30 0 38 102 153 255
-29 0 38 102 153 255
-28 0 38 102 153 255
-27 0 38 102 153 255
-26 0 38 102 153 255
-14 0 38 102 153 255
-13 0 38 102 153 255
-12 0 38 102 153 255
13 0 38 102 153 255
15 0 38 102 153 255
-11 1 38 102 153 255
13 1 38 102 153 255
14 1 38 102 153 255
15 1 38 102 153 255
-13 2 38 102 153 255
-12 2 38 102 153 255
-11 2 38 102 153 255
13 2 38 102 153 255
14 2 38 102 153 255
15 2 38 102 153 255
-13 3 38 102 153 255
-12 3 38 102 153 255
-11 3 38 102 153 255
13 3 38 102 153 255
14 3 38 102 153 255
15 3 38 102 153 255
-13 4 38 102 153 255
-12 4 38 102 153 255
-11 4 38 102 153 255
-10 4 38 102 153 255
12 4 38 102 153 255
14 4 38 102 153 255
-12 5 38 102 153 255
-11 5 38 102 153 255
-10 5 38 102 153 255
12 5 38 102 153 255
13 5 38 102 153 255
14 5 38 102 153 255
-12 6 38 102 153 255
-11 6 38 102 153 255
-10 6 38 102 153 255
-9 6 38 102 153 255
11 6 38 102 153 255
13 6 38 102 153 255
14 6 38 102 153 255
-11 7 38 102 153 255
-10 7 38 102 153 255
-9 7 38 102 153 255
-8 7 38 102 153 255
10 7 38 102 153 255
11 7 38 102 153 255
12 7 38 102 153 255
13 7 38 102 153 255
-11 8 38 102 153 255
-10 8 38 102 153 255
-9 8 38 102 153 255
-8 8 38 102 153 255
-7 8 38 102 153 255
9 8 38 102 153 255
10 8 38 102 153 255
11 8 38 102 153 255
12 8 38 102 153 255
-10 9 38 102 153 255
-9 9 38 102 153 255
-8 9 38 102 153 255
-7 9 38 102 153 255
-6 9 38 102 153 255
8 9 38 102 153 255
9 9 38 102 153 255
10 9 38 102 153 255
11 9 38 102 153 255
12 9 38 102 153 255
-9 10 38 102 153 255
-8 10 38 102 153 255
-7 10 38 102 153 255
-5 10 38 102 153 255
-4 10 38 102 153 255
6 10 38 102 153 255
7 10 38 102 153 255
9 10 38 102 153 255
10 10 38 102 153 255
11 10 38 102 153 255
-8 11 38 102 153 255
-7 11 38 102 153 255
-6 11 38 102 153 255
-5 11 38 102 153 255
-3 11 38 102 153 255
-2 11 38 102 153 255
-1 11 38 102 153 255
0 11 38 102 153 255
1 11 38 102 153 255
2 11 38 102 153 255
3 11 38 102 153 255
4 11 38 102 153 255
5 11 38 102 153 255
7 11 38 102 153 255
8 11 38 102 153 255
9 11 38 102 153 255
-6 12 38 102 153 255
-5 12 38 102 153 255
-4 12 38 102 153 255
-3 12 38 102 153 255
-2 12 38 102 153 255
-1 12 38 102 153 255
3 12 38 102 153 255
4 12 38 102 153 255
5 12 38 102 153 255
6 12 38 102 153 255
7 12 38 102 153 255
8 12 38 102 153 255
-4 13 38 102 153 255
-3 13 38 102 153 255
-2 13 38 102 153 255
-1 13 38 102 153 255
0 13 38 102 153 255
1 13 38 102 153 255
2 13 38 102 153 255
3 13 38 102 153 255
4 13 38 102 153 255
5 13 38 102 153 255
-1 -12 39 102 153 255
0 -12 39 102 153 255
1 -12 39 102 153 255
2 -12 39 102 153 255
3 -12 39 102 153 255
-4 -11 39 102 153 255
-3 -11 39 102 153 255
-2 -11 39 102 153 255
-1 -11 39 102 153 255
0 -11 39 102 153 255
1 -11 39 102 153 255
2 -11 39 102 153 255
3 -11 39 102 153 255
4 -11 39 102 153 255
5 -11 39 102 153 255
6 -11 39 102 153 255
-5 -10 39 102 153 255
-4 -10 39 102 153 255
-3 -10 39 102 153 255
-2 -10 39 102 153 255
-1 -10 39 102 153 255
0 -10 39 102 153 255
1 -10 39 102 153 255
2 -10 39 102 153 255
3 -10 39 102 153 255
4 -10 39 102 153 255
5 -10 39 102 153 255
6 -10 39 102 153 255
7 -10 39 102 153 255
-7 -9 39 102 153 255
-6 -9 39 102 153 255
-5 -9 39 102 153 255
-4 -9 39 102 153 255
-3 -9 39 102 153 255
-2 -9 39 102 153 255
-1 -9 39 102 153 255
0 -9 39 102 153 255
1 -9 39 102 153 255
2 -9 39 102 153 255
3 -9 39 102 153 255
4 -9 39 102 153 255
5 -9 39 102 153 255
6 -9 39 102 153 255
7 -9 39 102 153 255
8 -9 39 102 153 255
-7 -8 39 102 153 255
-6 -8 39 102 153 255
-5 -8 39 102 153 255
-4 -8 39 102 153 255
-3 -8 39 102 153 255
5 -8 39 102 153 255
6 -8 39 102 153 255
7 -8 39 102 153 255
8 -8 39 102 153 255
9 -8 39 102 153 255
-8 -7 39 102 153 255
-7 -7 39 102 153 255
-6 -7 39 102 153 255
-5 -7 39 102 153 255
-4 -7 39 102 153 255
6 -7 39 102 153 255
7 -7 39 102 153 255
8 -7 39 102 153 255
9 -7 39 102 153 255
10 -7 39 102 153 255
-9 -6 39 102 153 255
-8 -6 39 102 153 255
-7 -6 39 102 153 255
-6 -6 39 102 153 255
-5 -6 39 102 153 255
7 -6 39 102 153 255
8 -6 39 102 153 255
9 -6 39 102 153 255
10 -6 39 102 153 255
-9 -5 39 102 153 255
-8 -5 39 102 153 255
-7 -5 39 102 153 255
-6 -5 39 102 153 255
8 -5 39 102 153 255
9 -5 39 102 153 255
10 -5 39 102 153 255
11 -5 39 102 153 255
-9 -4 39 102 153 255
-8 -4 39 102 153 255
-7 -4 39 102 153 255
8 -4 39 102 153 255
9 -4 39 102 153 255
10 -4 39 102 153 255
11 -4 39 102 153 255
-10 -3 39 102 153 255
-9 -3 39 102 153 255
-8 -3 39 102 153 255
-7 -3 39 102 153 255
9 -3 39 102 153 255
10 -3 39 102 153 255
11 -3 39 102 153 255
-10 -2 39 102 153 255
-9 -2 39 102 153 255
-8 -2 39 102 153 255
-7 -2 39 102 153 255
9 -2 39 102 153 255
10 -2 39 102 153 255
11 -2 39 102 153 255
-10 -1 39 102 153 255
-9 -1 39 102 153 255
-8 -1 39 102 153 255
-7 -1 39 102 153 255
9 -1 39 102 153 255
10 -1 39 102 153 255
11 -1 39 102 153 255
-10 0 39 102 153 255
-9 0 39 102 153 255
-8 0 39 102 153 255
-7 0 39 102 153 255
9 0 39 102 153 255
10 0 39 102 153 255
11 0 39 102 153 255
-9 1 39 102 153 255
-8 1 39 102 153 255
-7 1 39 102 153 255
9 1 39 102 153 255
10 1 39 102 153 255
11 1 39 102 153 255
-9 2 39 102 153 255
-8 2 39 102 153 255
-7 2 39 102 153 255
-6 2 39 102 153 255
8 2 39 102 153 255
9 2 39 102 153 255
10 2 39 102 153 255
11 2 39 102 153 255
-9 3 39 102 153 255
-8 3 39 102 153 255
-7 3 39 102 153 255
-6 3 39 102 153 255
8 3 39 102 153 255
9 3 39 102 153 255
10 3 39 102 153 255
11 3 39 102 153 255
-9 4 39 102 153 255
-8 4 39 102 153 255
-7 4 39 102 153 255
-6 4 39 102 153 255
-5 4 39 102 153 255
7 4 39 102 153 255
8 4 39 102 153 255
9 4 39 102 153 255
10 4 39 102 153 255
-8 5 39 102 153 255
-7 5 39 102 153 255
-6 5 39 102 153 255
-5 5 39 102 153 255
-4 5 39 102 153 255
6 5 39 102 153 255
7 5 39 102 153 255
8 5 39 102 153 255
9 5 39 102 153 255
10 5 39 102 153 255
-7 6 39 102 153 255
-6 6 39 102 153 255
-5 6 39 102 153 255
-4 6 39 102 153 255
-3 6 39 102 153 255
-2 6 39 102 153 255
4 6 39 102 153 255
5 6 39 102 153 255
6 6 39 102 153 255
7 6 39 102 153 255
8 6 39 102 153 255
9 6 39 102 153 255
-6 7 39 102 153 255
-5 7 39 102 153 255
-4 7 39 102 153 255
-3 7 39 102 153 255
-2 7 39 102 153 255
-1 7 39 102 153 255
0 7 39 102 153 255
1 7 39 102 153 255
2 7 39 102 153 255
3 7 39 102 153 255
4 7 39 102 153 255
5 7 39 102 153 255
6 7 39 102 153 255
7 7 39 102 153 255
8 7 39 102 153 255
-5 8 39 102 153 255
-4 8 39 102 153 255
-3 8 39 102 153 255
-2 8 39 102 153 255
-1 8 39 102 153 255
0 8 39 102 153 255
1 8 39 102 153 255
2 8 39 102 153 255
3 8 39 102 153 255
4 8 39 102 153 255
5 8 39 102 153 255
6 8 39 102 153 255
7 8 39 102 153 255
-3 9 39 102 153 255
-2 9 39 102 153 255
-1 9 39 102 153 255
0 9 39 102 153 255
1 9 39 102 153 255
2 9 39 102 153 255
3 9 39 102 153 255
4 9 39 102 153 255
5 9 39 102 153 255
0 -6 40 102 153 255
1 -6 40 102 153 255
2 -6 40 102 153 255
-2 -5 40 102 153 255
-1 -5 40 102 153 255
0 -5 40 102 153 255
1 -5 40 102 153 255
2 -5 40 102 153 255
3 -5 40 102 153 255
4 -5 40 102 153 255
-3 -4 40 102 153 255
-2 -4 40 102 153 255
-1 -4 40 102 153 255
0 -4 40 102 153 255
1 -4 40 102 153 255
2 -4 40 102 153 255
3 -4 40 102 153 255
4 -4 40 102 153 255
5 -4 40 102 153 255
-3 -3 40 102 153 255
-2 -3 40 102 153 255
-1 -3 40 102 153 255
3 -3 40 102 153 255
4 -3 40 102 153 255
5 -3 40 102 153 255
-4 -2 40 102 153 255
-3 -2 40 102 153 255
-2 -2 40 102 153 255
4 -2 40 102 153 255
5 -2 40 102 153 255
-4 -1 40 102 153 255
-3 -1 40 102 153 255
-2 -1 40 102 153 255
4 -1 40 102 153 255
5 -1 40 102 153 255
-4 0 40 102 153 255
-3 0 40 102 153 255
-2 0 40 102 153 255
4 0 40 102 153 255
5 0 40 102 153 255
-3 1 40 102 153 255
-2 1 40 102 153 255
-1 1 40 102 153 255
3 1 40 102 153 255
4 1 40 102 153 255
5 1 40 102 153 255
-3 2 40 102 153 255
-2 2 40 102 153 255
-1 2 40 102 153 255
0 2 40 102 153 255
1 2 40 102 153 255
2 2 40 102 153 255
3 2 40 102 153 255
4 2 40 102 153 255
-2 3 40 102 153 255
-1 3 40 102 153 255
0 3 40 102 153 255
1 3 40 102 153 255
2 3 40 102 153 255
3 3 40 102 153 255
0 -3 41 102 153 255
1 -3 41 102 153 255
2 -3 41 102 153 255
-1 -2 41 102 153 255
2 -2 41 102 153 255
-1 -1 41 102 153 255
3 -1 41 102 153 255
-1 0 41 102 153 255
0 0 41 102 153 255
2 0 41 102 153 255
0 -3 42 102 153 255
1 -3 42 102 153 255
2 -3 42 102 153 255
-1 -2 42 102 153 255
3 -2 42 102 153 255
-1 -1 42 102 153 255
3 -1 42 102 153 255
-1 0 42 102 153 255
0 0 42 102 153 255
2 0 42 102 153 255
3 0 42 102 153 255
0 1 42 102 153 255
1 1 42 102 153 255
2 1 42 102 153 255
0 -4 43 102 153 255
1 -4 43 102 153 255
2 -4 43 102 153 255
-1 -3 43 102 153 255
3 -3 43 102 153 255
-2 -2 43 102 153 255
3 -2 43 102 153 255
4 -2 43 102 153 255
-2 -1 43 102 153 255
4 -1 43 102 153 255
-2 0 43 102 153 255
3 0 43 102 153 255
4 0 43 102 153 255
-1 1 43 102 153 255
0 1 43 102 153 255
2 1 43 102 153 255
3 1 43 102 153 255
0 2 43 102 153 255
1 2 43 102 153 255
-1 -4 44 102 153 255
3 -4 44 102 153 255
-2 -3 44 102 153 255
4 -3 44 102 153 255
4 -2 44 102 153 255
4 -1 44 102 153 255
-2 0 44 102 153 255
4 0 44 102 153 255
-2 1 44 102 153 255
4 1 44 102 153 255
-1 2 44 102 153 255
0 2 44 102 153 255
1 2 44 102 153 255
2 2 44 102 153 255
3 2 44 102 153 255
